LOCAL_RANK: 0 - CUDA_VISIBLE_DEVICES: [0]

  | Name              | Type                 | Params | Mode
-------------------------------------------------------------------
0 | feature_extractor | FeatureExtractorCNN  | 84.4 K | train
1 | lstm_model        | SleepStageLSTM       | 15.0 K | train
2 | criterion         | CrossEntropyLoss     | 0      | train
3 | kappa             | MulticlassCohenKappa | 0      | train
-------------------------------------------------------------------
99.4 K    Trainable params
0         Non-trainable params
99.4 K    Total params
0.398     Total estimated model params size (MB)
23        Modules in train mode
0         Modules in eval mode

Detected KeyboardInterrupt, attempting graceful shutdown ...
[W 2025-04-18 09:26:41,912] Trial 1 failed with parameters: {'cnn_output_channels': 16, 'lstm_hidden_size': 32, 'learning_rate': 1.4053290588482477e-05} because of the following error: NameError("name 'exit' is not defined").
Traceback (most recent call last):
  File "/gpfs/data/oermannlab/users/slj9342/.conda/envs/dl4med_25/lib/python3.11/site-packages/pytorch_lightning/trainer/call.py", line 48, in _call_and_handle_interrupt
    return trainer_fn(*args, **kwargs)
           ^^^^^^^^^^^^^^^^^^^^^^^^^^^
  File "/gpfs/data/oermannlab/users/slj9342/.conda/envs/dl4med_25/lib/python3.11/site-packages/pytorch_lightning/trainer/trainer.py", line 599, in _fit_impl
    self._run(model, ckpt_path=ckpt_path)
  File "/gpfs/data/oermannlab/users/slj9342/.conda/envs/dl4med_25/lib/python3.11/site-packages/pytorch_lightning/trainer/trainer.py", line 1012, in _run
    results = self._run_stage()
              ^^^^^^^^^^^^^^^^^
  File "/gpfs/data/oermannlab/users/slj9342/.conda/envs/dl4med_25/lib/python3.11/site-packages/pytorch_lightning/trainer/trainer.py", line 1056, in _run_stage
    self.fit_loop.run()
  File "/gpfs/data/oermannlab/users/slj9342/.conda/envs/dl4med_25/lib/python3.11/site-packages/pytorch_lightning/loops/fit_loop.py", line 216, in run
    self.advance()
  File "/gpfs/data/oermannlab/users/slj9342/.conda/envs/dl4med_25/lib/python3.11/site-packages/pytorch_lightning/loops/fit_loop.py", line 455, in advance
    self.epoch_loop.run(self._data_fetcher)
  File "/gpfs/data/oermannlab/users/slj9342/.conda/envs/dl4med_25/lib/python3.11/site-packages/pytorch_lightning/loops/training_epoch_loop.py", line 150, in run
    self.advance(data_fetcher)
  File "/gpfs/data/oermannlab/users/slj9342/.conda/envs/dl4med_25/lib/python3.11/site-packages/pytorch_lightning/loops/training_epoch_loop.py", line 282, in advance
    batch, _, __ = next(data_fetcher)
                   ^^^^^^^^^^^^^^^^^^
  File "/gpfs/data/oermannlab/users/slj9342/.conda/envs/dl4med_25/lib/python3.11/site-packages/pytorch_lightning/loops/fetchers.py", line 134, in __next__
    batch = super().__next__()
            ^^^^^^^^^^^^^^^^^^
  File "/gpfs/data/oermannlab/users/slj9342/.conda/envs/dl4med_25/lib/python3.11/site-packages/pytorch_lightning/loops/fetchers.py", line 61, in __next__
    batch = next(self.iterator)
            ^^^^^^^^^^^^^^^^^^^
  File "/gpfs/data/oermannlab/users/slj9342/.conda/envs/dl4med_25/lib/python3.11/site-packages/pytorch_lightning/utilities/combined_loader.py", line 341, in __next__
    out = next(self._iterator)
          ^^^^^^^^^^^^^^^^^^^^
  File "/gpfs/data/oermannlab/users/slj9342/.conda/envs/dl4med_25/lib/python3.11/site-packages/pytorch_lightning/utilities/combined_loader.py", line 78, in __next__
    out[i] = next(self.iterators[i])
             ^^^^^^^^^^^^^^^^^^^^^^^
  File "/gpfs/data/oermannlab/users/slj9342/.conda/envs/dl4med_25/lib/python3.11/site-packages/torch/utils/data/dataloader.py", line 708, in __next__
    data = self._next_data()
           ^^^^^^^^^^^^^^^^^
  File "/gpfs/data/oermannlab/users/slj9342/.conda/envs/dl4med_25/lib/python3.11/site-packages/torch/utils/data/dataloader.py", line 1458, in _next_data
    idx, data = self._get_data()
                ^^^^^^^^^^^^^^^^
  File "/gpfs/data/oermannlab/users/slj9342/.conda/envs/dl4med_25/lib/python3.11/site-packages/torch/utils/data/dataloader.py", line 1420, in _get_data
    success, data = self._try_get_data()
                    ^^^^^^^^^^^^^^^^^^^^
  File "/gpfs/data/oermannlab/users/slj9342/.conda/envs/dl4med_25/lib/python3.11/site-packages/torch/utils/data/dataloader.py", line 1251, in _try_get_data
    data = self._data_queue.get(timeout=timeout)
           ^^^^^^^^^^^^^^^^^^^^^^^^^^^^^^^^^^^^^
  File "/gpfs/data/oermannlab/users/slj9342/.conda/envs/dl4med_25/lib/python3.11/multiprocessing/queues.py", line 113, in get
    if not self._poll(timeout):
           ^^^^^^^^^^^^^^^^^^^
  File "/gpfs/data/oermannlab/users/slj9342/.conda/envs/dl4med_25/lib/python3.11/multiprocessing/connection.py", line 257, in poll
    return self._poll(timeout)
           ^^^^^^^^^^^^^^^^^^^
  File "/gpfs/data/oermannlab/users/slj9342/.conda/envs/dl4med_25/lib/python3.11/multiprocessing/connection.py", line 440, in _poll
    r = wait([self], timeout)
        ^^^^^^^^^^^^^^^^^^^^^
  File "/gpfs/data/oermannlab/users/slj9342/.conda/envs/dl4med_25/lib/python3.11/multiprocessing/connection.py", line 948, in wait
    ready = selector.select(timeout)
            ^^^^^^^^^^^^^^^^^^^^^^^^
  File "/gpfs/data/oermannlab/users/slj9342/.conda/envs/dl4med_25/lib/python3.11/selectors.py", line 415, in select
    fd_event_list = self._selector.poll(timeout)
                    ^^^^^^^^^^^^^^^^^^^^^^^^^^^^
KeyboardInterrupt

During handling of the above exception, another exception occurred:

Traceback (most recent call last):
  File "/gpfs/data/oermannlab/users/slj9342/.conda/envs/dl4med_25/lib/python3.11/site-packages/optuna/study/_optimize.py", line 197, in _run_trial
    value_or_values = func(trial)
                      ^^^^^^^^^^^
  File "/tmp/ipykernel_3737080/2158624156.py", line 38, in objective
    trainer.fit(model, train_loader, val_loader)
  File "/gpfs/data/oermannlab/users/slj9342/.conda/envs/dl4med_25/lib/python3.11/site-packages/pytorch_lightning/trainer/trainer.py", line 561, in fit
    call._call_and_handle_interrupt(
  File "/gpfs/data/oermannlab/users/slj9342/.conda/envs/dl4med_25/lib/python3.11/site-packages/pytorch_lightning/trainer/call.py", line 65, in _call_and_handle_interrupt
    exit(1)
    ^^^^
NameError: name 'exit' is not defined
[W 2025-04-18 09:26:41,954] Trial 1 failed with value None.
/gpfs/data/oermannlab/users/slj9342/.conda/envs/dl4med_25/lib/python3.11/site-packages/lightning_fabric/plugins/environments/slurm.py:204: The `srun` command is available on your system but is not used. HINT: If your intention is to run Lightning on SLURM, prepend your python command with `srun` like so: srun python /gpfs/data/oermannlab/users/slj9342/.conda/envs/dl4m ...
GPU available: True (cuda), used: True
TPU available: False, using: 0 TPU cores
HPU available: False, using: 0 HPUs
Max length: 2493810
Max length after downsampling: 7817
