
Terminal command to create your ssh tunnel
ssh -N -L 8393:a100-4027:8393 slj9342@bigpurple.nyumc.org
Windows MobaXterm info
Forwarded port:same as remote port
Remote server: a100-4027
Remote port: 8393
SSH server: bigpurple.nyumc.org
SSH login: slj9342
SSH port: 22
Use a Browser on your local machine to go to:
localhost:8393/lab?token=  (prefix w/ https:// if using password)

[I 2025-04-23 21:03:23.946 ServerApp] Extension package jupyter_lsp took 0.2449s to import
[I 2025-04-23 21:03:24.408 ServerApp] jupyter_lsp | extension was successfully linked.
[I 2025-04-23 21:03:24.412 ServerApp] jupyter_server_terminals | extension was successfully linked.
[I 2025-04-23 21:03:24.417 ServerApp] jupyterlab | extension was successfully linked.
[I 2025-04-23 21:03:24.421 ServerApp] notebook | extension was successfully linked.
[I 2025-04-23 21:03:28.224 ServerApp] notebook_shim | extension was successfully linked.
[I 2025-04-23 21:03:28.374 ServerApp] notebook_shim | extension was successfully loaded.
[I 2025-04-23 21:03:28.375 ServerApp] jupyter_lsp | extension was successfully loaded.
[I 2025-04-23 21:03:28.376 ServerApp] jupyter_server_terminals | extension was successfully loaded.
[I 2025-04-23 21:03:28.388 LabApp] JupyterLab extension loaded from /gpfs/data/oermannlab/users/slj9342/.local/lib/python3.8/site-packages/jupyterlab
[I 2025-04-23 21:03:28.388 LabApp] JupyterLab application directory is /gpfs/data/oermannlab/users/slj9342/.local/share/jupyter/lab
[I 2025-04-23 21:03:28.389 LabApp] Extension Manager is 'pypi'.
[I 2025-04-23 21:03:28.802 ServerApp] jupyterlab | extension was successfully loaded.
[I 2025-04-23 21:03:28.805 ServerApp] notebook | extension was successfully loaded.
[I 2025-04-23 21:03:28.806 ServerApp] Serving notebooks from local directory: /gpfs/data/oermannlab/users/slj9342/dl4med_final_project
[I 2025-04-23 21:03:28.806 ServerApp] Jupyter Server 2.14.2 is running at:
[I 2025-04-23 21:03:28.806 ServerApp] http://a100-4027:8393/tree?token=7c72de6b244bb3133d34ae79adf2a6151ef942816e4ce5b2
[I 2025-04-23 21:03:28.806 ServerApp]     http://127.0.0.1:8393/tree?token=7c72de6b244bb3133d34ae79adf2a6151ef942816e4ce5b2
[I 2025-04-23 21:03:28.806 ServerApp] Use Control-C to stop this server and shut down all kernels (twice to skip confirmation).
[C 2025-04-23 21:03:28.814 ServerApp] 
    
    To access the server, open this file in a browser:
        file:///gpfs/data/oermannlab/users/slj9342/.local/share/jupyter/runtime/jpserver-3109946-open.html
    Or copy and paste one of these URLs:
        http://a100-4027:8393/tree?token=7c72de6b244bb3133d34ae79adf2a6151ef942816e4ce5b2
        http://127.0.0.1:8393/tree?token=7c72de6b244bb3133d34ae79adf2a6151ef942816e4ce5b2
[I 2025-04-23 21:03:28.849 ServerApp] Skipped non-installed server(s): bash-language-server, dockerfile-language-server-nodejs, javascript-typescript-langserver, jedi-language-server, julia-language-server, pyright, python-language-server, python-lsp-server, r-languageserver, sql-language-server, texlab, typescript-language-server, unified-language-server, vscode-css-languageserver-bin, vscode-html-languageserver-bin, vscode-json-languageserver-bin, yaml-language-server
[W 2025-04-23 21:04:21.652 ServerApp] 404 GET /hub/api (@192.168.0.104) 74.49ms referer=None
[I 2025-04-23 21:04:21.656 ServerApp] 302 GET / (@192.168.0.104) 0.32ms
[I 2025-04-23 21:04:21.659 JupyterNotebookApp] 302 GET /tree? (@192.168.0.104) 0.40ms
[I 2025-04-23 21:04:31.098 ServerApp] User 74d6c8488655499386365b3a1221289c logged in.
[I 2025-04-23 21:04:31.099 ServerApp] 302 POST /login? (74d6c8488655499386365b3a1221289c@192.168.0.104) 1.95ms
[I 2025-04-23 21:04:38.027 ServerApp] Kernel started: e66f2c13-0eff-4fce-95a5-c5c3a53962f9
[I 2025-04-23 21:04:48.252 ServerApp] Connecting to kernel e66f2c13-0eff-4fce-95a5-c5c3a53962f9.
[I 2025-04-23 21:08:13.537 ServerApp] Kernel interrupted: e66f2c13-0eff-4fce-95a5-c5c3a53962f9
[I 2025-04-23 21:08:29.797 ServerApp] Kernel restarted: e66f2c13-0eff-4fce-95a5-c5c3a53962f9
[I 2025-04-23 21:08:29.801 ServerApp] Starting buffering for e66f2c13-0eff-4fce-95a5-c5c3a53962f9:0f83ebfb-8a8d-430e-b440-e31d553e79d5
[I 2025-04-23 21:08:29.806 ServerApp] Connecting to kernel e66f2c13-0eff-4fce-95a5-c5c3a53962f9.
[I 2025-04-23 21:08:29.806 ServerApp] Restoring connection for e66f2c13-0eff-4fce-95a5-c5c3a53962f9:0f83ebfb-8a8d-430e-b440-e31d553e79d5
[W 2025-04-23 21:08:34.316 ServerApp] Nudge: attempt 10 on kernel e66f2c13-0eff-4fce-95a5-c5c3a53962f9
[W 2025-04-23 21:08:39.326 ServerApp] Nudge: attempt 20 on kernel e66f2c13-0eff-4fce-95a5-c5c3a53962f9
[I 2025-04-24 01:28:26.690 ServerApp] Starting buffering for e66f2c13-0eff-4fce-95a5-c5c3a53962f9:0f83ebfb-8a8d-430e-b440-e31d553e79d5
[I 2025-04-24 09:42:05.384 ServerApp] 302 GET / (@192.168.0.104) 0.36ms
[I 2025-04-24 09:42:06.706 JupyterNotebookApp] 302 GET /tree? (@192.168.0.104) 0.58ms
[W 2025-04-24 09:57:30.947 ServerApp] wrote error: 'Forbidden'
    Traceback (most recent call last):
      File "/gpfs/data/oermannlab/users/slj9342/.local/lib/python3.8/site-packages/tornado/web.py", line 1788, in _execute
        result = method(*self.path_args, **self.path_kwargs)
      File "/gpfs/data/oermannlab/users/slj9342/.local/lib/python3.8/site-packages/tornado/web.py", line 3289, in wrapper
        url = self.get_login_url()
      File "/gpfs/data/oermannlab/users/slj9342/.local/lib/python3.8/site-packages/jupyter_server/base/handlers.py", line 783, in get_login_url
        raise web.HTTPError(403)
    tornado.web.HTTPError: HTTP 403: Forbidden
[W 2025-04-24 09:57:30.993 ServerApp] 403 GET /api/kernels?1745503050944 (@192.168.0.104) 46.54ms referer=None
[W 2025-04-24 09:57:30.993 ServerApp] wrote error: 'Forbidden'
    Traceback (most recent call last):
      File "/gpfs/data/oermannlab/users/slj9342/.local/lib/python3.8/site-packages/tornado/web.py", line 1788, in _execute
        result = method(*self.path_args, **self.path_kwargs)
      File "/gpfs/data/oermannlab/users/slj9342/.local/lib/python3.8/site-packages/tornado/web.py", line 3289, in wrapper
        url = self.get_login_url()
      File "/gpfs/data/oermannlab/users/slj9342/.local/lib/python3.8/site-packages/jupyter_server/base/handlers.py", line 783, in get_login_url
        raise web.HTTPError(403)
    tornado.web.HTTPError: HTTP 403: Forbidden
[W 2025-04-24 09:57:30.994 ServerApp] 403 GET /api/sessions?1745503050944 (@192.168.0.104) 47.04ms referer=None
[W 2025-04-24 09:57:30.994 ServerApp] wrote error: 'Forbidden'
    Traceback (most recent call last):
      File "/gpfs/data/oermannlab/users/slj9342/.local/lib/python3.8/site-packages/tornado/web.py", line 1788, in _execute
        result = method(*self.path_args, **self.path_kwargs)
      File "/gpfs/data/oermannlab/users/slj9342/.local/lib/python3.8/site-packages/tornado/web.py", line 3289, in wrapper
        url = self.get_login_url()
      File "/gpfs/data/oermannlab/users/slj9342/.local/lib/python3.8/site-packages/jupyter_server/base/handlers.py", line 783, in get_login_url
        raise web.HTTPError(403)
    tornado.web.HTTPError: HTTP 403: Forbidden
[W 2025-04-24 09:57:30.995 ServerApp] 403 GET /api/kernelspecs?1745503050940 (@192.168.0.104) 0.84ms referer=None
[W 2025-04-24 09:57:30.995 ServerApp] wrote error: 'Forbidden'
    Traceback (most recent call last):
      File "/gpfs/data/oermannlab/users/slj9342/.local/lib/python3.8/site-packages/tornado/web.py", line 1788, in _execute
        result = method(*self.path_args, **self.path_kwargs)
      File "/gpfs/data/oermannlab/users/slj9342/.local/lib/python3.8/site-packages/tornado/web.py", line 3289, in wrapper
        url = self.get_login_url()
      File "/gpfs/data/oermannlab/users/slj9342/.local/lib/python3.8/site-packages/jupyter_server/base/handlers.py", line 783, in get_login_url
        raise web.HTTPError(403)
    tornado.web.HTTPError: HTTP 403: Forbidden
[W 2025-04-24 09:57:30.995 ServerApp] 403 GET /api/kernels?1745503050941 (@192.168.0.104) 1.11ms referer=None
[I 2025-04-24 09:57:30.999 ServerApp] 302 GET / (@192.168.0.104) 0.27ms
[I 2025-04-24 09:57:31.001 JupyterNotebookApp] 302 GET /tree? (@192.168.0.104) 0.31ms
[W 2025-04-24 09:57:31.850 ServerApp] wrote error: 'Forbidden'
    Traceback (most recent call last):
      File "/gpfs/data/oermannlab/users/slj9342/.local/lib/python3.8/site-packages/tornado/web.py", line 1788, in _execute
        result = method(*self.path_args, **self.path_kwargs)
      File "/gpfs/data/oermannlab/users/slj9342/.local/lib/python3.8/site-packages/tornado/web.py", line 3289, in wrapper
        url = self.get_login_url()
      File "/gpfs/data/oermannlab/users/slj9342/.local/lib/python3.8/site-packages/jupyter_server/base/handlers.py", line 783, in get_login_url
        raise web.HTTPError(403)
    tornado.web.HTTPError: HTTP 403: Forbidden
[W 2025-04-24 09:57:31.868 ServerApp] 403 GET /api/kernelspecs?1745503051846 (@192.168.0.104) 18.78ms referer=None
[W 2025-04-24 09:57:31.870 ServerApp] wrote error: 'Forbidden'
    Traceback (most recent call last):
      File "/gpfs/data/oermannlab/users/slj9342/.local/lib/python3.8/site-packages/tornado/web.py", line 1788, in _execute
        result = method(*self.path_args, **self.path_kwargs)
      File "/gpfs/data/oermannlab/users/slj9342/.local/lib/python3.8/site-packages/tornado/web.py", line 3289, in wrapper
        url = self.get_login_url()
      File "/gpfs/data/oermannlab/users/slj9342/.local/lib/python3.8/site-packages/jupyter_server/base/handlers.py", line 783, in get_login_url
        raise web.HTTPError(403)
    tornado.web.HTTPError: HTTP 403: Forbidden
[W 2025-04-24 09:57:31.870 ServerApp] 403 GET /api/kernels?1745503051847 (@192.168.0.104) 1.14ms referer=None
[W 2025-04-24 09:57:31.870 ServerApp] wrote error: 'Forbidden'
    Traceback (most recent call last):
      File "/gpfs/data/oermannlab/users/slj9342/.local/lib/python3.8/site-packages/tornado/web.py", line 1788, in _execute
        result = method(*self.path_args, **self.path_kwargs)
      File "/gpfs/data/oermannlab/users/slj9342/.local/lib/python3.8/site-packages/tornado/web.py", line 3289, in wrapper
        url = self.get_login_url()
      File "/gpfs/data/oermannlab/users/slj9342/.local/lib/python3.8/site-packages/jupyter_server/base/handlers.py", line 783, in get_login_url
        raise web.HTTPError(403)
    tornado.web.HTTPError: HTTP 403: Forbidden
[W 2025-04-24 09:57:31.870 ServerApp] 403 GET /api/kernels?1745503051849 (@192.168.0.104) 1.31ms referer=None
[W 2025-04-24 09:57:31.871 ServerApp] wrote error: 'Forbidden'
    Traceback (most recent call last):
      File "/gpfs/data/oermannlab/users/slj9342/.local/lib/python3.8/site-packages/tornado/web.py", line 1788, in _execute
        result = method(*self.path_args, **self.path_kwargs)
      File "/gpfs/data/oermannlab/users/slj9342/.local/lib/python3.8/site-packages/tornado/web.py", line 3289, in wrapper
        url = self.get_login_url()
      File "/gpfs/data/oermannlab/users/slj9342/.local/lib/python3.8/site-packages/jupyter_server/base/handlers.py", line 783, in get_login_url
        raise web.HTTPError(403)
    tornado.web.HTTPError: HTTP 403: Forbidden
[W 2025-04-24 09:57:31.871 ServerApp] 403 GET /api/sessions?1745503051850 (@192.168.0.104) 1.55ms referer=None
[W 2025-04-24 09:57:31.874 ServerApp] wrote error: 'Forbidden'
    Traceback (most recent call last):
      File "/gpfs/data/oermannlab/users/slj9342/.local/lib/python3.8/site-packages/tornado/web.py", line 1788, in _execute
        result = method(*self.path_args, **self.path_kwargs)
      File "/gpfs/data/oermannlab/users/slj9342/.local/lib/python3.8/site-packages/tornado/web.py", line 3289, in wrapper
        url = self.get_login_url()
      File "/gpfs/data/oermannlab/users/slj9342/.local/lib/python3.8/site-packages/jupyter_server/base/handlers.py", line 783, in get_login_url
        raise web.HTTPError(403)
    tornado.web.HTTPError: HTTP 403: Forbidden
[W 2025-04-24 09:57:31.874 ServerApp] 403 GET /api/kernelspecs?1745503051871 (@192.168.0.104) 0.49ms referer=None
[W 2025-04-24 10:10:50.860 ServerApp] 404 GET /hub/api (@192.168.0.104) 2.58ms referer=None
[I 2025-04-24 10:10:50.862 ServerApp] 302 GET / (@192.168.0.104) 0.33ms
[I 2025-04-24 10:10:50.865 JupyterNotebookApp] 302 GET /tree? (@192.168.0.104) 0.37ms
[I 2025-04-24 10:10:59.825 ServerApp] User fb003215e3d140419e3cedb649eb4181 logged in.
[I 2025-04-24 10:10:59.826 ServerApp] 302 POST /login? (fb003215e3d140419e3cedb649eb4181@192.168.0.104) 1.85ms
[I 2025-04-24 10:11:05.720 ServerApp] Kernel started: 2a696a36-a54f-46a6-907a-9369c8d58e5b
[I 2025-04-24 10:11:15.797 ServerApp] Connecting to kernel 2a696a36-a54f-46a6-907a-9369c8d58e5b.
[I 2025-04-24 10:11:16.333 ServerApp] 302 GET / (@192.168.0.104) 0.75ms
[I 2025-04-24 10:11:16.393 JupyterNotebookApp] 302 GET /tree? (@192.168.0.104) 0.55ms
[I 2025-04-24 10:11:32.898 ServerApp] User 7284a3eaa0a5498e833c81e886482016 logged in.
[I 2025-04-24 10:11:32.898 ServerApp] 302 POST /login? (7284a3eaa0a5498e833c81e886482016@192.168.0.104) 0.91ms
[W 2025-04-24 14:52:51.103 ServerApp] 404 GET /hub/api (@192.168.0.104) 5.32ms referer=None
[I 2025-04-24 14:52:51.106 ServerApp] 302 GET / (@192.168.0.104) 0.34ms
[I 2025-04-24 14:52:51.109 JupyterNotebookApp] 302 GET /tree? (@192.168.0.104) 0.47ms
[I 2025-04-24 14:52:57.857 ServerApp] User 12ad257247b8420d8dbcd9f58814ba89 logged in.
[I 2025-04-24 14:52:57.857 ServerApp] 302 POST /login? (12ad257247b8420d8dbcd9f58814ba89@192.168.0.104) 0.87ms
[I 2025-04-24 14:53:19.377 ServerApp] Starting buffering for 2a696a36-a54f-46a6-907a-9369c8d58e5b:249335f3-5c94-4bf6-954c-356c678ff1d6
[I 2025-04-24 14:53:27.795 ServerApp] Kernel started: 70ead765-effe-442c-bc99-24e088fbda5b
[I 2025-04-24 14:53:38.286 ServerApp] Connecting to kernel 70ead765-effe-442c-bc99-24e088fbda5b.
[I 2025-04-24 15:12:57.711 ServerApp] Kernel restarted: 70ead765-effe-442c-bc99-24e088fbda5b
[I 2025-04-24 15:12:57.716 ServerApp] Starting buffering for 70ead765-effe-442c-bc99-24e088fbda5b:88b62c93-d04f-4600-9ebb-fa7815d8013e
[I 2025-04-24 15:12:57.724 ServerApp] Connecting to kernel 70ead765-effe-442c-bc99-24e088fbda5b.
[I 2025-04-24 15:12:57.724 ServerApp] Restoring connection for 70ead765-effe-442c-bc99-24e088fbda5b:88b62c93-d04f-4600-9ebb-fa7815d8013e
[W 2025-04-24 15:13:02.234 ServerApp] Nudge: attempt 10 on kernel 70ead765-effe-442c-bc99-24e088fbda5b
[I 2025-04-24 15:24:37.867 ServerApp] Connecting to kernel 2a696a36-a54f-46a6-907a-9369c8d58e5b.
[W 2025-04-24 15:24:38.700 ServerApp] 404 GET /nbextensions/jupyter-js-widgets/extension.js (@192.168.0.104) 9.92ms referer=None
[W 2025-04-24 15:24:38.701 ServerApp] 404 GET /nbextensions/jupyter-js-widgets/extension.js (@192.168.0.104) 0.68ms referer=None
[W 2025-04-24 16:03:57.726 ServerApp] WebSocket ping timeout after 119990 ms.
[W 2025-04-24 16:22:42.972 ServerApp] 
[W 2025-04-24 16:22:42.973 ServerApp] 
[W 2025-04-24 16:22:42.973 ServerApp] 
[W 2025-04-24 16:22:42.973 ServerApp] 
[W 2025-04-24 16:22:42.974 ServerApp] 
[W 2025-04-24 16:22:42.974 ServerApp] 
[W 2025-04-24 16:22:42.975 ServerApp] 
[W 2025-04-24 16:22:42.975 ServerApp] 
[W 2025-04-24 16:22:42.975 ServerApp] 
[W 2025-04-24 16:22:42.976 ServerApp] 
[W 2025-04-24 16:22:42.976 ServerApp] 
[W 2025-04-24 16:22:42.976 ServerApp] 
[I 2025-04-24 16:22:47.972 ServerApp] Starting buffering for 70ead765-effe-442c-bc99-24e088fbda5b:88b62c93-d04f-4600-9ebb-fa7815d8013e
[I 2025-04-24 16:22:57.953 ServerApp] Connecting to kernel 70ead765-effe-442c-bc99-24e088fbda5b.
[I 2025-04-24 16:22:57.964 ServerApp] Restoring connection for 70ead765-effe-442c-bc99-24e088fbda5b:88b62c93-d04f-4600-9ebb-fa7815d8013e
[I 2025-04-24 16:22:57.964 ServerApp] Replaying 4 buffered messages
[I 2025-04-24 18:17:54.592 ServerApp] 302 GET / (@192.168.0.104) 0.54ms
[I 2025-04-24 18:17:54.603 ServerApp] 302 GET / (@192.168.0.104) 10.75ms
[I 2025-04-24 18:17:54.603 ServerApp] 302 GET / (@192.168.0.104) 10.81ms
[I 2025-04-24 18:17:54.875 JupyterNotebookApp] 302 GET /tree? (@192.168.0.104) 0.71ms
[I 2025-04-24 18:17:54.876 JupyterNotebookApp] 302 GET /tree? (@192.168.0.104) 0.80ms
[I 2025-04-24 18:17:54.876 JupyterNotebookApp] 302 GET /tree? (@192.168.0.104) 0.89ms
[W 2025-04-24 18:17:56.299 ServerApp] wrote error: 'Forbidden'
    Traceback (most recent call last):
      File "/gpfs/data/oermannlab/users/slj9342/.local/lib/python3.8/site-packages/tornado/web.py", line 1788, in _execute
        result = method(*self.path_args, **self.path_kwargs)
      File "/gpfs/data/oermannlab/users/slj9342/.local/lib/python3.8/site-packages/tornado/web.py", line 3289, in wrapper
        url = self.get_login_url()
      File "/gpfs/data/oermannlab/users/slj9342/.local/lib/python3.8/site-packages/jupyter_server/base/handlers.py", line 783, in get_login_url
        raise web.HTTPError(403)
    tornado.web.HTTPError: HTTP 403: Forbidden
[W 2025-04-24 18:17:56.354 ServerApp] 403 GET /api/kernelspecs?1745533076282 (@192.168.0.104) 55.83ms referer=None
[W 2025-04-24 18:17:56.354 ServerApp] wrote error: 'Forbidden'
    Traceback (most recent call last):
      File "/gpfs/data/oermannlab/users/slj9342/.local/lib/python3.8/site-packages/tornado/web.py", line 1788, in _execute
        result = method(*self.path_args, **self.path_kwargs)
      File "/gpfs/data/oermannlab/users/slj9342/.local/lib/python3.8/site-packages/tornado/web.py", line 3289, in wrapper
        url = self.get_login_url()
      File "/gpfs/data/oermannlab/users/slj9342/.local/lib/python3.8/site-packages/jupyter_server/base/handlers.py", line 783, in get_login_url
        raise web.HTTPError(403)
    tornado.web.HTTPError: HTTP 403: Forbidden
[W 2025-04-24 18:17:56.354 ServerApp] 403 GET /api/kernels?1745533076282 (@192.168.0.104) 56.13ms referer=None
[W 2025-04-24 18:17:56.354 ServerApp] wrote error: 'Forbidden'
    Traceback (most recent call last):
      File "/gpfs/data/oermannlab/users/slj9342/.local/lib/python3.8/site-packages/tornado/web.py", line 1788, in _execute
        result = method(*self.path_args, **self.path_kwargs)
      File "/gpfs/data/oermannlab/users/slj9342/.local/lib/python3.8/site-packages/tornado/web.py", line 3289, in wrapper
        url = self.get_login_url()
      File "/gpfs/data/oermannlab/users/slj9342/.local/lib/python3.8/site-packages/jupyter_server/base/handlers.py", line 783, in get_login_url
        raise web.HTTPError(403)
    tornado.web.HTTPError: HTTP 403: Forbidden
[W 2025-04-24 18:17:56.355 ServerApp] 403 GET /api/kernelspecs?1745533076283 (@192.168.0.104) 56.42ms referer=None
[W 2025-04-24 18:17:56.693 ServerApp] wrote error: 'Forbidden'
    Traceback (most recent call last):
      File "/gpfs/data/oermannlab/users/slj9342/.local/lib/python3.8/site-packages/tornado/web.py", line 1788, in _execute
        result = method(*self.path_args, **self.path_kwargs)
      File "/gpfs/data/oermannlab/users/slj9342/.local/lib/python3.8/site-packages/tornado/web.py", line 3289, in wrapper
        url = self.get_login_url()
      File "/gpfs/data/oermannlab/users/slj9342/.local/lib/python3.8/site-packages/jupyter_server/base/handlers.py", line 783, in get_login_url
        raise web.HTTPError(403)
    tornado.web.HTTPError: HTTP 403: Forbidden
[W 2025-04-24 18:17:56.693 ServerApp] 403 GET /api/kernels?1745533076284 (@192.168.0.104) 2.22ms referer=None
[W 2025-04-24 18:17:56.693 ServerApp] wrote error: 'Forbidden'
    Traceback (most recent call last):
      File "/gpfs/data/oermannlab/users/slj9342/.local/lib/python3.8/site-packages/tornado/web.py", line 1788, in _execute
        result = method(*self.path_args, **self.path_kwargs)
      File "/gpfs/data/oermannlab/users/slj9342/.local/lib/python3.8/site-packages/tornado/web.py", line 3289, in wrapper
        url = self.get_login_url()
      File "/gpfs/data/oermannlab/users/slj9342/.local/lib/python3.8/site-packages/jupyter_server/base/handlers.py", line 783, in get_login_url
        raise web.HTTPError(403)
    tornado.web.HTTPError: HTTP 403: Forbidden
[W 2025-04-24 18:17:56.694 ServerApp] 403 GET /api/kernelspecs?1745533076284 (@192.168.0.104) 2.50ms referer=None
[W 2025-04-24 18:17:56.694 ServerApp] wrote error: 'Forbidden'
    Traceback (most recent call last):
      File "/gpfs/data/oermannlab/users/slj9342/.local/lib/python3.8/site-packages/tornado/web.py", line 1788, in _execute
        result = method(*self.path_args, **self.path_kwargs)
      File "/gpfs/data/oermannlab/users/slj9342/.local/lib/python3.8/site-packages/tornado/web.py", line 3289, in wrapper
        url = self.get_login_url()
      File "/gpfs/data/oermannlab/users/slj9342/.local/lib/python3.8/site-packages/jupyter_server/base/handlers.py", line 783, in get_login_url
        raise web.HTTPError(403)
    tornado.web.HTTPError: HTTP 403: Forbidden
[W 2025-04-24 18:17:56.705 ServerApp] 403 GET /api/kernels?1745533076285 (@192.168.0.104) 13.44ms referer=None
[W 2025-04-24 18:17:56.705 ServerApp] wrote error: 'Forbidden'
    Traceback (most recent call last):
      File "/gpfs/data/oermannlab/users/slj9342/.local/lib/python3.8/site-packages/tornado/web.py", line 1788, in _execute
        result = method(*self.path_args, **self.path_kwargs)
      File "/gpfs/data/oermannlab/users/slj9342/.local/lib/python3.8/site-packages/tornado/web.py", line 3289, in wrapper
        url = self.get_login_url()
      File "/gpfs/data/oermannlab/users/slj9342/.local/lib/python3.8/site-packages/jupyter_server/base/handlers.py", line 783, in get_login_url
        raise web.HTTPError(403)
    tornado.web.HTTPError: HTTP 403: Forbidden
[W 2025-04-24 18:17:56.705 ServerApp] 403 GET /api/kernelspecs?1745533076287 (@192.168.0.104) 13.74ms referer=None
[W 2025-04-24 18:17:56.705 ServerApp] wrote error: 'Forbidden'
    Traceback (most recent call last):
      File "/gpfs/data/oermannlab/users/slj9342/.local/lib/python3.8/site-packages/tornado/web.py", line 1788, in _execute
        result = method(*self.path_args, **self.path_kwargs)
      File "/gpfs/data/oermannlab/users/slj9342/.local/lib/python3.8/site-packages/tornado/web.py", line 3289, in wrapper
        url = self.get_login_url()
      File "/gpfs/data/oermannlab/users/slj9342/.local/lib/python3.8/site-packages/jupyter_server/base/handlers.py", line 783, in get_login_url
        raise web.HTTPError(403)
    tornado.web.HTTPError: HTTP 403: Forbidden
[W 2025-04-24 18:17:56.705 ServerApp] 403 GET /api/kernels?1745533076288 (@192.168.0.104) 14.03ms referer=None
[W 2025-04-24 18:17:56.706 ServerApp] wrote error: 'Forbidden'
    Traceback (most recent call last):
      File "/gpfs/data/oermannlab/users/slj9342/.local/lib/python3.8/site-packages/tornado/web.py", line 1788, in _execute
        result = method(*self.path_args, **self.path_kwargs)
      File "/gpfs/data/oermannlab/users/slj9342/.local/lib/python3.8/site-packages/tornado/web.py", line 3289, in wrapper
        url = self.get_login_url()
      File "/gpfs/data/oermannlab/users/slj9342/.local/lib/python3.8/site-packages/jupyter_server/base/handlers.py", line 783, in get_login_url
        raise web.HTTPError(403)
    tornado.web.HTTPError: HTTP 403: Forbidden
[W 2025-04-24 18:17:56.706 ServerApp] 403 GET /api/kernelspecs?1745533076290 (@192.168.0.104) 14.33ms referer=None
[W 2025-04-24 18:17:56.706 ServerApp] wrote error: 'Forbidden'
    Traceback (most recent call last):
      File "/gpfs/data/oermannlab/users/slj9342/.local/lib/python3.8/site-packages/tornado/web.py", line 1788, in _execute
        result = method(*self.path_args, **self.path_kwargs)
      File "/gpfs/data/oermannlab/users/slj9342/.local/lib/python3.8/site-packages/tornado/web.py", line 3289, in wrapper
        url = self.get_login_url()
      File "/gpfs/data/oermannlab/users/slj9342/.local/lib/python3.8/site-packages/jupyter_server/base/handlers.py", line 783, in get_login_url
        raise web.HTTPError(403)
    tornado.web.HTTPError: HTTP 403: Forbidden
[W 2025-04-24 18:17:56.706 ServerApp] 403 GET /api/kernels?1745533076291 (@192.168.0.104) 14.61ms referer=None
[W 2025-04-24 18:17:56.706 ServerApp] wrote error: 'Forbidden'
    Traceback (most recent call last):
      File "/gpfs/data/oermannlab/users/slj9342/.local/lib/python3.8/site-packages/tornado/web.py", line 1788, in _execute
        result = method(*self.path_args, **self.path_kwargs)
      File "/gpfs/data/oermannlab/users/slj9342/.local/lib/python3.8/site-packages/tornado/web.py", line 3289, in wrapper
        url = self.get_login_url()
      File "/gpfs/data/oermannlab/users/slj9342/.local/lib/python3.8/site-packages/jupyter_server/base/handlers.py", line 783, in get_login_url
        raise web.HTTPError(403)
    tornado.web.HTTPError: HTTP 403: Forbidden
[W 2025-04-24 18:17:56.715 ServerApp] 403 GET /api/kernels?1745533076298 (@192.168.0.104) 22.94ms referer=None
[W 2025-04-24 18:17:56.715 ServerApp] wrote error: 'Forbidden'
    Traceback (most recent call last):
      File "/gpfs/data/oermannlab/users/slj9342/.local/lib/python3.8/site-packages/tornado/web.py", line 1788, in _execute
        result = method(*self.path_args, **self.path_kwargs)
      File "/gpfs/data/oermannlab/users/slj9342/.local/lib/python3.8/site-packages/tornado/web.py", line 3289, in wrapper
        url = self.get_login_url()
      File "/gpfs/data/oermannlab/users/slj9342/.local/lib/python3.8/site-packages/jupyter_server/base/handlers.py", line 783, in get_login_url
        raise web.HTTPError(403)
    tornado.web.HTTPError: HTTP 403: Forbidden
[W 2025-04-24 18:17:56.715 ServerApp] 403 GET /api/sessions?1745533076299 (@192.168.0.104) 23.25ms referer=None
[W 2025-04-24 18:17:56.715 ServerApp] wrote error: 'Forbidden'
    Traceback (most recent call last):
      File "/gpfs/data/oermannlab/users/slj9342/.local/lib/python3.8/site-packages/tornado/web.py", line 1788, in _execute
        result = method(*self.path_args, **self.path_kwargs)
      File "/gpfs/data/oermannlab/users/slj9342/.local/lib/python3.8/site-packages/tornado/web.py", line 3289, in wrapper
        url = self.get_login_url()
      File "/gpfs/data/oermannlab/users/slj9342/.local/lib/python3.8/site-packages/jupyter_server/base/handlers.py", line 783, in get_login_url
        raise web.HTTPError(403)
    tornado.web.HTTPError: HTTP 403: Forbidden
[W 2025-04-24 18:17:56.715 ServerApp] 403 GET /api/kernels?1745533076300 (@192.168.0.104) 23.53ms referer=None
[W 2025-04-24 18:17:56.716 ServerApp] wrote error: 'Forbidden'
    Traceback (most recent call last):
      File "/gpfs/data/oermannlab/users/slj9342/.local/lib/python3.8/site-packages/tornado/web.py", line 1788, in _execute
        result = method(*self.path_args, **self.path_kwargs)
      File "/gpfs/data/oermannlab/users/slj9342/.local/lib/python3.8/site-packages/tornado/web.py", line 3289, in wrapper
        url = self.get_login_url()
      File "/gpfs/data/oermannlab/users/slj9342/.local/lib/python3.8/site-packages/jupyter_server/base/handlers.py", line 783, in get_login_url
        raise web.HTTPError(403)
    tornado.web.HTTPError: HTTP 403: Forbidden
[W 2025-04-24 18:17:56.716 ServerApp] 403 GET /api/sessions?1745533076301 (@192.168.0.104) 23.83ms referer=None
[W 2025-04-24 18:17:56.716 ServerApp] wrote error: 'Forbidden'
    Traceback (most recent call last):
      File "/gpfs/data/oermannlab/users/slj9342/.local/lib/python3.8/site-packages/tornado/web.py", line 1788, in _execute
        result = method(*self.path_args, **self.path_kwargs)
      File "/gpfs/data/oermannlab/users/slj9342/.local/lib/python3.8/site-packages/tornado/web.py", line 3289, in wrapper
        url = self.get_login_url()
      File "/gpfs/data/oermannlab/users/slj9342/.local/lib/python3.8/site-packages/jupyter_server/base/handlers.py", line 783, in get_login_url
        raise web.HTTPError(403)
    tornado.web.HTTPError: HTTP 403: Forbidden
[W 2025-04-24 18:17:56.716 ServerApp] 403 GET /api/kernels?1745533076302 (@192.168.0.104) 24.09ms referer=None
[W 2025-04-24 18:17:56.716 ServerApp] wrote error: 'Forbidden'
    Traceback (most recent call last):
      File "/gpfs/data/oermannlab/users/slj9342/.local/lib/python3.8/site-packages/tornado/web.py", line 1788, in _execute
        result = method(*self.path_args, **self.path_kwargs)
      File "/gpfs/data/oermannlab/users/slj9342/.local/lib/python3.8/site-packages/tornado/web.py", line 3289, in wrapper
        url = self.get_login_url()
      File "/gpfs/data/oermannlab/users/slj9342/.local/lib/python3.8/site-packages/jupyter_server/base/handlers.py", line 783, in get_login_url
        raise web.HTTPError(403)
    tornado.web.HTTPError: HTTP 403: Forbidden
[W 2025-04-24 18:17:56.717 ServerApp] 403 GET /api/sessions?1745533076303 (@192.168.0.104) 24.38ms referer=None
[W 2025-04-24 18:17:56.717 ServerApp] wrote error: 'Forbidden'
    Traceback (most recent call last):
      File "/gpfs/data/oermannlab/users/slj9342/.local/lib/python3.8/site-packages/tornado/web.py", line 1788, in _execute
        result = method(*self.path_args, **self.path_kwargs)
      File "/gpfs/data/oermannlab/users/slj9342/.local/lib/python3.8/site-packages/tornado/web.py", line 3289, in wrapper
        url = self.get_login_url()
      File "/gpfs/data/oermannlab/users/slj9342/.local/lib/python3.8/site-packages/jupyter_server/base/handlers.py", line 783, in get_login_url
        raise web.HTTPError(403)
    tornado.web.HTTPError: HTTP 403: Forbidden
[W 2025-04-24 18:17:56.737 ServerApp] 403 GET /api/kernels?1745533076304 (@192.168.0.104) 44.24ms referer=None
[W 2025-04-24 18:17:56.737 ServerApp] wrote error: 'Forbidden'
    Traceback (most recent call last):
      File "/gpfs/data/oermannlab/users/slj9342/.local/lib/python3.8/site-packages/tornado/web.py", line 1788, in _execute
        result = method(*self.path_args, **self.path_kwargs)
      File "/gpfs/data/oermannlab/users/slj9342/.local/lib/python3.8/site-packages/tornado/web.py", line 3289, in wrapper
        url = self.get_login_url()
      File "/gpfs/data/oermannlab/users/slj9342/.local/lib/python3.8/site-packages/jupyter_server/base/handlers.py", line 783, in get_login_url
        raise web.HTTPError(403)
    tornado.web.HTTPError: HTTP 403: Forbidden
[W 2025-04-24 18:17:56.737 ServerApp] 403 GET /api/sessions?1745533076305 (@192.168.0.104) 44.46ms referer=None
[W 2025-04-24 18:17:56.737 ServerApp] wrote error: 'Forbidden'
    Traceback (most recent call last):
      File "/gpfs/data/oermannlab/users/slj9342/.local/lib/python3.8/site-packages/tornado/web.py", line 1788, in _execute
        result = method(*self.path_args, **self.path_kwargs)
      File "/gpfs/data/oermannlab/users/slj9342/.local/lib/python3.8/site-packages/tornado/web.py", line 3289, in wrapper
        url = self.get_login_url()
      File "/gpfs/data/oermannlab/users/slj9342/.local/lib/python3.8/site-packages/jupyter_server/base/handlers.py", line 783, in get_login_url
        raise web.HTTPError(403)
    tornado.web.HTTPError: HTTP 403: Forbidden
[W 2025-04-24 18:17:56.737 ServerApp] 403 GET /api/kernels?1745533076306 (@192.168.0.104) 44.72ms referer=None
[W 2025-04-24 18:17:56.738 ServerApp] wrote error: 'Forbidden'
    Traceback (most recent call last):
      File "/gpfs/data/oermannlab/users/slj9342/.local/lib/python3.8/site-packages/tornado/web.py", line 1788, in _execute
        result = method(*self.path_args, **self.path_kwargs)
      File "/gpfs/data/oermannlab/users/slj9342/.local/lib/python3.8/site-packages/tornado/web.py", line 3289, in wrapper
        url = self.get_login_url()
      File "/gpfs/data/oermannlab/users/slj9342/.local/lib/python3.8/site-packages/jupyter_server/base/handlers.py", line 783, in get_login_url
        raise web.HTTPError(403)
    tornado.web.HTTPError: HTTP 403: Forbidden
[W 2025-04-24 18:17:56.738 ServerApp] 403 GET /api/sessions?1745533076307 (@192.168.0.104) 0.59ms referer=None
[W 2025-04-24 18:17:56.814 ServerApp] wrote error: 'Forbidden'
    Traceback (most recent call last):
      File "/gpfs/data/oermannlab/users/slj9342/.local/lib/python3.8/site-packages/tornado/web.py", line 1788, in _execute
        result = method(*self.path_args, **self.path_kwargs)
      File "/gpfs/data/oermannlab/users/slj9342/.local/lib/python3.8/site-packages/tornado/web.py", line 3289, in wrapper
        url = self.get_login_url()
      File "/gpfs/data/oermannlab/users/slj9342/.local/lib/python3.8/site-packages/jupyter_server/base/handlers.py", line 783, in get_login_url
        raise web.HTTPError(403)
    tornado.web.HTTPError: HTTP 403: Forbidden
[W 2025-04-24 18:17:56.814 ServerApp] 403 GET /api/kernelspecs?1745533076711 (@192.168.0.104) 0.59ms referer=None
[W 2025-04-24 18:17:56.814 ServerApp] wrote error: 'Forbidden'
    Traceback (most recent call last):
      File "/gpfs/data/oermannlab/users/slj9342/.local/lib/python3.8/site-packages/tornado/web.py", line 1788, in _execute
        result = method(*self.path_args, **self.path_kwargs)
      File "/gpfs/data/oermannlab/users/slj9342/.local/lib/python3.8/site-packages/tornado/web.py", line 3289, in wrapper
        url = self.get_login_url()
      File "/gpfs/data/oermannlab/users/slj9342/.local/lib/python3.8/site-packages/jupyter_server/base/handlers.py", line 783, in get_login_url
        raise web.HTTPError(403)
    tornado.web.HTTPError: HTTP 403: Forbidden
[W 2025-04-24 18:17:56.826 ServerApp] 403 GET /api/kernelspecs?1745533076712 (@192.168.0.104) 11.92ms referer=None
[W 2025-04-24 18:17:56.977 ServerApp] wrote error: 'Forbidden'
    Traceback (most recent call last):
      File "/gpfs/data/oermannlab/users/slj9342/.local/lib/python3.8/site-packages/tornado/web.py", line 1788, in _execute
        result = method(*self.path_args, **self.path_kwargs)
      File "/gpfs/data/oermannlab/users/slj9342/.local/lib/python3.8/site-packages/tornado/web.py", line 3289, in wrapper
        url = self.get_login_url()
      File "/gpfs/data/oermannlab/users/slj9342/.local/lib/python3.8/site-packages/jupyter_server/base/handlers.py", line 783, in get_login_url
        raise web.HTTPError(403)
    tornado.web.HTTPError: HTTP 403: Forbidden
[W 2025-04-24 18:17:56.977 ServerApp] 403 GET /api/kernelspecs?1745533076780 (@192.168.0.104) 0.70ms referer=None
[W 2025-04-24 18:17:56.977 ServerApp] wrote error: 'Forbidden'
    Traceback (most recent call last):
      File "/gpfs/data/oermannlab/users/slj9342/.local/lib/python3.8/site-packages/tornado/web.py", line 1788, in _execute
        result = method(*self.path_args, **self.path_kwargs)
      File "/gpfs/data/oermannlab/users/slj9342/.local/lib/python3.8/site-packages/tornado/web.py", line 3289, in wrapper
        url = self.get_login_url()
      File "/gpfs/data/oermannlab/users/slj9342/.local/lib/python3.8/site-packages/jupyter_server/base/handlers.py", line 783, in get_login_url
        raise web.HTTPError(403)
    tornado.web.HTTPError: HTTP 403: Forbidden
[W 2025-04-24 18:17:56.978 ServerApp] 403 GET /api/kernelspecs?1745533076781 (@192.168.0.104) 0.96ms referer=None
[W 2025-04-24 18:17:56.978 ServerApp] wrote error: 'Forbidden'
    Traceback (most recent call last):
      File "/gpfs/data/oermannlab/users/slj9342/.local/lib/python3.8/site-packages/tornado/web.py", line 1788, in _execute
        result = method(*self.path_args, **self.path_kwargs)
      File "/gpfs/data/oermannlab/users/slj9342/.local/lib/python3.8/site-packages/tornado/web.py", line 3289, in wrapper
        url = self.get_login_url()
      File "/gpfs/data/oermannlab/users/slj9342/.local/lib/python3.8/site-packages/jupyter_server/base/handlers.py", line 783, in get_login_url
        raise web.HTTPError(403)
    tornado.web.HTTPError: HTTP 403: Forbidden
[W 2025-04-24 18:17:56.978 ServerApp] 403 GET /api/kernelspecs?1745533076782 (@192.168.0.104) 1.24ms referer=None
[I 2025-04-24 18:17:57.000 ServerApp] 302 GET / (@192.168.0.104) 0.30ms
[I 2025-04-24 18:17:57.000 ServerApp] 302 GET / (@192.168.0.104) 0.31ms
[I 2025-04-24 18:17:57.118 JupyterNotebookApp] 302 GET /tree? (@192.168.0.104) 0.38ms
[I 2025-04-24 18:17:57.118 JupyterNotebookApp] 302 GET /tree? (@192.168.0.104) 0.45ms
[W 2025-04-24 18:17:57.528 ServerApp] wrote error: 'Forbidden'
    Traceback (most recent call last):
      File "/gpfs/data/oermannlab/users/slj9342/.local/lib/python3.8/site-packages/tornado/web.py", line 1788, in _execute
        result = method(*self.path_args, **self.path_kwargs)
      File "/gpfs/data/oermannlab/users/slj9342/.local/lib/python3.8/site-packages/tornado/web.py", line 3289, in wrapper
        url = self.get_login_url()
      File "/gpfs/data/oermannlab/users/slj9342/.local/lib/python3.8/site-packages/jupyter_server/base/handlers.py", line 783, in get_login_url
        raise web.HTTPError(403)
    tornado.web.HTTPError: HTTP 403: Forbidden
[W 2025-04-24 18:17:57.528 ServerApp] 403 GET /api/kernelspecs?1745533077510 (@192.168.0.104) 0.59ms referer=None
[W 2025-04-24 18:17:57.528 ServerApp] wrote error: 'Forbidden'
    Traceback (most recent call last):
      File "/gpfs/data/oermannlab/users/slj9342/.local/lib/python3.8/site-packages/tornado/web.py", line 1788, in _execute
        result = method(*self.path_args, **self.path_kwargs)
      File "/gpfs/data/oermannlab/users/slj9342/.local/lib/python3.8/site-packages/tornado/web.py", line 3289, in wrapper
        url = self.get_login_url()
      File "/gpfs/data/oermannlab/users/slj9342/.local/lib/python3.8/site-packages/jupyter_server/base/handlers.py", line 783, in get_login_url
        raise web.HTTPError(403)
    tornado.web.HTTPError: HTTP 403: Forbidden
[W 2025-04-24 18:17:57.540 ServerApp] 403 GET /api/kernels?1745533077511 (@192.168.0.104) 11.93ms referer=None
[W 2025-04-24 18:17:57.699 ServerApp] wrote error: 'Forbidden'
    Traceback (most recent call last):
      File "/gpfs/data/oermannlab/users/slj9342/.local/lib/python3.8/site-packages/tornado/web.py", line 1788, in _execute
        result = method(*self.path_args, **self.path_kwargs)
      File "/gpfs/data/oermannlab/users/slj9342/.local/lib/python3.8/site-packages/tornado/web.py", line 3289, in wrapper
        url = self.get_login_url()
      File "/gpfs/data/oermannlab/users/slj9342/.local/lib/python3.8/site-packages/jupyter_server/base/handlers.py", line 783, in get_login_url
        raise web.HTTPError(403)
    tornado.web.HTTPError: HTTP 403: Forbidden
[W 2025-04-24 18:17:57.699 ServerApp] 403 GET /api/kernelspecs?1745533077645 (@192.168.0.104) 1.33ms referer=None
[W 2025-04-24 18:17:57.701 ServerApp] wrote error: 'Forbidden'
    Traceback (most recent call last):
      File "/gpfs/data/oermannlab/users/slj9342/.local/lib/python3.8/site-packages/tornado/web.py", line 1788, in _execute
        result = method(*self.path_args, **self.path_kwargs)
      File "/gpfs/data/oermannlab/users/slj9342/.local/lib/python3.8/site-packages/tornado/web.py", line 3289, in wrapper
        url = self.get_login_url()
      File "/gpfs/data/oermannlab/users/slj9342/.local/lib/python3.8/site-packages/jupyter_server/base/handlers.py", line 783, in get_login_url
        raise web.HTTPError(403)
    tornado.web.HTTPError: HTTP 403: Forbidden
[W 2025-04-24 18:17:57.701 ServerApp] 403 GET /api/kernelspecs?1745533077512 (@192.168.0.104) 1.95ms referer=None
[W 2025-04-24 18:17:57.702 ServerApp] wrote error: 'Forbidden'
    Traceback (most recent call last):
      File "/gpfs/data/oermannlab/users/slj9342/.local/lib/python3.8/site-packages/tornado/web.py", line 1788, in _execute
        result = method(*self.path_args, **self.path_kwargs)
      File "/gpfs/data/oermannlab/users/slj9342/.local/lib/python3.8/site-packages/tornado/web.py", line 3289, in wrapper
        url = self.get_login_url()
      File "/gpfs/data/oermannlab/users/slj9342/.local/lib/python3.8/site-packages/jupyter_server/base/handlers.py", line 783, in get_login_url
        raise web.HTTPError(403)
    tornado.web.HTTPError: HTTP 403: Forbidden
[W 2025-04-24 18:17:57.702 ServerApp] 403 GET /api/kernelspecs?1745533077513 (@192.168.0.104) 2.22ms referer=None
[W 2025-04-24 18:17:57.702 ServerApp] wrote error: 'Forbidden'
    Traceback (most recent call last):
      File "/gpfs/data/oermannlab/users/slj9342/.local/lib/python3.8/site-packages/tornado/web.py", line 1788, in _execute
        result = method(*self.path_args, **self.path_kwargs)
      File "/gpfs/data/oermannlab/users/slj9342/.local/lib/python3.8/site-packages/tornado/web.py", line 3289, in wrapper
        url = self.get_login_url()
      File "/gpfs/data/oermannlab/users/slj9342/.local/lib/python3.8/site-packages/jupyter_server/base/handlers.py", line 783, in get_login_url
        raise web.HTTPError(403)
    tornado.web.HTTPError: HTTP 403: Forbidden
[W 2025-04-24 18:17:57.702 ServerApp] 403 GET /api/kernels?1745533077514 (@192.168.0.104) 2.50ms referer=None
[W 2025-04-24 18:17:57.702 ServerApp] wrote error: 'Forbidden'
    Traceback (most recent call last):
      File "/gpfs/data/oermannlab/users/slj9342/.local/lib/python3.8/site-packages/tornado/web.py", line 1788, in _execute
        result = method(*self.path_args, **self.path_kwargs)
      File "/gpfs/data/oermannlab/users/slj9342/.local/lib/python3.8/site-packages/tornado/web.py", line 3289, in wrapper
        url = self.get_login_url()
      File "/gpfs/data/oermannlab/users/slj9342/.local/lib/python3.8/site-packages/jupyter_server/base/handlers.py", line 783, in get_login_url
        raise web.HTTPError(403)
    tornado.web.HTTPError: HTTP 403: Forbidden
[W 2025-04-24 18:17:57.708 ServerApp] 403 GET /api/kernels?1745533077512 (@192.168.0.104) 7.78ms referer=None
[W 2025-04-24 18:17:57.708 ServerApp] wrote error: 'Forbidden'
    Traceback (most recent call last):
      File "/gpfs/data/oermannlab/users/slj9342/.local/lib/python3.8/site-packages/tornado/web.py", line 1788, in _execute
        result = method(*self.path_args, **self.path_kwargs)
      File "/gpfs/data/oermannlab/users/slj9342/.local/lib/python3.8/site-packages/tornado/web.py", line 3289, in wrapper
        url = self.get_login_url()
      File "/gpfs/data/oermannlab/users/slj9342/.local/lib/python3.8/site-packages/jupyter_server/base/handlers.py", line 783, in get_login_url
        raise web.HTTPError(403)
    tornado.web.HTTPError: HTTP 403: Forbidden
[W 2025-04-24 18:17:57.708 ServerApp] 403 GET /api/kernelspecs?1745533077514 (@192.168.0.104) 8.12ms referer=None
[W 2025-04-24 18:17:57.708 ServerApp] wrote error: 'Forbidden'
    Traceback (most recent call last):
      File "/gpfs/data/oermannlab/users/slj9342/.local/lib/python3.8/site-packages/tornado/web.py", line 1788, in _execute
        result = method(*self.path_args, **self.path_kwargs)
      File "/gpfs/data/oermannlab/users/slj9342/.local/lib/python3.8/site-packages/tornado/web.py", line 3289, in wrapper
        url = self.get_login_url()
      File "/gpfs/data/oermannlab/users/slj9342/.local/lib/python3.8/site-packages/jupyter_server/base/handlers.py", line 783, in get_login_url
        raise web.HTTPError(403)
    tornado.web.HTTPError: HTTP 403: Forbidden
[W 2025-04-24 18:17:57.709 ServerApp] 403 GET /api/kernels?1745533077515 (@192.168.0.104) 8.42ms referer=None
[W 2025-04-24 18:17:57.709 ServerApp] wrote error: 'Forbidden'
    Traceback (most recent call last):
      File "/gpfs/data/oermannlab/users/slj9342/.local/lib/python3.8/site-packages/tornado/web.py", line 1788, in _execute
        result = method(*self.path_args, **self.path_kwargs)
      File "/gpfs/data/oermannlab/users/slj9342/.local/lib/python3.8/site-packages/tornado/web.py", line 3289, in wrapper
        url = self.get_login_url()
      File "/gpfs/data/oermannlab/users/slj9342/.local/lib/python3.8/site-packages/jupyter_server/base/handlers.py", line 783, in get_login_url
        raise web.HTTPError(403)
    tornado.web.HTTPError: HTTP 403: Forbidden
[W 2025-04-24 18:17:57.709 ServerApp] 403 GET /api/kernels?1745533077547 (@192.168.0.104) 8.70ms referer=None
[W 2025-04-24 18:17:57.709 ServerApp] wrote error: 'Forbidden'
    Traceback (most recent call last):
      File "/gpfs/data/oermannlab/users/slj9342/.local/lib/python3.8/site-packages/tornado/web.py", line 1788, in _execute
        result = method(*self.path_args, **self.path_kwargs)
      File "/gpfs/data/oermannlab/users/slj9342/.local/lib/python3.8/site-packages/tornado/web.py", line 3289, in wrapper
        url = self.get_login_url()
      File "/gpfs/data/oermannlab/users/slj9342/.local/lib/python3.8/site-packages/jupyter_server/base/handlers.py", line 783, in get_login_url
        raise web.HTTPError(403)
    tornado.web.HTTPError: HTTP 403: Forbidden
[W 2025-04-24 18:17:57.709 ServerApp] 403 GET /api/sessions?1745533077548 (@192.168.0.104) 8.98ms referer=None
[W 2025-04-24 18:17:57.709 ServerApp] wrote error: 'Forbidden'
    Traceback (most recent call last):
      File "/gpfs/data/oermannlab/users/slj9342/.local/lib/python3.8/site-packages/tornado/web.py", line 1788, in _execute
        result = method(*self.path_args, **self.path_kwargs)
      File "/gpfs/data/oermannlab/users/slj9342/.local/lib/python3.8/site-packages/tornado/web.py", line 3289, in wrapper
        url = self.get_login_url()
      File "/gpfs/data/oermannlab/users/slj9342/.local/lib/python3.8/site-packages/jupyter_server/base/handlers.py", line 783, in get_login_url
        raise web.HTTPError(403)
    tornado.web.HTTPError: HTTP 403: Forbidden
[W 2025-04-24 18:17:57.720 ServerApp] 403 GET /api/kernels?1745533077549 (@192.168.0.104) 19.18ms referer=None
[W 2025-04-24 18:17:57.720 ServerApp] wrote error: 'Forbidden'
    Traceback (most recent call last):
      File "/gpfs/data/oermannlab/users/slj9342/.local/lib/python3.8/site-packages/tornado/web.py", line 1788, in _execute
        result = method(*self.path_args, **self.path_kwargs)
      File "/gpfs/data/oermannlab/users/slj9342/.local/lib/python3.8/site-packages/tornado/web.py", line 3289, in wrapper
        url = self.get_login_url()
      File "/gpfs/data/oermannlab/users/slj9342/.local/lib/python3.8/site-packages/jupyter_server/base/handlers.py", line 783, in get_login_url
        raise web.HTTPError(403)
    tornado.web.HTTPError: HTTP 403: Forbidden
[W 2025-04-24 18:17:57.720 ServerApp] 403 GET /api/sessions?1745533077551 (@192.168.0.104) 19.45ms referer=None
[W 2025-04-24 18:17:57.720 ServerApp] wrote error: 'Forbidden'
    Traceback (most recent call last):
      File "/gpfs/data/oermannlab/users/slj9342/.local/lib/python3.8/site-packages/tornado/web.py", line 1788, in _execute
        result = method(*self.path_args, **self.path_kwargs)
      File "/gpfs/data/oermannlab/users/slj9342/.local/lib/python3.8/site-packages/tornado/web.py", line 3289, in wrapper
        url = self.get_login_url()
      File "/gpfs/data/oermannlab/users/slj9342/.local/lib/python3.8/site-packages/jupyter_server/base/handlers.py", line 783, in get_login_url
        raise web.HTTPError(403)
    tornado.web.HTTPError: HTTP 403: Forbidden
[W 2025-04-24 18:17:57.720 ServerApp] 403 GET /api/kernels?1745533077552 (@192.168.0.104) 19.73ms referer=None
[W 2025-04-24 18:17:57.721 ServerApp] wrote error: 'Forbidden'
    Traceback (most recent call last):
      File "/gpfs/data/oermannlab/users/slj9342/.local/lib/python3.8/site-packages/tornado/web.py", line 1788, in _execute
        result = method(*self.path_args, **self.path_kwargs)
      File "/gpfs/data/oermannlab/users/slj9342/.local/lib/python3.8/site-packages/tornado/web.py", line 3289, in wrapper
        url = self.get_login_url()
      File "/gpfs/data/oermannlab/users/slj9342/.local/lib/python3.8/site-packages/jupyter_server/base/handlers.py", line 783, in get_login_url
        raise web.HTTPError(403)
    tornado.web.HTTPError: HTTP 403: Forbidden
[W 2025-04-24 18:17:57.721 ServerApp] 403 GET /api/sessions?1745533077553 (@192.168.0.104) 20.01ms referer=None
[W 2025-04-24 18:17:57.721 ServerApp] wrote error: 'Forbidden'
    Traceback (most recent call last):
      File "/gpfs/data/oermannlab/users/slj9342/.local/lib/python3.8/site-packages/tornado/web.py", line 1788, in _execute
        result = method(*self.path_args, **self.path_kwargs)
      File "/gpfs/data/oermannlab/users/slj9342/.local/lib/python3.8/site-packages/tornado/web.py", line 3289, in wrapper
        url = self.get_login_url()
      File "/gpfs/data/oermannlab/users/slj9342/.local/lib/python3.8/site-packages/jupyter_server/base/handlers.py", line 783, in get_login_url
        raise web.HTTPError(403)
    tornado.web.HTTPError: HTTP 403: Forbidden
[W 2025-04-24 18:17:57.721 ServerApp] 403 GET /api/kernels?1745533077554 (@192.168.0.104) 20.28ms referer=None
[W 2025-04-24 18:17:57.721 ServerApp] wrote error: 'Forbidden'
    Traceback (most recent call last):
      File "/gpfs/data/oermannlab/users/slj9342/.local/lib/python3.8/site-packages/tornado/web.py", line 1788, in _execute
        result = method(*self.path_args, **self.path_kwargs)
      File "/gpfs/data/oermannlab/users/slj9342/.local/lib/python3.8/site-packages/tornado/web.py", line 3289, in wrapper
        url = self.get_login_url()
      File "/gpfs/data/oermannlab/users/slj9342/.local/lib/python3.8/site-packages/jupyter_server/base/handlers.py", line 783, in get_login_url
        raise web.HTTPError(403)
    tornado.web.HTTPError: HTTP 403: Forbidden
[W 2025-04-24 18:17:57.722 ServerApp] 403 GET /api/sessions?1745533077555 (@192.168.0.104) 20.54ms referer=None
[I 2025-04-24 18:17:57.786 ServerApp] 302 GET / (@192.168.0.104) 0.55ms
[W 2025-04-24 18:17:57.786 ServerApp] wrote error: 'Forbidden'
    Traceback (most recent call last):
      File "/gpfs/data/oermannlab/users/slj9342/.local/lib/python3.8/site-packages/tornado/web.py", line 1788, in _execute
        result = method(*self.path_args, **self.path_kwargs)
      File "/gpfs/data/oermannlab/users/slj9342/.local/lib/python3.8/site-packages/tornado/web.py", line 3289, in wrapper
        url = self.get_login_url()
      File "/gpfs/data/oermannlab/users/slj9342/.local/lib/python3.8/site-packages/jupyter_server/base/handlers.py", line 783, in get_login_url
        raise web.HTTPError(403)
    tornado.web.HTTPError: HTTP 403: Forbidden
[W 2025-04-24 18:17:57.787 ServerApp] 403 GET /api/kernelspecs?1745533077746 (@192.168.0.104) 0.85ms referer=None
[W 2025-04-24 18:17:57.787 ServerApp] wrote error: 'Forbidden'
    Traceback (most recent call last):
      File "/gpfs/data/oermannlab/users/slj9342/.local/lib/python3.8/site-packages/tornado/web.py", line 1788, in _execute
        result = method(*self.path_args, **self.path_kwargs)
      File "/gpfs/data/oermannlab/users/slj9342/.local/lib/python3.8/site-packages/tornado/web.py", line 3289, in wrapper
        url = self.get_login_url()
      File "/gpfs/data/oermannlab/users/slj9342/.local/lib/python3.8/site-packages/jupyter_server/base/handlers.py", line 783, in get_login_url
        raise web.HTTPError(403)
    tornado.web.HTTPError: HTTP 403: Forbidden
[W 2025-04-24 18:17:57.787 ServerApp] 403 GET /api/kernelspecs?1745533077747 (@192.168.0.104) 1.14ms referer=None
[W 2025-04-24 18:17:57.787 ServerApp] wrote error: 'Forbidden'
    Traceback (most recent call last):
      File "/gpfs/data/oermannlab/users/slj9342/.local/lib/python3.8/site-packages/tornado/web.py", line 1788, in _execute
        result = method(*self.path_args, **self.path_kwargs)
      File "/gpfs/data/oermannlab/users/slj9342/.local/lib/python3.8/site-packages/tornado/web.py", line 3289, in wrapper
        url = self.get_login_url()
      File "/gpfs/data/oermannlab/users/slj9342/.local/lib/python3.8/site-packages/jupyter_server/base/handlers.py", line 783, in get_login_url
        raise web.HTTPError(403)
    tornado.web.HTTPError: HTTP 403: Forbidden
[W 2025-04-24 18:17:57.787 ServerApp] 403 GET /api/kernelspecs?1745533077748 (@192.168.0.104) 1.42ms referer=None
[I 2025-04-24 18:17:57.930 JupyterNotebookApp] 302 GET /tree? (@192.168.0.104) 0.28ms
[W 2025-04-24 18:17:58.275 ServerApp] wrote error: 'Forbidden'
    Traceback (most recent call last):
      File "/gpfs/data/oermannlab/users/slj9342/.local/lib/python3.8/site-packages/tornado/web.py", line 1788, in _execute
        result = method(*self.path_args, **self.path_kwargs)
      File "/gpfs/data/oermannlab/users/slj9342/.local/lib/python3.8/site-packages/tornado/web.py", line 3289, in wrapper
        url = self.get_login_url()
      File "/gpfs/data/oermannlab/users/slj9342/.local/lib/python3.8/site-packages/jupyter_server/base/handlers.py", line 783, in get_login_url
        raise web.HTTPError(403)
    tornado.web.HTTPError: HTTP 403: Forbidden
[W 2025-04-24 18:17:58.275 ServerApp] 403 GET /api/kernelspecs?1745533078261 (@192.168.0.104) 0.47ms referer=None
[W 2025-04-24 18:17:58.707 ServerApp] wrote error: 'Forbidden'
    Traceback (most recent call last):
      File "/gpfs/data/oermannlab/users/slj9342/.local/lib/python3.8/site-packages/tornado/web.py", line 1788, in _execute
        result = method(*self.path_args, **self.path_kwargs)
      File "/gpfs/data/oermannlab/users/slj9342/.local/lib/python3.8/site-packages/tornado/web.py", line 3289, in wrapper
        url = self.get_login_url()
      File "/gpfs/data/oermannlab/users/slj9342/.local/lib/python3.8/site-packages/jupyter_server/base/handlers.py", line 783, in get_login_url
        raise web.HTTPError(403)
    tornado.web.HTTPError: HTTP 403: Forbidden
[W 2025-04-24 18:17:58.718 ServerApp] 403 GET /api/kernels?1745533078262 (@192.168.0.104) 11.02ms referer=None
[W 2025-04-24 18:17:58.729 ServerApp] wrote error: 'Forbidden'
    Traceback (most recent call last):
      File "/gpfs/data/oermannlab/users/slj9342/.local/lib/python3.8/site-packages/tornado/web.py", line 1788, in _execute
        result = method(*self.path_args, **self.path_kwargs)
      File "/gpfs/data/oermannlab/users/slj9342/.local/lib/python3.8/site-packages/tornado/web.py", line 3289, in wrapper
        url = self.get_login_url()
      File "/gpfs/data/oermannlab/users/slj9342/.local/lib/python3.8/site-packages/jupyter_server/base/handlers.py", line 783, in get_login_url
        raise web.HTTPError(403)
    tornado.web.HTTPError: HTTP 403: Forbidden
[W 2025-04-24 18:17:58.729 ServerApp] 403 GET /api/kernelspecs?1745533078262 (@192.168.0.104) 22.11ms referer=None
[W 2025-04-24 18:17:58.729 ServerApp] wrote error: 'Forbidden'
    Traceback (most recent call last):
      File "/gpfs/data/oermannlab/users/slj9342/.local/lib/python3.8/site-packages/tornado/web.py", line 1788, in _execute
        result = method(*self.path_args, **self.path_kwargs)
      File "/gpfs/data/oermannlab/users/slj9342/.local/lib/python3.8/site-packages/tornado/web.py", line 3289, in wrapper
        url = self.get_login_url()
      File "/gpfs/data/oermannlab/users/slj9342/.local/lib/python3.8/site-packages/jupyter_server/base/handlers.py", line 783, in get_login_url
        raise web.HTTPError(403)
    tornado.web.HTTPError: HTTP 403: Forbidden
[W 2025-04-24 18:17:58.729 ServerApp] 403 GET /api/kernels?1745533078263 (@192.168.0.104) 22.39ms referer=None
[W 2025-04-24 18:18:01.142 ServerApp] wrote error: 'Forbidden'
    Traceback (most recent call last):
      File "/gpfs/data/oermannlab/users/slj9342/.local/lib/python3.8/site-packages/tornado/web.py", line 1788, in _execute
        result = method(*self.path_args, **self.path_kwargs)
      File "/gpfs/data/oermannlab/users/slj9342/.local/lib/python3.8/site-packages/tornado/web.py", line 3289, in wrapper
        url = self.get_login_url()
      File "/gpfs/data/oermannlab/users/slj9342/.local/lib/python3.8/site-packages/jupyter_server/base/handlers.py", line 783, in get_login_url
        raise web.HTTPError(403)
    tornado.web.HTTPError: HTTP 403: Forbidden
[W 2025-04-24 18:18:01.143 ServerApp] 403 GET /api/kernels?1745533078265 (@192.168.0.104) 0.85ms referer=None
[W 2025-04-24 18:18:01.143 ServerApp] wrote error: 'Forbidden'
    Traceback (most recent call last):
      File "/gpfs/data/oermannlab/users/slj9342/.local/lib/python3.8/site-packages/tornado/web.py", line 1788, in _execute
        result = method(*self.path_args, **self.path_kwargs)
      File "/gpfs/data/oermannlab/users/slj9342/.local/lib/python3.8/site-packages/tornado/web.py", line 3289, in wrapper
        url = self.get_login_url()
      File "/gpfs/data/oermannlab/users/slj9342/.local/lib/python3.8/site-packages/jupyter_server/base/handlers.py", line 783, in get_login_url
        raise web.HTTPError(403)
    tornado.web.HTTPError: HTTP 403: Forbidden
[W 2025-04-24 18:18:01.144 ServerApp] 403 GET /api/sessions?1745533078267 (@192.168.0.104) 0.70ms referer=None
[W 2025-04-24 18:18:01.144 ServerApp] wrote error: 'Forbidden'
    Traceback (most recent call last):
      File "/gpfs/data/oermannlab/users/slj9342/.local/lib/python3.8/site-packages/tornado/web.py", line 1788, in _execute
        result = method(*self.path_args, **self.path_kwargs)
      File "/gpfs/data/oermannlab/users/slj9342/.local/lib/python3.8/site-packages/tornado/web.py", line 3289, in wrapper
        url = self.get_login_url()
      File "/gpfs/data/oermannlab/users/slj9342/.local/lib/python3.8/site-packages/jupyter_server/base/handlers.py", line 783, in get_login_url
        raise web.HTTPError(403)
    tornado.web.HTTPError: HTTP 403: Forbidden
[W 2025-04-24 18:18:01.144 ServerApp] 403 GET /api/kernels?1745533078268 (@192.168.0.104) 0.94ms referer=None
[W 2025-04-24 18:18:01.144 ServerApp] wrote error: 'Forbidden'
    Traceback (most recent call last):
      File "/gpfs/data/oermannlab/users/slj9342/.local/lib/python3.8/site-packages/tornado/web.py", line 1788, in _execute
        result = method(*self.path_args, **self.path_kwargs)
      File "/gpfs/data/oermannlab/users/slj9342/.local/lib/python3.8/site-packages/tornado/web.py", line 3289, in wrapper
        url = self.get_login_url()
      File "/gpfs/data/oermannlab/users/slj9342/.local/lib/python3.8/site-packages/jupyter_server/base/handlers.py", line 783, in get_login_url
        raise web.HTTPError(403)
    tornado.web.HTTPError: HTTP 403: Forbidden
[W 2025-04-24 18:18:01.155 ServerApp] 403 GET /api/sessions?1745533078269 (@192.168.0.104) 10.61ms referer=None
[W 2025-04-24 18:18:01.461 ServerApp] wrote error: 'Forbidden'
    Traceback (most recent call last):
      File "/gpfs/data/oermannlab/users/slj9342/.local/lib/python3.8/site-packages/tornado/web.py", line 1788, in _execute
        result = method(*self.path_args, **self.path_kwargs)
      File "/gpfs/data/oermannlab/users/slj9342/.local/lib/python3.8/site-packages/tornado/web.py", line 3289, in wrapper
        url = self.get_login_url()
      File "/gpfs/data/oermannlab/users/slj9342/.local/lib/python3.8/site-packages/jupyter_server/base/handlers.py", line 783, in get_login_url
        raise web.HTTPError(403)
    tornado.web.HTTPError: HTTP 403: Forbidden
[W 2025-04-24 18:18:01.461 ServerApp] 403 GET /api/kernelspecs?1745533081194 (@192.168.0.104) 0.62ms referer=None
[W 2025-04-24 18:18:01.461 ServerApp] wrote error: 'Forbidden'
    Traceback (most recent call last):
      File "/gpfs/data/oermannlab/users/slj9342/.local/lib/python3.8/site-packages/tornado/web.py", line 1788, in _execute
        result = method(*self.path_args, **self.path_kwargs)
      File "/gpfs/data/oermannlab/users/slj9342/.local/lib/python3.8/site-packages/tornado/web.py", line 3289, in wrapper
        url = self.get_login_url()
      File "/gpfs/data/oermannlab/users/slj9342/.local/lib/python3.8/site-packages/jupyter_server/base/handlers.py", line 783, in get_login_url
        raise web.HTTPError(403)
    tornado.web.HTTPError: HTTP 403: Forbidden
[W 2025-04-24 18:18:01.462 ServerApp] 403 GET /api/kernelspecs?1745533081196 (@192.168.0.104) 0.89ms referer=None
[I 2025-04-24 18:18:03.581 ServerApp] 302 GET / (@192.168.0.104) 0.31ms
[I 2025-04-24 18:18:03.632 JupyterNotebookApp] 302 GET /tree? (@192.168.0.104) 0.35ms
[W 2025-04-24 18:18:03.773 ServerApp] wrote error: 'Forbidden'
    Traceback (most recent call last):
      File "/gpfs/data/oermannlab/users/slj9342/.local/lib/python3.8/site-packages/tornado/web.py", line 1788, in _execute
        result = method(*self.path_args, **self.path_kwargs)
      File "/gpfs/data/oermannlab/users/slj9342/.local/lib/python3.8/site-packages/tornado/web.py", line 3289, in wrapper
        url = self.get_login_url()
      File "/gpfs/data/oermannlab/users/slj9342/.local/lib/python3.8/site-packages/jupyter_server/base/handlers.py", line 783, in get_login_url
        raise web.HTTPError(403)
    tornado.web.HTTPError: HTTP 403: Forbidden
[W 2025-04-24 18:18:03.773 ServerApp] 403 GET /api/kernelspecs?1745533083769 (@192.168.0.104) 0.56ms referer=None
[W 2025-04-24 18:18:03.795 ServerApp] wrote error: 'Forbidden'
    Traceback (most recent call last):
      File "/gpfs/data/oermannlab/users/slj9342/.local/lib/python3.8/site-packages/tornado/web.py", line 1788, in _execute
        result = method(*self.path_args, **self.path_kwargs)
      File "/gpfs/data/oermannlab/users/slj9342/.local/lib/python3.8/site-packages/tornado/web.py", line 3289, in wrapper
        url = self.get_login_url()
      File "/gpfs/data/oermannlab/users/slj9342/.local/lib/python3.8/site-packages/jupyter_server/base/handlers.py", line 783, in get_login_url
        raise web.HTTPError(403)
    tornado.web.HTTPError: HTTP 403: Forbidden
[W 2025-04-24 18:18:03.795 ServerApp] 403 GET /api/kernelspecs?1745533083782 (@192.168.0.104) 0.56ms referer=None
[W 2025-04-24 18:18:03.796 ServerApp] wrote error: 'Forbidden'
    Traceback (most recent call last):
      File "/gpfs/data/oermannlab/users/slj9342/.local/lib/python3.8/site-packages/tornado/web.py", line 1788, in _execute
        result = method(*self.path_args, **self.path_kwargs)
      File "/gpfs/data/oermannlab/users/slj9342/.local/lib/python3.8/site-packages/tornado/web.py", line 3289, in wrapper
        url = self.get_login_url()
      File "/gpfs/data/oermannlab/users/slj9342/.local/lib/python3.8/site-packages/jupyter_server/base/handlers.py", line 783, in get_login_url
        raise web.HTTPError(403)
    tornado.web.HTTPError: HTTP 403: Forbidden
[W 2025-04-24 18:18:03.811 ServerApp] 403 GET /api/kernels?1745533083770 (@192.168.0.104) 15.13ms referer=None
[W 2025-04-24 18:18:03.811 ServerApp] wrote error: 'Forbidden'
    Traceback (most recent call last):
      File "/gpfs/data/oermannlab/users/slj9342/.local/lib/python3.8/site-packages/tornado/web.py", line 1788, in _execute
        result = method(*self.path_args, **self.path_kwargs)
      File "/gpfs/data/oermannlab/users/slj9342/.local/lib/python3.8/site-packages/tornado/web.py", line 3289, in wrapper
        url = self.get_login_url()
      File "/gpfs/data/oermannlab/users/slj9342/.local/lib/python3.8/site-packages/jupyter_server/base/handlers.py", line 783, in get_login_url
        raise web.HTTPError(403)
    tornado.web.HTTPError: HTTP 403: Forbidden
[W 2025-04-24 18:18:03.811 ServerApp] 403 GET /api/kernelspecs?1745533083770 (@192.168.0.104) 15.41ms referer=None
[W 2025-04-24 18:18:03.811 ServerApp] wrote error: 'Forbidden'
    Traceback (most recent call last):
      File "/gpfs/data/oermannlab/users/slj9342/.local/lib/python3.8/site-packages/tornado/web.py", line 1788, in _execute
        result = method(*self.path_args, **self.path_kwargs)
      File "/gpfs/data/oermannlab/users/slj9342/.local/lib/python3.8/site-packages/tornado/web.py", line 3289, in wrapper
        url = self.get_login_url()
      File "/gpfs/data/oermannlab/users/slj9342/.local/lib/python3.8/site-packages/jupyter_server/base/handlers.py", line 783, in get_login_url
        raise web.HTTPError(403)
    tornado.web.HTTPError: HTTP 403: Forbidden
[W 2025-04-24 18:18:03.811 ServerApp] 403 GET /api/kernels?1745533083771 (@192.168.0.104) 15.70ms referer=None
[W 2025-04-24 18:18:03.812 ServerApp] wrote error: 'Forbidden'
    Traceback (most recent call last):
      File "/gpfs/data/oermannlab/users/slj9342/.local/lib/python3.8/site-packages/tornado/web.py", line 1788, in _execute
        result = method(*self.path_args, **self.path_kwargs)
      File "/gpfs/data/oermannlab/users/slj9342/.local/lib/python3.8/site-packages/tornado/web.py", line 3289, in wrapper
        url = self.get_login_url()
      File "/gpfs/data/oermannlab/users/slj9342/.local/lib/python3.8/site-packages/jupyter_server/base/handlers.py", line 783, in get_login_url
        raise web.HTTPError(403)
    tornado.web.HTTPError: HTTP 403: Forbidden
[W 2025-04-24 18:18:03.812 ServerApp] 403 GET /api/kernels?1745533083773 (@192.168.0.104) 15.98ms referer=None
[W 2025-04-24 18:18:03.812 ServerApp] wrote error: 'Forbidden'
    Traceback (most recent call last):
      File "/gpfs/data/oermannlab/users/slj9342/.local/lib/python3.8/site-packages/tornado/web.py", line 1788, in _execute
        result = method(*self.path_args, **self.path_kwargs)
      File "/gpfs/data/oermannlab/users/slj9342/.local/lib/python3.8/site-packages/tornado/web.py", line 3289, in wrapper
        url = self.get_login_url()
      File "/gpfs/data/oermannlab/users/slj9342/.local/lib/python3.8/site-packages/jupyter_server/base/handlers.py", line 783, in get_login_url
        raise web.HTTPError(403)
    tornado.web.HTTPError: HTTP 403: Forbidden
[W 2025-04-24 18:18:03.812 ServerApp] 403 GET /api/sessions?1745533083774 (@192.168.0.104) 16.25ms referer=None
[W 2025-04-24 18:18:03.812 ServerApp] wrote error: 'Forbidden'
    Traceback (most recent call last):
      File "/gpfs/data/oermannlab/users/slj9342/.local/lib/python3.8/site-packages/tornado/web.py", line 1788, in _execute
        result = method(*self.path_args, **self.path_kwargs)
      File "/gpfs/data/oermannlab/users/slj9342/.local/lib/python3.8/site-packages/tornado/web.py", line 3289, in wrapper
        url = self.get_login_url()
      File "/gpfs/data/oermannlab/users/slj9342/.local/lib/python3.8/site-packages/jupyter_server/base/handlers.py", line 783, in get_login_url
        raise web.HTTPError(403)
    tornado.web.HTTPError: HTTP 403: Forbidden
[W 2025-04-24 18:18:03.817 ServerApp] 403 GET /api/kernels?1745533083774 (@192.168.0.104) 20.58ms referer=None
[W 2025-04-24 18:18:03.817 ServerApp] wrote error: 'Forbidden'
    Traceback (most recent call last):
      File "/gpfs/data/oermannlab/users/slj9342/.local/lib/python3.8/site-packages/tornado/web.py", line 1788, in _execute
        result = method(*self.path_args, **self.path_kwargs)
      File "/gpfs/data/oermannlab/users/slj9342/.local/lib/python3.8/site-packages/tornado/web.py", line 3289, in wrapper
        url = self.get_login_url()
      File "/gpfs/data/oermannlab/users/slj9342/.local/lib/python3.8/site-packages/jupyter_server/base/handlers.py", line 783, in get_login_url
        raise web.HTTPError(403)
    tornado.web.HTTPError: HTTP 403: Forbidden
[W 2025-04-24 18:18:03.817 ServerApp] 403 GET /api/sessions?1745533083775 (@192.168.0.104) 20.86ms referer=None
[W 2025-04-24 18:18:03.828 ServerApp] wrote error: 'Forbidden'
    Traceback (most recent call last):
      File "/gpfs/data/oermannlab/users/slj9342/.local/lib/python3.8/site-packages/tornado/web.py", line 1788, in _execute
        result = method(*self.path_args, **self.path_kwargs)
      File "/gpfs/data/oermannlab/users/slj9342/.local/lib/python3.8/site-packages/tornado/web.py", line 3289, in wrapper
        url = self.get_login_url()
      File "/gpfs/data/oermannlab/users/slj9342/.local/lib/python3.8/site-packages/jupyter_server/base/handlers.py", line 783, in get_login_url
        raise web.HTTPError(403)
    tornado.web.HTTPError: HTTP 403: Forbidden
[W 2025-04-24 18:18:03.828 ServerApp] 403 GET /api/kernelspecs?1745533083817 (@192.168.0.104) 0.49ms referer=None
[W 2025-04-24 18:18:10.331 ServerApp] 401 POST /login? (@192.168.0.104) 0.72ms referer=None
[W 2025-04-24 18:18:10.340 ServerApp] wrote error: 'Forbidden'
    Traceback (most recent call last):
      File "/gpfs/data/oermannlab/users/slj9342/.local/lib/python3.8/site-packages/tornado/web.py", line 1788, in _execute
        result = method(*self.path_args, **self.path_kwargs)
      File "/gpfs/data/oermannlab/users/slj9342/.local/lib/python3.8/site-packages/tornado/web.py", line 3289, in wrapper
        url = self.get_login_url()
      File "/gpfs/data/oermannlab/users/slj9342/.local/lib/python3.8/site-packages/jupyter_server/base/handlers.py", line 783, in get_login_url
        raise web.HTTPError(403)
    tornado.web.HTTPError: HTTP 403: Forbidden
[W 2025-04-24 18:18:10.341 ServerApp] 403 GET /api/kernelspecs?1745533090336 (@192.168.0.104) 0.54ms referer=None
[W 2025-04-24 18:18:10.352 ServerApp] wrote error: 'Forbidden'
    Traceback (most recent call last):
      File "/gpfs/data/oermannlab/users/slj9342/.local/lib/python3.8/site-packages/tornado/web.py", line 1788, in _execute
        result = method(*self.path_args, **self.path_kwargs)
      File "/gpfs/data/oermannlab/users/slj9342/.local/lib/python3.8/site-packages/tornado/web.py", line 3289, in wrapper
        url = self.get_login_url()
      File "/gpfs/data/oermannlab/users/slj9342/.local/lib/python3.8/site-packages/jupyter_server/base/handlers.py", line 783, in get_login_url
        raise web.HTTPError(403)
    tornado.web.HTTPError: HTTP 403: Forbidden
[W 2025-04-24 18:18:10.353 ServerApp] 403 GET /api/kernels?1745533090337 (@192.168.0.104) 0.89ms referer=None
[W 2025-04-24 18:18:10.353 ServerApp] wrote error: 'Forbidden'
    Traceback (most recent call last):
      File "/gpfs/data/oermannlab/users/slj9342/.local/lib/python3.8/site-packages/tornado/web.py", line 1788, in _execute
        result = method(*self.path_args, **self.path_kwargs)
      File "/gpfs/data/oermannlab/users/slj9342/.local/lib/python3.8/site-packages/tornado/web.py", line 3289, in wrapper
        url = self.get_login_url()
      File "/gpfs/data/oermannlab/users/slj9342/.local/lib/python3.8/site-packages/jupyter_server/base/handlers.py", line 783, in get_login_url
        raise web.HTTPError(403)
    tornado.web.HTTPError: HTTP 403: Forbidden
[W 2025-04-24 18:18:10.353 ServerApp] 403 GET /api/sessions?1745533090340 (@192.168.0.104) 1.11ms referer=None
[W 2025-04-24 18:18:10.353 ServerApp] wrote error: 'Forbidden'
    Traceback (most recent call last):
      File "/gpfs/data/oermannlab/users/slj9342/.local/lib/python3.8/site-packages/tornado/web.py", line 1788, in _execute
        result = method(*self.path_args, **self.path_kwargs)
      File "/gpfs/data/oermannlab/users/slj9342/.local/lib/python3.8/site-packages/tornado/web.py", line 3289, in wrapper
        url = self.get_login_url()
      File "/gpfs/data/oermannlab/users/slj9342/.local/lib/python3.8/site-packages/jupyter_server/base/handlers.py", line 783, in get_login_url
        raise web.HTTPError(403)
    tornado.web.HTTPError: HTTP 403: Forbidden
[W 2025-04-24 18:18:10.353 ServerApp] 403 GET /api/kernels?1745533090339 (@192.168.0.104) 1.32ms referer=None
[W 2025-04-24 18:18:10.354 ServerApp] wrote error: 'Forbidden'
    Traceback (most recent call last):
      File "/gpfs/data/oermannlab/users/slj9342/.local/lib/python3.8/site-packages/tornado/web.py", line 1788, in _execute
        result = method(*self.path_args, **self.path_kwargs)
      File "/gpfs/data/oermannlab/users/slj9342/.local/lib/python3.8/site-packages/tornado/web.py", line 3289, in wrapper
        url = self.get_login_url()
      File "/gpfs/data/oermannlab/users/slj9342/.local/lib/python3.8/site-packages/jupyter_server/base/handlers.py", line 783, in get_login_url
        raise web.HTTPError(403)
    tornado.web.HTTPError: HTTP 403: Forbidden
[W 2025-04-24 18:18:10.354 ServerApp] 403 GET /api/kernelspecs?1745533090347 (@192.168.0.104) 0.46ms referer=None
[I 2025-04-24 18:18:54.726 ServerApp] 302 GET / (@192.168.0.104) 0.52ms
[I 2025-04-24 18:18:54.737 ServerApp] 302 GET / (@192.168.0.104) 10.78ms
[I 2025-04-24 18:18:54.737 ServerApp] 302 GET / (@192.168.0.104) 10.83ms
[I 2025-04-24 18:18:54.786 JupyterNotebookApp] 302 GET /tree? (@192.168.0.104) 0.38ms
[I 2025-04-24 18:18:54.786 JupyterNotebookApp] 302 GET /tree? (@192.168.0.104) 0.29ms
[I 2025-04-24 18:18:54.787 JupyterNotebookApp] 302 GET /tree? (@192.168.0.104) 0.29ms
[W 2025-04-24 18:18:54.876 ServerApp] wrote error: 'Forbidden'
    Traceback (most recent call last):
      File "/gpfs/data/oermannlab/users/slj9342/.local/lib/python3.8/site-packages/tornado/web.py", line 1788, in _execute
        result = method(*self.path_args, **self.path_kwargs)
      File "/gpfs/data/oermannlab/users/slj9342/.local/lib/python3.8/site-packages/tornado/web.py", line 3289, in wrapper
        url = self.get_login_url()
      File "/gpfs/data/oermannlab/users/slj9342/.local/lib/python3.8/site-packages/jupyter_server/base/handlers.py", line 783, in get_login_url
        raise web.HTTPError(403)
    tornado.web.HTTPError: HTTP 403: Forbidden
[W 2025-04-24 18:18:54.876 ServerApp] 403 GET /api/sessions?1745533134869 (@192.168.0.104) 1.83ms referer=None
[W 2025-04-24 18:18:54.876 ServerApp] wrote error: 'Forbidden'
    Traceback (most recent call last):
      File "/gpfs/data/oermannlab/users/slj9342/.local/lib/python3.8/site-packages/tornado/web.py", line 1788, in _execute
        result = method(*self.path_args, **self.path_kwargs)
      File "/gpfs/data/oermannlab/users/slj9342/.local/lib/python3.8/site-packages/tornado/web.py", line 3289, in wrapper
        url = self.get_login_url()
      File "/gpfs/data/oermannlab/users/slj9342/.local/lib/python3.8/site-packages/jupyter_server/base/handlers.py", line 783, in get_login_url
        raise web.HTTPError(403)
    tornado.web.HTTPError: HTTP 403: Forbidden
[W 2025-04-24 18:18:54.876 ServerApp] 403 GET /api/kernels?1745533134867 (@192.168.0.104) 2.01ms referer=None
[W 2025-04-24 18:18:54.877 ServerApp] wrote error: 'Forbidden'
    Traceback (most recent call last):
      File "/gpfs/data/oermannlab/users/slj9342/.local/lib/python3.8/site-packages/tornado/web.py", line 1788, in _execute
        result = method(*self.path_args, **self.path_kwargs)
      File "/gpfs/data/oermannlab/users/slj9342/.local/lib/python3.8/site-packages/tornado/web.py", line 3289, in wrapper
        url = self.get_login_url()
      File "/gpfs/data/oermannlab/users/slj9342/.local/lib/python3.8/site-packages/jupyter_server/base/handlers.py", line 783, in get_login_url
        raise web.HTTPError(403)
    tornado.web.HTTPError: HTTP 403: Forbidden
[W 2025-04-24 18:18:54.877 ServerApp] 403 GET /api/kernels?1745533134869 (@192.168.0.104) 2.22ms referer=None
[W 2025-04-24 18:18:54.877 ServerApp] wrote error: 'Forbidden'
    Traceback (most recent call last):
      File "/gpfs/data/oermannlab/users/slj9342/.local/lib/python3.8/site-packages/tornado/web.py", line 1788, in _execute
        result = method(*self.path_args, **self.path_kwargs)
      File "/gpfs/data/oermannlab/users/slj9342/.local/lib/python3.8/site-packages/tornado/web.py", line 3289, in wrapper
        url = self.get_login_url()
      File "/gpfs/data/oermannlab/users/slj9342/.local/lib/python3.8/site-packages/jupyter_server/base/handlers.py", line 783, in get_login_url
        raise web.HTTPError(403)
    tornado.web.HTTPError: HTTP 403: Forbidden
[W 2025-04-24 18:18:54.877 ServerApp] 403 GET /api/kernels?1745533134868 (@192.168.0.104) 2.44ms referer=None
[W 2025-04-24 18:18:54.877 ServerApp] wrote error: 'Forbidden'
    Traceback (most recent call last):
      File "/gpfs/data/oermannlab/users/slj9342/.local/lib/python3.8/site-packages/tornado/web.py", line 1788, in _execute
        result = method(*self.path_args, **self.path_kwargs)
      File "/gpfs/data/oermannlab/users/slj9342/.local/lib/python3.8/site-packages/tornado/web.py", line 3289, in wrapper
        url = self.get_login_url()
      File "/gpfs/data/oermannlab/users/slj9342/.local/lib/python3.8/site-packages/jupyter_server/base/handlers.py", line 783, in get_login_url
        raise web.HTTPError(403)
    tornado.web.HTTPError: HTTP 403: Forbidden
[W 2025-04-24 18:18:54.878 ServerApp] 403 GET /api/sessions?1745533134870 (@192.168.0.104) 2.68ms referer=None
[W 2025-04-24 18:18:54.878 ServerApp] wrote error: 'Forbidden'
    Traceback (most recent call last):
      File "/gpfs/data/oermannlab/users/slj9342/.local/lib/python3.8/site-packages/tornado/web.py", line 1788, in _execute
        result = method(*self.path_args, **self.path_kwargs)
      File "/gpfs/data/oermannlab/users/slj9342/.local/lib/python3.8/site-packages/tornado/web.py", line 3289, in wrapper
        url = self.get_login_url()
      File "/gpfs/data/oermannlab/users/slj9342/.local/lib/python3.8/site-packages/jupyter_server/base/handlers.py", line 783, in get_login_url
        raise web.HTTPError(403)
    tornado.web.HTTPError: HTTP 403: Forbidden
[W 2025-04-24 18:18:54.878 ServerApp] 403 GET /api/kernelspecs?1745533134865 (@192.168.0.104) 2.94ms referer=None
[W 2025-04-24 18:18:54.878 ServerApp] wrote error: 'Forbidden'
    Traceback (most recent call last):
      File "/gpfs/data/oermannlab/users/slj9342/.local/lib/python3.8/site-packages/tornado/web.py", line 1788, in _execute
        result = method(*self.path_args, **self.path_kwargs)
      File "/gpfs/data/oermannlab/users/slj9342/.local/lib/python3.8/site-packages/tornado/web.py", line 3289, in wrapper
        url = self.get_login_url()
      File "/gpfs/data/oermannlab/users/slj9342/.local/lib/python3.8/site-packages/jupyter_server/base/handlers.py", line 783, in get_login_url
        raise web.HTTPError(403)
    tornado.web.HTTPError: HTTP 403: Forbidden
[W 2025-04-24 18:18:54.878 ServerApp] 403 GET /api/kernels?1745533134866 (@192.168.0.104) 3.21ms referer=None
[W 2025-04-24 18:18:54.879 ServerApp] wrote error: 'Forbidden'
    Traceback (most recent call last):
      File "/gpfs/data/oermannlab/users/slj9342/.local/lib/python3.8/site-packages/tornado/web.py", line 1788, in _execute
        result = method(*self.path_args, **self.path_kwargs)
      File "/gpfs/data/oermannlab/users/slj9342/.local/lib/python3.8/site-packages/tornado/web.py", line 3289, in wrapper
        url = self.get_login_url()
      File "/gpfs/data/oermannlab/users/slj9342/.local/lib/python3.8/site-packages/jupyter_server/base/handlers.py", line 783, in get_login_url
        raise web.HTTPError(403)
    tornado.web.HTTPError: HTTP 403: Forbidden
[W 2025-04-24 18:18:54.879 ServerApp] 403 GET /api/kernelspecs?1745533134866 (@192.168.0.104) 3.61ms referer=None
[I 2025-04-24 18:18:54.891 ServerApp] 302 GET / (@192.168.0.104) 0.76ms
[W 2025-04-24 18:18:54.891 ServerApp] wrote error: 'Forbidden'
    Traceback (most recent call last):
      File "/gpfs/data/oermannlab/users/slj9342/.local/lib/python3.8/site-packages/tornado/web.py", line 1788, in _execute
        result = method(*self.path_args, **self.path_kwargs)
      File "/gpfs/data/oermannlab/users/slj9342/.local/lib/python3.8/site-packages/tornado/web.py", line 3289, in wrapper
        url = self.get_login_url()
      File "/gpfs/data/oermannlab/users/slj9342/.local/lib/python3.8/site-packages/jupyter_server/base/handlers.py", line 783, in get_login_url
        raise web.HTTPError(403)
    tornado.web.HTTPError: HTTP 403: Forbidden
[W 2025-04-24 18:18:54.891 ServerApp] 403 GET /api/kernelspecs?1745533134879 (@192.168.0.104) 0.98ms referer=None
[W 2025-04-24 18:18:54.891 ServerApp] wrote error: 'Forbidden'
    Traceback (most recent call last):
      File "/gpfs/data/oermannlab/users/slj9342/.local/lib/python3.8/site-packages/tornado/web.py", line 1788, in _execute
        result = method(*self.path_args, **self.path_kwargs)
      File "/gpfs/data/oermannlab/users/slj9342/.local/lib/python3.8/site-packages/tornado/web.py", line 3289, in wrapper
        url = self.get_login_url()
      File "/gpfs/data/oermannlab/users/slj9342/.local/lib/python3.8/site-packages/jupyter_server/base/handlers.py", line 783, in get_login_url
        raise web.HTTPError(403)
    tornado.web.HTTPError: HTTP 403: Forbidden
[W 2025-04-24 18:18:54.891 ServerApp] 403 GET /api/sessions?1745533134880 (@192.168.0.104) 1.19ms referer=None
[I 2025-04-24 18:18:54.891 ServerApp] 302 GET / (@192.168.0.104) 1.17ms
[I 2025-04-24 18:18:54.896 JupyterNotebookApp] 302 GET /tree? (@192.168.0.104) 0.40ms
[I 2025-04-24 18:18:54.896 JupyterNotebookApp] 302 GET /tree? (@192.168.0.104) 0.45ms
[W 2025-04-24 18:18:54.974 ServerApp] wrote error: 'Forbidden'
    Traceback (most recent call last):
      File "/gpfs/data/oermannlab/users/slj9342/.local/lib/python3.8/site-packages/tornado/web.py", line 1788, in _execute
        result = method(*self.path_args, **self.path_kwargs)
      File "/gpfs/data/oermannlab/users/slj9342/.local/lib/python3.8/site-packages/tornado/web.py", line 3289, in wrapper
        url = self.get_login_url()
      File "/gpfs/data/oermannlab/users/slj9342/.local/lib/python3.8/site-packages/jupyter_server/base/handlers.py", line 783, in get_login_url
        raise web.HTTPError(403)
    tornado.web.HTTPError: HTTP 403: Forbidden
[W 2025-04-24 18:18:54.974 ServerApp] 403 GET /api/kernelspecs?1745533134970 (@192.168.0.104) 0.48ms referer=None
[W 2025-04-24 18:18:54.974 ServerApp] wrote error: 'Forbidden'
    Traceback (most recent call last):
      File "/gpfs/data/oermannlab/users/slj9342/.local/lib/python3.8/site-packages/tornado/web.py", line 1788, in _execute
        result = method(*self.path_args, **self.path_kwargs)
      File "/gpfs/data/oermannlab/users/slj9342/.local/lib/python3.8/site-packages/tornado/web.py", line 3289, in wrapper
        url = self.get_login_url()
      File "/gpfs/data/oermannlab/users/slj9342/.local/lib/python3.8/site-packages/jupyter_server/base/handlers.py", line 783, in get_login_url
        raise web.HTTPError(403)
    tornado.web.HTTPError: HTTP 403: Forbidden
[W 2025-04-24 18:18:54.975 ServerApp] 403 GET /api/kernels?1745533134971 (@192.168.0.104) 0.46ms referer=None
[W 2025-04-24 18:18:54.986 ServerApp] wrote error: 'Forbidden'
    Traceback (most recent call last):
      File "/gpfs/data/oermannlab/users/slj9342/.local/lib/python3.8/site-packages/tornado/web.py", line 1788, in _execute
        result = method(*self.path_args, **self.path_kwargs)
      File "/gpfs/data/oermannlab/users/slj9342/.local/lib/python3.8/site-packages/tornado/web.py", line 3289, in wrapper
        url = self.get_login_url()
      File "/gpfs/data/oermannlab/users/slj9342/.local/lib/python3.8/site-packages/jupyter_server/base/handlers.py", line 783, in get_login_url
        raise web.HTTPError(403)
    tornado.web.HTTPError: HTTP 403: Forbidden
[W 2025-04-24 18:18:54.987 ServerApp] 403 GET /api/kernelspecs?1745533134971 (@192.168.0.104) 1.50ms referer=None
[W 2025-04-24 18:18:54.987 ServerApp] wrote error: 'Forbidden'
    Traceback (most recent call last):
      File "/gpfs/data/oermannlab/users/slj9342/.local/lib/python3.8/site-packages/tornado/web.py", line 1788, in _execute
        result = method(*self.path_args, **self.path_kwargs)
      File "/gpfs/data/oermannlab/users/slj9342/.local/lib/python3.8/site-packages/tornado/web.py", line 3289, in wrapper
        url = self.get_login_url()
      File "/gpfs/data/oermannlab/users/slj9342/.local/lib/python3.8/site-packages/jupyter_server/base/handlers.py", line 783, in get_login_url
        raise web.HTTPError(403)
    tornado.web.HTTPError: HTTP 403: Forbidden
[W 2025-04-24 18:18:54.987 ServerApp] 403 GET /api/kernels?1745533134972 (@192.168.0.104) 1.70ms referer=None
[W 2025-04-24 18:18:54.987 ServerApp] wrote error: 'Forbidden'
    Traceback (most recent call last):
      File "/gpfs/data/oermannlab/users/slj9342/.local/lib/python3.8/site-packages/tornado/web.py", line 1788, in _execute
        result = method(*self.path_args, **self.path_kwargs)
      File "/gpfs/data/oermannlab/users/slj9342/.local/lib/python3.8/site-packages/tornado/web.py", line 3289, in wrapper
        url = self.get_login_url()
      File "/gpfs/data/oermannlab/users/slj9342/.local/lib/python3.8/site-packages/jupyter_server/base/handlers.py", line 783, in get_login_url
        raise web.HTTPError(403)
    tornado.web.HTTPError: HTTP 403: Forbidden
[W 2025-04-24 18:18:54.988 ServerApp] 403 GET /api/kernels?1745533134975 (@192.168.0.104) 1.94ms referer=None
[W 2025-04-24 18:18:54.988 ServerApp] wrote error: 'Forbidden'
    Traceback (most recent call last):
      File "/gpfs/data/oermannlab/users/slj9342/.local/lib/python3.8/site-packages/tornado/web.py", line 1788, in _execute
        result = method(*self.path_args, **self.path_kwargs)
      File "/gpfs/data/oermannlab/users/slj9342/.local/lib/python3.8/site-packages/tornado/web.py", line 3289, in wrapper
        url = self.get_login_url()
      File "/gpfs/data/oermannlab/users/slj9342/.local/lib/python3.8/site-packages/jupyter_server/base/handlers.py", line 783, in get_login_url
        raise web.HTTPError(403)
    tornado.web.HTTPError: HTTP 403: Forbidden
[W 2025-04-24 18:18:54.988 ServerApp] 403 GET /api/kernels?1745533134974 (@192.168.0.104) 2.16ms referer=None
[W 2025-04-24 18:18:54.988 ServerApp] wrote error: 'Forbidden'
    Traceback (most recent call last):
      File "/gpfs/data/oermannlab/users/slj9342/.local/lib/python3.8/site-packages/tornado/web.py", line 1788, in _execute
        result = method(*self.path_args, **self.path_kwargs)
      File "/gpfs/data/oermannlab/users/slj9342/.local/lib/python3.8/site-packages/tornado/web.py", line 3289, in wrapper
        url = self.get_login_url()
      File "/gpfs/data/oermannlab/users/slj9342/.local/lib/python3.8/site-packages/jupyter_server/base/handlers.py", line 783, in get_login_url
        raise web.HTTPError(403)
    tornado.web.HTTPError: HTTP 403: Forbidden
[W 2025-04-24 18:18:54.988 ServerApp] 403 GET /api/sessions?1745533134975 (@192.168.0.104) 2.39ms referer=None
[W 2025-04-24 18:18:54.989 ServerApp] wrote error: 'Forbidden'
    Traceback (most recent call last):
      File "/gpfs/data/oermannlab/users/slj9342/.local/lib/python3.8/site-packages/tornado/web.py", line 1788, in _execute
        result = method(*self.path_args, **self.path_kwargs)
      File "/gpfs/data/oermannlab/users/slj9342/.local/lib/python3.8/site-packages/tornado/web.py", line 3289, in wrapper
        url = self.get_login_url()
      File "/gpfs/data/oermannlab/users/slj9342/.local/lib/python3.8/site-packages/jupyter_server/base/handlers.py", line 783, in get_login_url
        raise web.HTTPError(403)
    tornado.web.HTTPError: HTTP 403: Forbidden
[W 2025-04-24 18:18:54.989 ServerApp] 403 GET /api/sessions?1745533134976 (@192.168.0.104) 2.60ms referer=None
[W 2025-04-24 18:18:54.989 ServerApp] wrote error: 'Forbidden'
    Traceback (most recent call last):
      File "/gpfs/data/oermannlab/users/slj9342/.local/lib/python3.8/site-packages/tornado/web.py", line 1788, in _execute
        result = method(*self.path_args, **self.path_kwargs)
      File "/gpfs/data/oermannlab/users/slj9342/.local/lib/python3.8/site-packages/tornado/web.py", line 3289, in wrapper
        url = self.get_login_url()
      File "/gpfs/data/oermannlab/users/slj9342/.local/lib/python3.8/site-packages/jupyter_server/base/handlers.py", line 783, in get_login_url
        raise web.HTTPError(403)
    tornado.web.HTTPError: HTTP 403: Forbidden
[W 2025-04-24 18:18:54.989 ServerApp] 403 GET /api/kernelspecs?1745533134979 (@192.168.0.104) 2.81ms referer=None
[W 2025-04-24 18:18:54.996 ServerApp] wrote error: 'Forbidden'
    Traceback (most recent call last):
      File "/gpfs/data/oermannlab/users/slj9342/.local/lib/python3.8/site-packages/tornado/web.py", line 1788, in _execute
        result = method(*self.path_args, **self.path_kwargs)
      File "/gpfs/data/oermannlab/users/slj9342/.local/lib/python3.8/site-packages/tornado/web.py", line 3289, in wrapper
        url = self.get_login_url()
      File "/gpfs/data/oermannlab/users/slj9342/.local/lib/python3.8/site-packages/jupyter_server/base/handlers.py", line 783, in get_login_url
        raise web.HTTPError(403)
    tornado.web.HTTPError: HTTP 403: Forbidden
[W 2025-04-24 18:18:54.996 ServerApp] 403 GET /api/kernelspecs?1745533134988 (@192.168.0.104) 0.66ms referer=None
[I 2025-04-24 18:18:54.997 ServerApp] 302 GET / (@192.168.0.104) 0.62ms
[I 2025-04-24 18:18:55.007 JupyterNotebookApp] 302 GET /tree? (@192.168.0.104) 0.28ms
[W 2025-04-24 18:18:55.051 ServerApp] wrote error: 'Forbidden'
    Traceback (most recent call last):
      File "/gpfs/data/oermannlab/users/slj9342/.local/lib/python3.8/site-packages/tornado/web.py", line 1788, in _execute
        result = method(*self.path_args, **self.path_kwargs)
      File "/gpfs/data/oermannlab/users/slj9342/.local/lib/python3.8/site-packages/tornado/web.py", line 3289, in wrapper
        url = self.get_login_url()
      File "/gpfs/data/oermannlab/users/slj9342/.local/lib/python3.8/site-packages/jupyter_server/base/handlers.py", line 783, in get_login_url
        raise web.HTTPError(403)
    tornado.web.HTTPError: HTTP 403: Forbidden
[W 2025-04-24 18:18:55.052 ServerApp] 403 GET /api/kernels?1745533135045 (@192.168.0.104) 0.94ms referer=None
[W 2025-04-24 18:18:55.052 ServerApp] wrote error: 'Forbidden'
    Traceback (most recent call last):
      File "/gpfs/data/oermannlab/users/slj9342/.local/lib/python3.8/site-packages/tornado/web.py", line 1788, in _execute
        result = method(*self.path_args, **self.path_kwargs)
      File "/gpfs/data/oermannlab/users/slj9342/.local/lib/python3.8/site-packages/tornado/web.py", line 3289, in wrapper
        url = self.get_login_url()
      File "/gpfs/data/oermannlab/users/slj9342/.local/lib/python3.8/site-packages/jupyter_server/base/handlers.py", line 783, in get_login_url
        raise web.HTTPError(403)
    tornado.web.HTTPError: HTTP 403: Forbidden
[W 2025-04-24 18:18:55.052 ServerApp] 403 GET /api/kernels?1745533135047 (@192.168.0.104) 1.15ms referer=None
[W 2025-04-24 18:18:55.052 ServerApp] wrote error: 'Forbidden'
    Traceback (most recent call last):
      File "/gpfs/data/oermannlab/users/slj9342/.local/lib/python3.8/site-packages/tornado/web.py", line 1788, in _execute
        result = method(*self.path_args, **self.path_kwargs)
      File "/gpfs/data/oermannlab/users/slj9342/.local/lib/python3.8/site-packages/tornado/web.py", line 3289, in wrapper
        url = self.get_login_url()
      File "/gpfs/data/oermannlab/users/slj9342/.local/lib/python3.8/site-packages/jupyter_server/base/handlers.py", line 783, in get_login_url
        raise web.HTTPError(403)
    tornado.web.HTTPError: HTTP 403: Forbidden
[W 2025-04-24 18:18:55.052 ServerApp] 403 GET /api/sessions?1745533135047 (@192.168.0.104) 1.37ms referer=None
[W 2025-04-24 18:18:55.053 ServerApp] wrote error: 'Forbidden'
    Traceback (most recent call last):
      File "/gpfs/data/oermannlab/users/slj9342/.local/lib/python3.8/site-packages/tornado/web.py", line 1788, in _execute
        result = method(*self.path_args, **self.path_kwargs)
      File "/gpfs/data/oermannlab/users/slj9342/.local/lib/python3.8/site-packages/tornado/web.py", line 3289, in wrapper
        url = self.get_login_url()
      File "/gpfs/data/oermannlab/users/slj9342/.local/lib/python3.8/site-packages/jupyter_server/base/handlers.py", line 783, in get_login_url
        raise web.HTTPError(403)
    tornado.web.HTTPError: HTTP 403: Forbidden
[W 2025-04-24 18:18:55.053 ServerApp] 403 GET /api/kernelspecs?1745533135045 (@192.168.0.104) 1.63ms referer=None
[W 2025-04-24 18:19:02.681 ServerApp] 401 POST /login? (@192.168.0.104) 0.68ms referer=None
[W 2025-04-24 18:19:02.767 ServerApp] wrote error: 'Forbidden'
    Traceback (most recent call last):
      File "/gpfs/data/oermannlab/users/slj9342/.local/lib/python3.8/site-packages/tornado/web.py", line 1788, in _execute
        result = method(*self.path_args, **self.path_kwargs)
      File "/gpfs/data/oermannlab/users/slj9342/.local/lib/python3.8/site-packages/tornado/web.py", line 3289, in wrapper
        url = self.get_login_url()
      File "/gpfs/data/oermannlab/users/slj9342/.local/lib/python3.8/site-packages/jupyter_server/base/handlers.py", line 783, in get_login_url
        raise web.HTTPError(403)
    tornado.web.HTTPError: HTTP 403: Forbidden
[W 2025-04-24 18:19:02.767 ServerApp] 403 GET /api/kernels?1745533142684 (@192.168.0.104) 76.25ms referer=None
[W 2025-04-24 18:19:02.768 ServerApp] wrote error: 'Forbidden'
    Traceback (most recent call last):
      File "/gpfs/data/oermannlab/users/slj9342/.local/lib/python3.8/site-packages/tornado/web.py", line 1788, in _execute
        result = method(*self.path_args, **self.path_kwargs)
      File "/gpfs/data/oermannlab/users/slj9342/.local/lib/python3.8/site-packages/tornado/web.py", line 3289, in wrapper
        url = self.get_login_url()
      File "/gpfs/data/oermannlab/users/slj9342/.local/lib/python3.8/site-packages/jupyter_server/base/handlers.py", line 783, in get_login_url
        raise web.HTTPError(403)
    tornado.web.HTTPError: HTTP 403: Forbidden
[W 2025-04-24 18:19:02.768 ServerApp] 403 GET /api/kernels?1745533142686 (@192.168.0.104) 76.53ms referer=None
[W 2025-04-24 18:19:02.768 ServerApp] wrote error: 'Forbidden'
    Traceback (most recent call last):
      File "/gpfs/data/oermannlab/users/slj9342/.local/lib/python3.8/site-packages/tornado/web.py", line 1788, in _execute
        result = method(*self.path_args, **self.path_kwargs)
      File "/gpfs/data/oermannlab/users/slj9342/.local/lib/python3.8/site-packages/tornado/web.py", line 3289, in wrapper
        url = self.get_login_url()
      File "/gpfs/data/oermannlab/users/slj9342/.local/lib/python3.8/site-packages/jupyter_server/base/handlers.py", line 783, in get_login_url
        raise web.HTTPError(403)
    tornado.web.HTTPError: HTTP 403: Forbidden
[W 2025-04-24 18:19:02.768 ServerApp] 403 GET /api/sessions?1745533142686 (@192.168.0.104) 76.77ms referer=None
[W 2025-04-24 18:19:02.769 ServerApp] wrote error: 'Forbidden'
    Traceback (most recent call last):
      File "/gpfs/data/oermannlab/users/slj9342/.local/lib/python3.8/site-packages/tornado/web.py", line 1788, in _execute
        result = method(*self.path_args, **self.path_kwargs)
      File "/gpfs/data/oermannlab/users/slj9342/.local/lib/python3.8/site-packages/tornado/web.py", line 3289, in wrapper
        url = self.get_login_url()
      File "/gpfs/data/oermannlab/users/slj9342/.local/lib/python3.8/site-packages/jupyter_server/base/handlers.py", line 783, in get_login_url
        raise web.HTTPError(403)
    tornado.web.HTTPError: HTTP 403: Forbidden
[W 2025-04-24 18:19:02.769 ServerApp] 403 GET /api/kernelspecs?1745533142684 (@192.168.0.104) 0.50ms referer=None
[I 2025-04-24 18:19:37.714 ServerApp] 302 GET / (@192.168.0.104) 0.33ms
[I 2025-04-24 18:19:37.715 ServerApp] 302 GET / (@192.168.0.104) 0.27ms
[I 2025-04-24 18:19:37.715 ServerApp] 302 GET / (@192.168.0.104) 0.24ms
[I 2025-04-24 18:19:37.804 JupyterNotebookApp] 302 GET /tree? (@192.168.0.104) 0.52ms
[I 2025-04-24 18:19:37.804 JupyterNotebookApp] 302 GET /tree? (@192.168.0.104) 0.60ms
[I 2025-04-24 18:19:37.805 JupyterNotebookApp] 302 GET /tree? (@192.168.0.104) 0.69ms
[W 2025-04-24 18:19:37.934 ServerApp] wrote error: 'Forbidden'
    Traceback (most recent call last):
      File "/gpfs/data/oermannlab/users/slj9342/.local/lib/python3.8/site-packages/tornado/web.py", line 1788, in _execute
        result = method(*self.path_args, **self.path_kwargs)
      File "/gpfs/data/oermannlab/users/slj9342/.local/lib/python3.8/site-packages/tornado/web.py", line 3289, in wrapper
        url = self.get_login_url()
      File "/gpfs/data/oermannlab/users/slj9342/.local/lib/python3.8/site-packages/jupyter_server/base/handlers.py", line 783, in get_login_url
        raise web.HTTPError(403)
    tornado.web.HTTPError: HTTP 403: Forbidden
[W 2025-04-24 18:19:37.934 ServerApp] 403 GET /api/kernelspecs?1745533177929 (@192.168.0.104) 0.56ms referer=None
[W 2025-04-24 18:19:37.935 ServerApp] wrote error: 'Forbidden'
    Traceback (most recent call last):
      File "/gpfs/data/oermannlab/users/slj9342/.local/lib/python3.8/site-packages/tornado/web.py", line 1788, in _execute
        result = method(*self.path_args, **self.path_kwargs)
      File "/gpfs/data/oermannlab/users/slj9342/.local/lib/python3.8/site-packages/tornado/web.py", line 3289, in wrapper
        url = self.get_login_url()
      File "/gpfs/data/oermannlab/users/slj9342/.local/lib/python3.8/site-packages/jupyter_server/base/handlers.py", line 783, in get_login_url
        raise web.HTTPError(403)
    tornado.web.HTTPError: HTTP 403: Forbidden
[W 2025-04-24 18:19:37.935 ServerApp] 403 GET /api/kernels?1745533177930 (@192.168.0.104) 0.51ms referer=None
[W 2025-04-24 18:19:37.935 ServerApp] wrote error: 'Forbidden'
    Traceback (most recent call last):
      File "/gpfs/data/oermannlab/users/slj9342/.local/lib/python3.8/site-packages/tornado/web.py", line 1788, in _execute
        result = method(*self.path_args, **self.path_kwargs)
      File "/gpfs/data/oermannlab/users/slj9342/.local/lib/python3.8/site-packages/tornado/web.py", line 3289, in wrapper
        url = self.get_login_url()
      File "/gpfs/data/oermannlab/users/slj9342/.local/lib/python3.8/site-packages/jupyter_server/base/handlers.py", line 783, in get_login_url
        raise web.HTTPError(403)
    tornado.web.HTTPError: HTTP 403: Forbidden
[W 2025-04-24 18:19:37.936 ServerApp] 403 GET /api/kernelspecs?1745533177931 (@192.168.0.104) 0.50ms referer=None
[W 2025-04-24 18:19:37.947 ServerApp] wrote error: 'Forbidden'
    Traceback (most recent call last):
      File "/gpfs/data/oermannlab/users/slj9342/.local/lib/python3.8/site-packages/tornado/web.py", line 1788, in _execute
        result = method(*self.path_args, **self.path_kwargs)
      File "/gpfs/data/oermannlab/users/slj9342/.local/lib/python3.8/site-packages/tornado/web.py", line 3289, in wrapper
        url = self.get_login_url()
      File "/gpfs/data/oermannlab/users/slj9342/.local/lib/python3.8/site-packages/jupyter_server/base/handlers.py", line 783, in get_login_url
        raise web.HTTPError(403)
    tornado.web.HTTPError: HTTP 403: Forbidden
[W 2025-04-24 18:19:37.948 ServerApp] 403 GET /api/kernels?1745533177932 (@192.168.0.104) 1.52ms referer=None
[W 2025-04-24 18:19:37.948 ServerApp] wrote error: 'Forbidden'
    Traceback (most recent call last):
      File "/gpfs/data/oermannlab/users/slj9342/.local/lib/python3.8/site-packages/tornado/web.py", line 1788, in _execute
        result = method(*self.path_args, **self.path_kwargs)
      File "/gpfs/data/oermannlab/users/slj9342/.local/lib/python3.8/site-packages/tornado/web.py", line 3289, in wrapper
        url = self.get_login_url()
      File "/gpfs/data/oermannlab/users/slj9342/.local/lib/python3.8/site-packages/jupyter_server/base/handlers.py", line 783, in get_login_url
        raise web.HTTPError(403)
    tornado.web.HTTPError: HTTP 403: Forbidden
[W 2025-04-24 18:19:37.948 ServerApp] 403 GET /api/kernels?1745533177934 (@192.168.0.104) 1.74ms referer=None
[W 2025-04-24 18:19:37.948 ServerApp] wrote error: 'Forbidden'
    Traceback (most recent call last):
      File "/gpfs/data/oermannlab/users/slj9342/.local/lib/python3.8/site-packages/tornado/web.py", line 1788, in _execute
        result = method(*self.path_args, **self.path_kwargs)
      File "/gpfs/data/oermannlab/users/slj9342/.local/lib/python3.8/site-packages/tornado/web.py", line 3289, in wrapper
        url = self.get_login_url()
      File "/gpfs/data/oermannlab/users/slj9342/.local/lib/python3.8/site-packages/jupyter_server/base/handlers.py", line 783, in get_login_url
        raise web.HTTPError(403)
    tornado.web.HTTPError: HTTP 403: Forbidden
[W 2025-04-24 18:19:37.948 ServerApp] 403 GET /api/sessions?1745533177935 (@192.168.0.104) 1.98ms referer=None
[W 2025-04-24 18:19:37.949 ServerApp] wrote error: 'Forbidden'
    Traceback (most recent call last):
      File "/gpfs/data/oermannlab/users/slj9342/.local/lib/python3.8/site-packages/tornado/web.py", line 1788, in _execute
        result = method(*self.path_args, **self.path_kwargs)
      File "/gpfs/data/oermannlab/users/slj9342/.local/lib/python3.8/site-packages/tornado/web.py", line 3289, in wrapper
        url = self.get_login_url()
      File "/gpfs/data/oermannlab/users/slj9342/.local/lib/python3.8/site-packages/jupyter_server/base/handlers.py", line 783, in get_login_url
        raise web.HTTPError(403)
    tornado.web.HTTPError: HTTP 403: Forbidden
[W 2025-04-24 18:19:37.949 ServerApp] 403 GET /api/kernels?1745533177936 (@192.168.0.104) 2.19ms referer=None
[W 2025-04-24 18:19:37.949 ServerApp] wrote error: 'Forbidden'
    Traceback (most recent call last):
      File "/gpfs/data/oermannlab/users/slj9342/.local/lib/python3.8/site-packages/tornado/web.py", line 1788, in _execute
        result = method(*self.path_args, **self.path_kwargs)
      File "/gpfs/data/oermannlab/users/slj9342/.local/lib/python3.8/site-packages/tornado/web.py", line 3289, in wrapper
        url = self.get_login_url()
      File "/gpfs/data/oermannlab/users/slj9342/.local/lib/python3.8/site-packages/jupyter_server/base/handlers.py", line 783, in get_login_url
        raise web.HTTPError(403)
    tornado.web.HTTPError: HTTP 403: Forbidden
[W 2025-04-24 18:19:37.949 ServerApp] 403 GET /api/sessions?1745533177938 (@192.168.0.104) 2.41ms referer=None
[W 2025-04-24 18:19:37.949 ServerApp] wrote error: 'Forbidden'
    Traceback (most recent call last):
      File "/gpfs/data/oermannlab/users/slj9342/.local/lib/python3.8/site-packages/tornado/web.py", line 1788, in _execute
        result = method(*self.path_args, **self.path_kwargs)
      File "/gpfs/data/oermannlab/users/slj9342/.local/lib/python3.8/site-packages/tornado/web.py", line 3289, in wrapper
        url = self.get_login_url()
      File "/gpfs/data/oermannlab/users/slj9342/.local/lib/python3.8/site-packages/jupyter_server/base/handlers.py", line 783, in get_login_url
        raise web.HTTPError(403)
    tornado.web.HTTPError: HTTP 403: Forbidden
[W 2025-04-24 18:19:37.950 ServerApp] 403 GET /api/kernelspecs?1745533177942 (@192.168.0.104) 2.62ms referer=None
[W 2025-04-24 18:19:37.950 ServerApp] wrote error: 'Forbidden'
    Traceback (most recent call last):
      File "/gpfs/data/oermannlab/users/slj9342/.local/lib/python3.8/site-packages/tornado/web.py", line 1788, in _execute
        result = method(*self.path_args, **self.path_kwargs)
      File "/gpfs/data/oermannlab/users/slj9342/.local/lib/python3.8/site-packages/tornado/web.py", line 3289, in wrapper
        url = self.get_login_url()
      File "/gpfs/data/oermannlab/users/slj9342/.local/lib/python3.8/site-packages/jupyter_server/base/handlers.py", line 783, in get_login_url
        raise web.HTTPError(403)
    tornado.web.HTTPError: HTTP 403: Forbidden
[W 2025-04-24 18:19:37.950 ServerApp] 403 GET /api/kernelspecs?1745533177943 (@192.168.0.104) 2.82ms referer=None
[I 2025-04-24 18:19:37.956 ServerApp] 302 GET / (@192.168.0.104) 0.39ms
[I 2025-04-24 18:19:37.956 ServerApp] 302 GET / (@192.168.0.104) 0.34ms
[I 2025-04-24 18:19:37.967 JupyterNotebookApp] 302 GET /tree? (@192.168.0.104) 0.44ms
[I 2025-04-24 18:19:37.967 JupyterNotebookApp] 302 GET /tree? (@192.168.0.104) 0.46ms
[W 2025-04-24 18:19:38.005 ServerApp] wrote error: 'Forbidden'
    Traceback (most recent call last):
      File "/gpfs/data/oermannlab/users/slj9342/.local/lib/python3.8/site-packages/tornado/web.py", line 1788, in _execute
        result = method(*self.path_args, **self.path_kwargs)
      File "/gpfs/data/oermannlab/users/slj9342/.local/lib/python3.8/site-packages/tornado/web.py", line 3289, in wrapper
        url = self.get_login_url()
      File "/gpfs/data/oermannlab/users/slj9342/.local/lib/python3.8/site-packages/jupyter_server/base/handlers.py", line 783, in get_login_url
        raise web.HTTPError(403)
    tornado.web.HTTPError: HTTP 403: Forbidden
[W 2025-04-24 18:19:38.005 ServerApp] 403 GET /api/kernelspecs?1745533178000 (@192.168.0.104) 0.60ms referer=None
[W 2025-04-24 18:19:38.005 ServerApp] wrote error: 'Forbidden'
    Traceback (most recent call last):
      File "/gpfs/data/oermannlab/users/slj9342/.local/lib/python3.8/site-packages/tornado/web.py", line 1788, in _execute
        result = method(*self.path_args, **self.path_kwargs)
      File "/gpfs/data/oermannlab/users/slj9342/.local/lib/python3.8/site-packages/tornado/web.py", line 3289, in wrapper
        url = self.get_login_url()
      File "/gpfs/data/oermannlab/users/slj9342/.local/lib/python3.8/site-packages/jupyter_server/base/handlers.py", line 783, in get_login_url
        raise web.HTTPError(403)
    tornado.web.HTTPError: HTTP 403: Forbidden
[W 2025-04-24 18:19:38.006 ServerApp] 403 GET /api/kernels?1745533178001 (@192.168.0.104) 0.87ms referer=None
[W 2025-04-24 18:19:38.015 ServerApp] wrote error: 'Forbidden'
    Traceback (most recent call last):
      File "/gpfs/data/oermannlab/users/slj9342/.local/lib/python3.8/site-packages/tornado/web.py", line 1788, in _execute
        result = method(*self.path_args, **self.path_kwargs)
      File "/gpfs/data/oermannlab/users/slj9342/.local/lib/python3.8/site-packages/tornado/web.py", line 3289, in wrapper
        url = self.get_login_url()
      File "/gpfs/data/oermannlab/users/slj9342/.local/lib/python3.8/site-packages/jupyter_server/base/handlers.py", line 783, in get_login_url
        raise web.HTTPError(403)
    tornado.web.HTTPError: HTTP 403: Forbidden
[W 2025-04-24 18:19:38.015 ServerApp] 403 GET /api/kernelspecs?1745533178001 (@192.168.0.104) 1.49ms referer=None
[W 2025-04-24 18:19:38.016 ServerApp] wrote error: 'Forbidden'
    Traceback (most recent call last):
      File "/gpfs/data/oermannlab/users/slj9342/.local/lib/python3.8/site-packages/tornado/web.py", line 1788, in _execute
        result = method(*self.path_args, **self.path_kwargs)
      File "/gpfs/data/oermannlab/users/slj9342/.local/lib/python3.8/site-packages/tornado/web.py", line 3289, in wrapper
        url = self.get_login_url()
      File "/gpfs/data/oermannlab/users/slj9342/.local/lib/python3.8/site-packages/jupyter_server/base/handlers.py", line 783, in get_login_url
        raise web.HTTPError(403)
    tornado.web.HTTPError: HTTP 403: Forbidden
[W 2025-04-24 18:19:38.016 ServerApp] 403 GET /api/kernels?1745533178002 (@192.168.0.104) 1.71ms referer=None
[W 2025-04-24 18:19:38.016 ServerApp] wrote error: 'Forbidden'
    Traceback (most recent call last):
      File "/gpfs/data/oermannlab/users/slj9342/.local/lib/python3.8/site-packages/tornado/web.py", line 1788, in _execute
        result = method(*self.path_args, **self.path_kwargs)
      File "/gpfs/data/oermannlab/users/slj9342/.local/lib/python3.8/site-packages/tornado/web.py", line 3289, in wrapper
        url = self.get_login_url()
      File "/gpfs/data/oermannlab/users/slj9342/.local/lib/python3.8/site-packages/jupyter_server/base/handlers.py", line 783, in get_login_url
        raise web.HTTPError(403)
    tornado.web.HTTPError: HTTP 403: Forbidden
[W 2025-04-24 18:19:38.016 ServerApp] 403 GET /api/kernels?1745533178004 (@192.168.0.104) 1.94ms referer=None
[W 2025-04-24 18:19:38.016 ServerApp] wrote error: 'Forbidden'
    Traceback (most recent call last):
      File "/gpfs/data/oermannlab/users/slj9342/.local/lib/python3.8/site-packages/tornado/web.py", line 1788, in _execute
        result = method(*self.path_args, **self.path_kwargs)
      File "/gpfs/data/oermannlab/users/slj9342/.local/lib/python3.8/site-packages/tornado/web.py", line 3289, in wrapper
        url = self.get_login_url()
      File "/gpfs/data/oermannlab/users/slj9342/.local/lib/python3.8/site-packages/jupyter_server/base/handlers.py", line 783, in get_login_url
        raise web.HTTPError(403)
    tornado.web.HTTPError: HTTP 403: Forbidden
[W 2025-04-24 18:19:38.017 ServerApp] 403 GET /api/sessions?1745533178005 (@192.168.0.104) 2.17ms referer=None
[W 2025-04-24 18:19:38.017 ServerApp] wrote error: 'Forbidden'
    Traceback (most recent call last):
      File "/gpfs/data/oermannlab/users/slj9342/.local/lib/python3.8/site-packages/tornado/web.py", line 1788, in _execute
        result = method(*self.path_args, **self.path_kwargs)
      File "/gpfs/data/oermannlab/users/slj9342/.local/lib/python3.8/site-packages/tornado/web.py", line 3289, in wrapper
        url = self.get_login_url()
      File "/gpfs/data/oermannlab/users/slj9342/.local/lib/python3.8/site-packages/jupyter_server/base/handlers.py", line 783, in get_login_url
        raise web.HTTPError(403)
    tornado.web.HTTPError: HTTP 403: Forbidden
[W 2025-04-24 18:19:38.017 ServerApp] 403 GET /api/kernels?1745533178006 (@192.168.0.104) 2.39ms referer=None
[W 2025-04-24 18:19:38.017 ServerApp] wrote error: 'Forbidden'
    Traceback (most recent call last):
      File "/gpfs/data/oermannlab/users/slj9342/.local/lib/python3.8/site-packages/tornado/web.py", line 1788, in _execute
        result = method(*self.path_args, **self.path_kwargs)
      File "/gpfs/data/oermannlab/users/slj9342/.local/lib/python3.8/site-packages/tornado/web.py", line 3289, in wrapper
        url = self.get_login_url()
      File "/gpfs/data/oermannlab/users/slj9342/.local/lib/python3.8/site-packages/jupyter_server/base/handlers.py", line 783, in get_login_url
        raise web.HTTPError(403)
    tornado.web.HTTPError: HTTP 403: Forbidden
[W 2025-04-24 18:19:38.017 ServerApp] 403 GET /api/sessions?1745533178007 (@192.168.0.104) 2.61ms referer=None
[W 2025-04-24 18:19:38.018 ServerApp] wrote error: 'Forbidden'
    Traceback (most recent call last):
      File "/gpfs/data/oermannlab/users/slj9342/.local/lib/python3.8/site-packages/tornado/web.py", line 1788, in _execute
        result = method(*self.path_args, **self.path_kwargs)
      File "/gpfs/data/oermannlab/users/slj9342/.local/lib/python3.8/site-packages/tornado/web.py", line 3289, in wrapper
        url = self.get_login_url()
      File "/gpfs/data/oermannlab/users/slj9342/.local/lib/python3.8/site-packages/jupyter_server/base/handlers.py", line 783, in get_login_url
        raise web.HTTPError(403)
    tornado.web.HTTPError: HTTP 403: Forbidden
[W 2025-04-24 18:19:38.018 ServerApp] 403 GET /api/kernelspecs?1745533178009 (@192.168.0.104) 2.82ms referer=None
[W 2025-04-24 18:19:38.027 ServerApp] wrote error: 'Forbidden'
    Traceback (most recent call last):
      File "/gpfs/data/oermannlab/users/slj9342/.local/lib/python3.8/site-packages/tornado/web.py", line 1788, in _execute
        result = method(*self.path_args, **self.path_kwargs)
      File "/gpfs/data/oermannlab/users/slj9342/.local/lib/python3.8/site-packages/tornado/web.py", line 3289, in wrapper
        url = self.get_login_url()
      File "/gpfs/data/oermannlab/users/slj9342/.local/lib/python3.8/site-packages/jupyter_server/base/handlers.py", line 783, in get_login_url
        raise web.HTTPError(403)
    tornado.web.HTTPError: HTTP 403: Forbidden
[W 2025-04-24 18:19:38.027 ServerApp] 403 GET /api/kernelspecs?1745533178017 (@192.168.0.104) 0.69ms referer=None
[I 2025-04-24 18:19:38.028 ServerApp] 302 GET / (@192.168.0.104) 0.64ms
[I 2025-04-24 18:19:38.035 JupyterNotebookApp] 302 GET /tree? (@192.168.0.104) 0.27ms
[W 2025-04-24 18:19:38.067 ServerApp] wrote error: 'Forbidden'
    Traceback (most recent call last):
      File "/gpfs/data/oermannlab/users/slj9342/.local/lib/python3.8/site-packages/tornado/web.py", line 1788, in _execute
        result = method(*self.path_args, **self.path_kwargs)
      File "/gpfs/data/oermannlab/users/slj9342/.local/lib/python3.8/site-packages/tornado/web.py", line 3289, in wrapper
        url = self.get_login_url()
      File "/gpfs/data/oermannlab/users/slj9342/.local/lib/python3.8/site-packages/jupyter_server/base/handlers.py", line 783, in get_login_url
        raise web.HTTPError(403)
    tornado.web.HTTPError: HTTP 403: Forbidden
[W 2025-04-24 18:19:38.068 ServerApp] 403 GET /api/kernelspecs?1745533178065 (@192.168.0.104) 0.48ms referer=None
[W 2025-04-24 18:19:38.068 ServerApp] wrote error: 'Forbidden'
    Traceback (most recent call last):
      File "/gpfs/data/oermannlab/users/slj9342/.local/lib/python3.8/site-packages/tornado/web.py", line 1788, in _execute
        result = method(*self.path_args, **self.path_kwargs)
      File "/gpfs/data/oermannlab/users/slj9342/.local/lib/python3.8/site-packages/tornado/web.py", line 3289, in wrapper
        url = self.get_login_url()
      File "/gpfs/data/oermannlab/users/slj9342/.local/lib/python3.8/site-packages/jupyter_server/base/handlers.py", line 783, in get_login_url
        raise web.HTTPError(403)
    tornado.web.HTTPError: HTTP 403: Forbidden
[W 2025-04-24 18:19:38.068 ServerApp] 403 GET /api/kernels?1745533178066 (@192.168.0.104) 0.49ms referer=None
[W 2025-04-24 18:19:38.079 ServerApp] wrote error: 'Forbidden'
    Traceback (most recent call last):
      File "/gpfs/data/oermannlab/users/slj9342/.local/lib/python3.8/site-packages/tornado/web.py", line 1788, in _execute
        result = method(*self.path_args, **self.path_kwargs)
      File "/gpfs/data/oermannlab/users/slj9342/.local/lib/python3.8/site-packages/tornado/web.py", line 3289, in wrapper
        url = self.get_login_url()
      File "/gpfs/data/oermannlab/users/slj9342/.local/lib/python3.8/site-packages/jupyter_server/base/handlers.py", line 783, in get_login_url
        raise web.HTTPError(403)
    tornado.web.HTTPError: HTTP 403: Forbidden
[W 2025-04-24 18:19:38.080 ServerApp] 403 GET /api/kernels?1745533178068 (@192.168.0.104) 0.84ms referer=None
[W 2025-04-24 18:19:38.080 ServerApp] wrote error: 'Forbidden'
    Traceback (most recent call last):
      File "/gpfs/data/oermannlab/users/slj9342/.local/lib/python3.8/site-packages/tornado/web.py", line 1788, in _execute
        result = method(*self.path_args, **self.path_kwargs)
      File "/gpfs/data/oermannlab/users/slj9342/.local/lib/python3.8/site-packages/tornado/web.py", line 3289, in wrapper
        url = self.get_login_url()
      File "/gpfs/data/oermannlab/users/slj9342/.local/lib/python3.8/site-packages/jupyter_server/base/handlers.py", line 783, in get_login_url
        raise web.HTTPError(403)
    tornado.web.HTTPError: HTTP 403: Forbidden
[W 2025-04-24 18:19:38.080 ServerApp] 403 GET /api/sessions?1745533178069 (@192.168.0.104) 1.04ms referer=None
[W 2025-04-24 18:19:38.080 ServerApp] wrote error: 'Forbidden'
    Traceback (most recent call last):
      File "/gpfs/data/oermannlab/users/slj9342/.local/lib/python3.8/site-packages/tornado/web.py", line 1788, in _execute
        result = method(*self.path_args, **self.path_kwargs)
      File "/gpfs/data/oermannlab/users/slj9342/.local/lib/python3.8/site-packages/tornado/web.py", line 3289, in wrapper
        url = self.get_login_url()
      File "/gpfs/data/oermannlab/users/slj9342/.local/lib/python3.8/site-packages/jupyter_server/base/handlers.py", line 783, in get_login_url
        raise web.HTTPError(403)
    tornado.web.HTTPError: HTTP 403: Forbidden
[W 2025-04-24 18:19:38.080 ServerApp] 403 GET /api/kernelspecs?1745533178070 (@192.168.0.104) 1.24ms referer=None
[W 2025-04-24 18:19:44.808 ServerApp] 401 POST /login? (@192.168.0.104) 0.68ms referer=None
[W 2025-04-24 18:19:44.820 ServerApp] wrote error: 'Forbidden'
    Traceback (most recent call last):
      File "/gpfs/data/oermannlab/users/slj9342/.local/lib/python3.8/site-packages/tornado/web.py", line 1788, in _execute
        result = method(*self.path_args, **self.path_kwargs)
      File "/gpfs/data/oermannlab/users/slj9342/.local/lib/python3.8/site-packages/tornado/web.py", line 3289, in wrapper
        url = self.get_login_url()
      File "/gpfs/data/oermannlab/users/slj9342/.local/lib/python3.8/site-packages/jupyter_server/base/handlers.py", line 783, in get_login_url
        raise web.HTTPError(403)
    tornado.web.HTTPError: HTTP 403: Forbidden
[W 2025-04-24 18:19:44.821 ServerApp] 403 GET /api/kernels?1745533184812 (@192.168.0.104) 0.89ms referer=None
[W 2025-04-24 18:19:44.821 ServerApp] wrote error: 'Forbidden'
    Traceback (most recent call last):
      File "/gpfs/data/oermannlab/users/slj9342/.local/lib/python3.8/site-packages/tornado/web.py", line 1788, in _execute
        result = method(*self.path_args, **self.path_kwargs)
      File "/gpfs/data/oermannlab/users/slj9342/.local/lib/python3.8/site-packages/tornado/web.py", line 3289, in wrapper
        url = self.get_login_url()
      File "/gpfs/data/oermannlab/users/slj9342/.local/lib/python3.8/site-packages/jupyter_server/base/handlers.py", line 783, in get_login_url
        raise web.HTTPError(403)
    tornado.web.HTTPError: HTTP 403: Forbidden
[W 2025-04-24 18:19:44.821 ServerApp] 403 GET /api/sessions?1745533184815 (@192.168.0.104) 1.11ms referer=None
[W 2025-04-24 18:19:44.821 ServerApp] wrote error: 'Forbidden'
    Traceback (most recent call last):
      File "/gpfs/data/oermannlab/users/slj9342/.local/lib/python3.8/site-packages/tornado/web.py", line 1788, in _execute
        result = method(*self.path_args, **self.path_kwargs)
      File "/gpfs/data/oermannlab/users/slj9342/.local/lib/python3.8/site-packages/tornado/web.py", line 3289, in wrapper
        url = self.get_login_url()
      File "/gpfs/data/oermannlab/users/slj9342/.local/lib/python3.8/site-packages/jupyter_server/base/handlers.py", line 783, in get_login_url
        raise web.HTTPError(403)
    tornado.web.HTTPError: HTTP 403: Forbidden
[W 2025-04-24 18:19:44.822 ServerApp] 403 GET /api/kernelspecs?1745533184812 (@192.168.0.104) 1.51ms referer=None
[W 2025-04-24 18:19:44.822 ServerApp] wrote error: 'Forbidden'
    Traceback (most recent call last):
      File "/gpfs/data/oermannlab/users/slj9342/.local/lib/python3.8/site-packages/tornado/web.py", line 1788, in _execute
        result = method(*self.path_args, **self.path_kwargs)
      File "/gpfs/data/oermannlab/users/slj9342/.local/lib/python3.8/site-packages/tornado/web.py", line 3289, in wrapper
        url = self.get_login_url()
      File "/gpfs/data/oermannlab/users/slj9342/.local/lib/python3.8/site-packages/jupyter_server/base/handlers.py", line 783, in get_login_url
        raise web.HTTPError(403)
    tornado.web.HTTPError: HTTP 403: Forbidden
[W 2025-04-24 18:19:44.822 ServerApp] 403 GET /api/kernels?1745533184815 (@192.168.0.104) 0.87ms referer=None
[W 2025-04-24 18:19:44.831 ServerApp] wrote error: 'Forbidden'
    Traceback (most recent call last):
      File "/gpfs/data/oermannlab/users/slj9342/.local/lib/python3.8/site-packages/tornado/web.py", line 1788, in _execute
        result = method(*self.path_args, **self.path_kwargs)
      File "/gpfs/data/oermannlab/users/slj9342/.local/lib/python3.8/site-packages/tornado/web.py", line 3289, in wrapper
        url = self.get_login_url()
      File "/gpfs/data/oermannlab/users/slj9342/.local/lib/python3.8/site-packages/jupyter_server/base/handlers.py", line 783, in get_login_url
        raise web.HTTPError(403)
    tornado.web.HTTPError: HTTP 403: Forbidden
[W 2025-04-24 18:19:44.831 ServerApp] 403 GET /api/kernelspecs?1745533184823 (@192.168.0.104) 0.49ms referer=None
[I 2025-04-24 18:22:42.113 ServerApp] Starting buffering for 70ead765-effe-442c-bc99-24e088fbda5b:88b62c93-d04f-4600-9ebb-fa7815d8013e
[I 2025-04-24 18:22:42.124 ServerApp] Starting buffering for 2a696a36-a54f-46a6-907a-9369c8d58e5b:c95c7f3e-ded2-4289-9484-3d74a79fbc7a
[I 2025-04-25 09:12:26.308 ServerApp] 302 GET / (@192.168.0.104) 0.51ms
[I 2025-04-25 09:12:26.336 ServerApp] 302 GET / (@192.168.0.104) 0.29ms
[I 2025-04-25 09:12:26.336 ServerApp] 302 GET / (@192.168.0.104) 0.19ms
[I 2025-04-25 09:12:26.492 JupyterNotebookApp] 302 GET /tree? (@192.168.0.104) 0.53ms
[I 2025-04-25 09:12:26.492 JupyterNotebookApp] 302 GET /tree? (@192.168.0.104) 0.59ms
[I 2025-04-25 09:12:26.492 JupyterNotebookApp] 302 GET /tree? (@192.168.0.104) 0.25ms
[W 2025-04-25 09:12:26.711 ServerApp] wrote error: 'Forbidden'
    Traceback (most recent call last):
      File "/gpfs/data/oermannlab/users/slj9342/.local/lib/python3.8/site-packages/tornado/web.py", line 1788, in _execute
        result = method(*self.path_args, **self.path_kwargs)
      File "/gpfs/data/oermannlab/users/slj9342/.local/lib/python3.8/site-packages/tornado/web.py", line 3289, in wrapper
        url = self.get_login_url()
      File "/gpfs/data/oermannlab/users/slj9342/.local/lib/python3.8/site-packages/jupyter_server/base/handlers.py", line 783, in get_login_url
        raise web.HTTPError(403)
    tornado.web.HTTPError: HTTP 403: Forbidden
[W 2025-04-25 09:12:26.713 ServerApp] 403 GET /api/kernelspecs?1745586746706 (@192.168.0.104) 2.61ms referer=None
[W 2025-04-25 09:12:26.713 ServerApp] wrote error: 'Forbidden'
    Traceback (most recent call last):
      File "/gpfs/data/oermannlab/users/slj9342/.local/lib/python3.8/site-packages/tornado/web.py", line 1788, in _execute
        result = method(*self.path_args, **self.path_kwargs)
      File "/gpfs/data/oermannlab/users/slj9342/.local/lib/python3.8/site-packages/tornado/web.py", line 3289, in wrapper
        url = self.get_login_url()
      File "/gpfs/data/oermannlab/users/slj9342/.local/lib/python3.8/site-packages/jupyter_server/base/handlers.py", line 783, in get_login_url
        raise web.HTTPError(403)
    tornado.web.HTTPError: HTTP 403: Forbidden
[W 2025-04-25 09:12:26.714 ServerApp] 403 GET /api/kernels?1745586746707 (@192.168.0.104) 2.90ms referer=None
[W 2025-04-25 09:12:26.714 ServerApp] wrote error: 'Forbidden'
    Traceback (most recent call last):
      File "/gpfs/data/oermannlab/users/slj9342/.local/lib/python3.8/site-packages/tornado/web.py", line 1788, in _execute
        result = method(*self.path_args, **self.path_kwargs)
      File "/gpfs/data/oermannlab/users/slj9342/.local/lib/python3.8/site-packages/tornado/web.py", line 3289, in wrapper
        url = self.get_login_url()
      File "/gpfs/data/oermannlab/users/slj9342/.local/lib/python3.8/site-packages/jupyter_server/base/handlers.py", line 783, in get_login_url
        raise web.HTTPError(403)
    tornado.web.HTTPError: HTTP 403: Forbidden
[W 2025-04-25 09:12:26.714 ServerApp] 403 GET /api/kernelspecs?1745586746708 (@192.168.0.104) 0.47ms referer=None
[W 2025-04-25 09:12:30.686 ServerApp] wrote error: 'Forbidden'
    Traceback (most recent call last):
      File "/gpfs/data/oermannlab/users/slj9342/.local/lib/python3.8/site-packages/tornado/web.py", line 1788, in _execute
        result = method(*self.path_args, **self.path_kwargs)
      File "/gpfs/data/oermannlab/users/slj9342/.local/lib/python3.8/site-packages/tornado/web.py", line 3289, in wrapper
        url = self.get_login_url()
      File "/gpfs/data/oermannlab/users/slj9342/.local/lib/python3.8/site-packages/jupyter_server/base/handlers.py", line 783, in get_login_url
        raise web.HTTPError(403)
    tornado.web.HTTPError: HTTP 403: Forbidden
[W 2025-04-25 09:12:30.686 ServerApp] 403 GET /api/kernels?1745586746708 (@192.168.0.104) 0.52ms referer=None
[W 2025-04-25 09:12:30.686 ServerApp] wrote error: 'Forbidden'
    Traceback (most recent call last):
      File "/gpfs/data/oermannlab/users/slj9342/.local/lib/python3.8/site-packages/tornado/web.py", line 1788, in _execute
        result = method(*self.path_args, **self.path_kwargs)
      File "/gpfs/data/oermannlab/users/slj9342/.local/lib/python3.8/site-packages/tornado/web.py", line 3289, in wrapper
        url = self.get_login_url()
      File "/gpfs/data/oermannlab/users/slj9342/.local/lib/python3.8/site-packages/jupyter_server/base/handlers.py", line 783, in get_login_url
        raise web.HTTPError(403)
    tornado.web.HTTPError: HTTP 403: Forbidden
[W 2025-04-25 09:12:30.687 ServerApp] 403 GET /api/kernels?1745586746711 (@192.168.0.104) 0.55ms referer=None
[W 2025-04-25 09:12:30.687 ServerApp] wrote error: 'Forbidden'
    Traceback (most recent call last):
      File "/gpfs/data/oermannlab/users/slj9342/.local/lib/python3.8/site-packages/tornado/web.py", line 1788, in _execute
        result = method(*self.path_args, **self.path_kwargs)
      File "/gpfs/data/oermannlab/users/slj9342/.local/lib/python3.8/site-packages/tornado/web.py", line 3289, in wrapper
        url = self.get_login_url()
      File "/gpfs/data/oermannlab/users/slj9342/.local/lib/python3.8/site-packages/jupyter_server/base/handlers.py", line 783, in get_login_url
        raise web.HTTPError(403)
    tornado.web.HTTPError: HTTP 403: Forbidden
[W 2025-04-25 09:12:30.687 ServerApp] 403 GET /api/sessions?1745586746711 (@192.168.0.104) 0.51ms referer=None
[W 2025-04-25 09:12:30.688 ServerApp] wrote error: 'Forbidden'
    Traceback (most recent call last):
      File "/gpfs/data/oermannlab/users/slj9342/.local/lib/python3.8/site-packages/tornado/web.py", line 1788, in _execute
        result = method(*self.path_args, **self.path_kwargs)
      File "/gpfs/data/oermannlab/users/slj9342/.local/lib/python3.8/site-packages/tornado/web.py", line 3289, in wrapper
        url = self.get_login_url()
      File "/gpfs/data/oermannlab/users/slj9342/.local/lib/python3.8/site-packages/jupyter_server/base/handlers.py", line 783, in get_login_url
        raise web.HTTPError(403)
    tornado.web.HTTPError: HTTP 403: Forbidden
[W 2025-04-25 09:12:30.688 ServerApp] 403 GET /api/kernels?1745586746717 (@192.168.0.104) 0.83ms referer=None
[W 2025-04-25 09:12:30.688 ServerApp] wrote error: 'Forbidden'
    Traceback (most recent call last):
      File "/gpfs/data/oermannlab/users/slj9342/.local/lib/python3.8/site-packages/tornado/web.py", line 1788, in _execute
        result = method(*self.path_args, **self.path_kwargs)
      File "/gpfs/data/oermannlab/users/slj9342/.local/lib/python3.8/site-packages/tornado/web.py", line 3289, in wrapper
        url = self.get_login_url()
      File "/gpfs/data/oermannlab/users/slj9342/.local/lib/python3.8/site-packages/jupyter_server/base/handlers.py", line 783, in get_login_url
        raise web.HTTPError(403)
    tornado.web.HTTPError: HTTP 403: Forbidden
[W 2025-04-25 09:12:30.689 ServerApp] 403 GET /api/sessions?1745586746718 (@192.168.0.104) 1.09ms referer=None
[W 2025-04-25 09:12:30.689 ServerApp] wrote error: 'Forbidden'
    Traceback (most recent call last):
      File "/gpfs/data/oermannlab/users/slj9342/.local/lib/python3.8/site-packages/tornado/web.py", line 1788, in _execute
        result = method(*self.path_args, **self.path_kwargs)
      File "/gpfs/data/oermannlab/users/slj9342/.local/lib/python3.8/site-packages/tornado/web.py", line 3289, in wrapper
        url = self.get_login_url()
      File "/gpfs/data/oermannlab/users/slj9342/.local/lib/python3.8/site-packages/jupyter_server/base/handlers.py", line 783, in get_login_url
        raise web.HTTPError(403)
    tornado.web.HTTPError: HTTP 403: Forbidden
[W 2025-04-25 09:12:30.689 ServerApp] 403 GET /api/kernelspecs?1745586746727 (@192.168.0.104) 1.35ms referer=None
[W 2025-04-25 09:12:30.689 ServerApp] wrote error: 'Forbidden'
    Traceback (most recent call last):
      File "/gpfs/data/oermannlab/users/slj9342/.local/lib/python3.8/site-packages/tornado/web.py", line 1788, in _execute
        result = method(*self.path_args, **self.path_kwargs)
      File "/gpfs/data/oermannlab/users/slj9342/.local/lib/python3.8/site-packages/tornado/web.py", line 3289, in wrapper
        url = self.get_login_url()
      File "/gpfs/data/oermannlab/users/slj9342/.local/lib/python3.8/site-packages/jupyter_server/base/handlers.py", line 783, in get_login_url
        raise web.HTTPError(403)
    tornado.web.HTTPError: HTTP 403: Forbidden
[W 2025-04-25 09:12:30.689 ServerApp] 403 GET /api/kernelspecs?1745586746726 (@192.168.0.104) 1.61ms referer=None
[I 2025-04-25 09:12:30.699 ServerApp] 302 GET / (@192.168.0.104) 0.18ms
[I 2025-04-25 09:12:30.699 ServerApp] 302 GET / (@192.168.0.104) 0.18ms
[I 2025-04-25 09:12:30.703 JupyterNotebookApp] 302 GET /tree? (@192.168.0.104) 0.25ms
[I 2025-04-25 09:12:30.703 JupyterNotebookApp] 302 GET /tree? (@192.168.0.104) 0.23ms
[W 2025-04-25 09:12:30.788 ServerApp] wrote error: 'Forbidden'
    Traceback (most recent call last):
      File "/gpfs/data/oermannlab/users/slj9342/.local/lib/python3.8/site-packages/tornado/web.py", line 1788, in _execute
        result = method(*self.path_args, **self.path_kwargs)
      File "/gpfs/data/oermannlab/users/slj9342/.local/lib/python3.8/site-packages/tornado/web.py", line 3289, in wrapper
        url = self.get_login_url()
      File "/gpfs/data/oermannlab/users/slj9342/.local/lib/python3.8/site-packages/jupyter_server/base/handlers.py", line 783, in get_login_url
        raise web.HTTPError(403)
    tornado.web.HTTPError: HTTP 403: Forbidden
[W 2025-04-25 09:12:30.789 ServerApp] 403 GET /api/kernelspecs?1745586750783 (@192.168.0.104) 0.61ms referer=None
[W 2025-04-25 09:12:30.789 ServerApp] wrote error: 'Forbidden'
    Traceback (most recent call last):
      File "/gpfs/data/oermannlab/users/slj9342/.local/lib/python3.8/site-packages/tornado/web.py", line 1788, in _execute
        result = method(*self.path_args, **self.path_kwargs)
      File "/gpfs/data/oermannlab/users/slj9342/.local/lib/python3.8/site-packages/tornado/web.py", line 3289, in wrapper
        url = self.get_login_url()
      File "/gpfs/data/oermannlab/users/slj9342/.local/lib/python3.8/site-packages/jupyter_server/base/handlers.py", line 783, in get_login_url
        raise web.HTTPError(403)
    tornado.web.HTTPError: HTTP 403: Forbidden
[W 2025-04-25 09:12:30.789 ServerApp] 403 GET /api/kernels?1745586750783 (@192.168.0.104) 0.86ms referer=None
[W 2025-04-25 09:12:30.799 ServerApp] wrote error: 'Forbidden'
    Traceback (most recent call last):
      File "/gpfs/data/oermannlab/users/slj9342/.local/lib/python3.8/site-packages/tornado/web.py", line 1788, in _execute
        result = method(*self.path_args, **self.path_kwargs)
      File "/gpfs/data/oermannlab/users/slj9342/.local/lib/python3.8/site-packages/tornado/web.py", line 3289, in wrapper
        url = self.get_login_url()
      File "/gpfs/data/oermannlab/users/slj9342/.local/lib/python3.8/site-packages/jupyter_server/base/handlers.py", line 783, in get_login_url
        raise web.HTTPError(403)
    tornado.web.HTTPError: HTTP 403: Forbidden
[W 2025-04-25 09:12:30.799 ServerApp] 403 GET /api/kernelspecs?1745586750785 (@192.168.0.104) 0.46ms referer=None
[W 2025-04-25 09:12:30.800 ServerApp] wrote error: 'Forbidden'
    Traceback (most recent call last):
      File "/gpfs/data/oermannlab/users/slj9342/.local/lib/python3.8/site-packages/tornado/web.py", line 1788, in _execute
        result = method(*self.path_args, **self.path_kwargs)
      File "/gpfs/data/oermannlab/users/slj9342/.local/lib/python3.8/site-packages/tornado/web.py", line 3289, in wrapper
        url = self.get_login_url()
      File "/gpfs/data/oermannlab/users/slj9342/.local/lib/python3.8/site-packages/jupyter_server/base/handlers.py", line 783, in get_login_url
        raise web.HTTPError(403)
    tornado.web.HTTPError: HTTP 403: Forbidden
[W 2025-04-25 09:12:30.800 ServerApp] 403 GET /api/kernels?1745586750786 (@192.168.0.104) 0.68ms referer=None
[W 2025-04-25 09:12:30.800 ServerApp] wrote error: 'Forbidden'
    Traceback (most recent call last):
      File "/gpfs/data/oermannlab/users/slj9342/.local/lib/python3.8/site-packages/tornado/web.py", line 1788, in _execute
        result = method(*self.path_args, **self.path_kwargs)
      File "/gpfs/data/oermannlab/users/slj9342/.local/lib/python3.8/site-packages/tornado/web.py", line 3289, in wrapper
        url = self.get_login_url()
      File "/gpfs/data/oermannlab/users/slj9342/.local/lib/python3.8/site-packages/jupyter_server/base/handlers.py", line 783, in get_login_url
        raise web.HTTPError(403)
    tornado.web.HTTPError: HTTP 403: Forbidden
[W 2025-04-25 09:12:30.801 ServerApp] 403 GET /api/kernels?1745586750788 (@192.168.0.104) 0.95ms referer=None
[W 2025-04-25 09:12:30.801 ServerApp] wrote error: 'Forbidden'
    Traceback (most recent call last):
      File "/gpfs/data/oermannlab/users/slj9342/.local/lib/python3.8/site-packages/tornado/web.py", line 1788, in _execute
        result = method(*self.path_args, **self.path_kwargs)
      File "/gpfs/data/oermannlab/users/slj9342/.local/lib/python3.8/site-packages/tornado/web.py", line 3289, in wrapper
        url = self.get_login_url()
      File "/gpfs/data/oermannlab/users/slj9342/.local/lib/python3.8/site-packages/jupyter_server/base/handlers.py", line 783, in get_login_url
        raise web.HTTPError(403)
    tornado.web.HTTPError: HTTP 403: Forbidden
[W 2025-04-25 09:12:30.801 ServerApp] 403 GET /api/sessions?1745586750789 (@192.168.0.104) 1.24ms referer=None
[W 2025-04-25 09:12:30.802 ServerApp] wrote error: 'Forbidden'
    Traceback (most recent call last):
      File "/gpfs/data/oermannlab/users/slj9342/.local/lib/python3.8/site-packages/tornado/web.py", line 1788, in _execute
        result = method(*self.path_args, **self.path_kwargs)
      File "/gpfs/data/oermannlab/users/slj9342/.local/lib/python3.8/site-packages/tornado/web.py", line 3289, in wrapper
        url = self.get_login_url()
      File "/gpfs/data/oermannlab/users/slj9342/.local/lib/python3.8/site-packages/jupyter_server/base/handlers.py", line 783, in get_login_url
        raise web.HTTPError(403)
    tornado.web.HTTPError: HTTP 403: Forbidden
[W 2025-04-25 09:12:30.802 ServerApp] 403 GET /api/kernels?1745586750791 (@192.168.0.104) 0.69ms referer=None
[W 2025-04-25 09:12:30.802 ServerApp] wrote error: 'Forbidden'
    Traceback (most recent call last):
      File "/gpfs/data/oermannlab/users/slj9342/.local/lib/python3.8/site-packages/tornado/web.py", line 1788, in _execute
        result = method(*self.path_args, **self.path_kwargs)
      File "/gpfs/data/oermannlab/users/slj9342/.local/lib/python3.8/site-packages/tornado/web.py", line 3289, in wrapper
        url = self.get_login_url()
      File "/gpfs/data/oermannlab/users/slj9342/.local/lib/python3.8/site-packages/jupyter_server/base/handlers.py", line 783, in get_login_url
        raise web.HTTPError(403)
    tornado.web.HTTPError: HTTP 403: Forbidden
[W 2025-04-25 09:12:30.802 ServerApp] 403 GET /api/sessions?1745586750792 (@192.168.0.104) 0.92ms referer=None
[W 2025-04-25 09:12:30.802 ServerApp] wrote error: 'Forbidden'
    Traceback (most recent call last):
      File "/gpfs/data/oermannlab/users/slj9342/.local/lib/python3.8/site-packages/tornado/web.py", line 1788, in _execute
        result = method(*self.path_args, **self.path_kwargs)
      File "/gpfs/data/oermannlab/users/slj9342/.local/lib/python3.8/site-packages/tornado/web.py", line 3289, in wrapper
        url = self.get_login_url()
      File "/gpfs/data/oermannlab/users/slj9342/.local/lib/python3.8/site-packages/jupyter_server/base/handlers.py", line 783, in get_login_url
        raise web.HTTPError(403)
    tornado.web.HTTPError: HTTP 403: Forbidden
[W 2025-04-25 09:12:30.803 ServerApp] 403 GET /api/kernelspecs?1745586750797 (@192.168.0.104) 1.18ms referer=None
[W 2025-04-25 09:12:30.808 ServerApp] wrote error: 'Forbidden'
    Traceback (most recent call last):
      File "/gpfs/data/oermannlab/users/slj9342/.local/lib/python3.8/site-packages/tornado/web.py", line 1788, in _execute
        result = method(*self.path_args, **self.path_kwargs)
      File "/gpfs/data/oermannlab/users/slj9342/.local/lib/python3.8/site-packages/tornado/web.py", line 3289, in wrapper
        url = self.get_login_url()
      File "/gpfs/data/oermannlab/users/slj9342/.local/lib/python3.8/site-packages/jupyter_server/base/handlers.py", line 783, in get_login_url
        raise web.HTTPError(403)
    tornado.web.HTTPError: HTTP 403: Forbidden
[W 2025-04-25 09:12:30.808 ServerApp] 403 GET /api/kernelspecs?1745586750802 (@192.168.0.104) 0.52ms referer=None
[I 2025-04-25 09:12:30.809 ServerApp] 302 GET / (@192.168.0.104) 0.22ms
[I 2025-04-25 09:12:30.810 JupyterNotebookApp] 302 GET /tree? (@192.168.0.104) 0.26ms
[W 2025-04-25 09:12:30.826 ServerApp] wrote error: 'Forbidden'
    Traceback (most recent call last):
      File "/gpfs/data/oermannlab/users/slj9342/.local/lib/python3.8/site-packages/tornado/web.py", line 1788, in _execute
        result = method(*self.path_args, **self.path_kwargs)
      File "/gpfs/data/oermannlab/users/slj9342/.local/lib/python3.8/site-packages/tornado/web.py", line 3289, in wrapper
        url = self.get_login_url()
      File "/gpfs/data/oermannlab/users/slj9342/.local/lib/python3.8/site-packages/jupyter_server/base/handlers.py", line 783, in get_login_url
        raise web.HTTPError(403)
    tornado.web.HTTPError: HTTP 403: Forbidden
[W 2025-04-25 09:12:30.826 ServerApp] 403 GET /api/kernelspecs?1745586750824 (@192.168.0.104) 0.46ms referer=None
[W 2025-04-25 09:12:30.826 ServerApp] wrote error: 'Forbidden'
    Traceback (most recent call last):
      File "/gpfs/data/oermannlab/users/slj9342/.local/lib/python3.8/site-packages/tornado/web.py", line 1788, in _execute
        result = method(*self.path_args, **self.path_kwargs)
      File "/gpfs/data/oermannlab/users/slj9342/.local/lib/python3.8/site-packages/tornado/web.py", line 3289, in wrapper
        url = self.get_login_url()
      File "/gpfs/data/oermannlab/users/slj9342/.local/lib/python3.8/site-packages/jupyter_server/base/handlers.py", line 783, in get_login_url
        raise web.HTTPError(403)
    tornado.web.HTTPError: HTTP 403: Forbidden
[W 2025-04-25 09:12:30.827 ServerApp] 403 GET /api/kernels?1745586750824 (@192.168.0.104) 0.48ms referer=None
[W 2025-04-25 09:12:30.830 ServerApp] wrote error: 'Forbidden'
    Traceback (most recent call last):
      File "/gpfs/data/oermannlab/users/slj9342/.local/lib/python3.8/site-packages/tornado/web.py", line 1788, in _execute
        result = method(*self.path_args, **self.path_kwargs)
      File "/gpfs/data/oermannlab/users/slj9342/.local/lib/python3.8/site-packages/tornado/web.py", line 3289, in wrapper
        url = self.get_login_url()
      File "/gpfs/data/oermannlab/users/slj9342/.local/lib/python3.8/site-packages/jupyter_server/base/handlers.py", line 783, in get_login_url
        raise web.HTTPError(403)
    tornado.web.HTTPError: HTTP 403: Forbidden
[W 2025-04-25 09:12:30.830 ServerApp] 403 GET /api/kernels?1745586750826 (@192.168.0.104) 0.81ms referer=None
[W 2025-04-25 09:12:30.831 ServerApp] wrote error: 'Forbidden'
    Traceback (most recent call last):
      File "/gpfs/data/oermannlab/users/slj9342/.local/lib/python3.8/site-packages/tornado/web.py", line 1788, in _execute
        result = method(*self.path_args, **self.path_kwargs)
      File "/gpfs/data/oermannlab/users/slj9342/.local/lib/python3.8/site-packages/tornado/web.py", line 3289, in wrapper
        url = self.get_login_url()
      File "/gpfs/data/oermannlab/users/slj9342/.local/lib/python3.8/site-packages/jupyter_server/base/handlers.py", line 783, in get_login_url
        raise web.HTTPError(403)
    tornado.web.HTTPError: HTTP 403: Forbidden
[W 2025-04-25 09:12:30.831 ServerApp] 403 GET /api/sessions?1745586750827 (@192.168.0.104) 1.02ms referer=None
[W 2025-04-25 09:12:30.831 ServerApp] wrote error: 'Forbidden'
    Traceback (most recent call last):
      File "/gpfs/data/oermannlab/users/slj9342/.local/lib/python3.8/site-packages/tornado/web.py", line 1788, in _execute
        result = method(*self.path_args, **self.path_kwargs)
      File "/gpfs/data/oermannlab/users/slj9342/.local/lib/python3.8/site-packages/tornado/web.py", line 3289, in wrapper
        url = self.get_login_url()
      File "/gpfs/data/oermannlab/users/slj9342/.local/lib/python3.8/site-packages/jupyter_server/base/handlers.py", line 783, in get_login_url
        raise web.HTTPError(403)
    tornado.web.HTTPError: HTTP 403: Forbidden
[W 2025-04-25 09:12:30.831 ServerApp] 403 GET /api/kernelspecs?1745586750828 (@192.168.0.104) 1.24ms referer=None
slurmstepd-a100-4027: error: *** JOB 63261676 ON a100-4027 CANCELLED AT 2025-04-25T09:13:35 ***
