
Terminal command to create your ssh tunnel
ssh -N -L 9651:a100-4032:9651 slj9342@bigpurple.nyumc.org
Windows MobaXterm info
Forwarded port:same as remote port
Remote server: a100-4032
Remote port: 9651
SSH server: bigpurple.nyumc.org
SSH login: slj9342
SSH port: 22
Use a Browser on your local machine to go to:
localhost:9651/lab?token=  (prefix w/ https:// if using password)

[I 2025-04-21 09:26:31.950 ServerApp] Extension package jupyter_lsp took 0.1994s to import
[I 2025-04-21 09:26:32.472 ServerApp] jupyter_lsp | extension was successfully linked.
[I 2025-04-21 09:26:32.475 ServerApp] jupyter_server_terminals | extension was successfully linked.
[I 2025-04-21 09:26:32.480 ServerApp] jupyterlab | extension was successfully linked.
[I 2025-04-21 09:26:32.483 ServerApp] notebook | extension was successfully linked.
[I 2025-04-21 09:26:36.464 ServerApp] notebook_shim | extension was successfully linked.
[I 2025-04-21 09:26:36.625 ServerApp] notebook_shim | extension was successfully loaded.
[I 2025-04-21 09:26:36.627 ServerApp] jupyter_lsp | extension was successfully loaded.
[I 2025-04-21 09:26:36.631 ServerApp] jupyter_server_terminals | extension was successfully loaded.
[I 2025-04-21 09:26:36.638 LabApp] JupyterLab extension loaded from /gpfs/data/oermannlab/users/slj9342/.local/lib/python3.8/site-packages/jupyterlab
[I 2025-04-21 09:26:36.638 LabApp] JupyterLab application directory is /gpfs/data/oermannlab/users/slj9342/.local/share/jupyter/lab
[I 2025-04-21 09:26:36.639 LabApp] Extension Manager is 'pypi'.
[I 2025-04-21 09:26:37.094 ServerApp] jupyterlab | extension was successfully loaded.
[I 2025-04-21 09:26:37.097 ServerApp] notebook | extension was successfully loaded.
[I 2025-04-21 09:26:37.098 ServerApp] Serving notebooks from local directory: /gpfs/data/oermannlab/users/slj9342/dl4med_final_project
[I 2025-04-21 09:26:37.098 ServerApp] Jupyter Server 2.14.2 is running at:
[I 2025-04-21 09:26:37.098 ServerApp] http://a100-4032:9651/tree?token=70de3f60789652ca300875560599e3eea3880e250651b6ff
[I 2025-04-21 09:26:37.098 ServerApp]     http://127.0.0.1:9651/tree?token=70de3f60789652ca300875560599e3eea3880e250651b6ff
[I 2025-04-21 09:26:37.098 ServerApp] Use Control-C to stop this server and shut down all kernels (twice to skip confirmation).
[C 2025-04-21 09:26:37.224 ServerApp] 
    
    To access the server, open this file in a browser:
        file:///gpfs/data/oermannlab/users/slj9342/.local/share/jupyter/runtime/jpserver-1399799-open.html
    Or copy and paste one of these URLs:
        http://a100-4032:9651/tree?token=70de3f60789652ca300875560599e3eea3880e250651b6ff
        http://127.0.0.1:9651/tree?token=70de3f60789652ca300875560599e3eea3880e250651b6ff
[I 2025-04-21 09:26:37.264 ServerApp] Skipped non-installed server(s): bash-language-server, dockerfile-language-server-nodejs, javascript-typescript-langserver, jedi-language-server, julia-language-server, pyright, python-language-server, python-lsp-server, r-languageserver, sql-language-server, texlab, typescript-language-server, unified-language-server, vscode-css-languageserver-bin, vscode-html-languageserver-bin, vscode-json-languageserver-bin, yaml-language-server
[W 2025-04-21 09:29:57.925 ServerApp] 404 GET /hub/api (@192.168.0.103) 86.78ms referer=None
[I 2025-04-21 09:29:57.928 ServerApp] 302 GET / (@192.168.0.103) 0.34ms
[I 2025-04-21 09:29:57.931 JupyterNotebookApp] 302 GET /tree? (@192.168.0.103) 0.40ms
[I 2025-04-21 09:30:06.217 ServerApp] User c60f45a8c0574bffa87c8156d062f96a logged in.
[I 2025-04-21 09:30:06.218 ServerApp] 302 POST /login? (c60f45a8c0574bffa87c8156d062f96a@192.168.0.103) 1.89ms
[I 2025-04-21 09:31:03.165 ServerApp] Kernel started: c03b8bd4-3b7b-44b1-adc2-276a250b501b
[I 2025-04-21 09:31:15.807 ServerApp] Connecting to kernel c03b8bd4-3b7b-44b1-adc2-276a250b501b.
[I 2025-04-21 10:09:39.394 ServerApp] Starting buffering for c03b8bd4-3b7b-44b1-adc2-276a250b501b:41aa3b28-7d15-4c7d-a982-13cfc019ece7
[I 2025-04-21 10:10:21.435 ServerApp] 302 GET / (@192.168.0.103) 0.37ms
[I 2025-04-21 10:10:22.423 JupyterNotebookApp] 302 GET /tree? (@192.168.0.103) 0.50ms
[I 2025-04-21 10:10:30.254 ServerApp] User efacc3891177480aace6a5c7757e386a logged in.
[I 2025-04-21 10:10:30.264 ServerApp] 302 POST /login? (efacc3891177480aace6a5c7757e386a@192.168.0.103) 10.12ms
[I 2025-04-21 10:10:56.884 ServerApp] Kernel started: 15d09102-e24c-44b4-9de5-9b34cb12cfe7
[W 2025-04-21 10:11:56.907 ServerApp] Timeout waiting for kernel_info reply from 15d09102-e24c-44b4-9de5-9b34cb12cfe7
[I 2025-04-21 10:11:56.919 ServerApp] Connecting to kernel 15d09102-e24c-44b4-9de5-9b34cb12cfe7.
[W 2025-04-21 10:12:01.441 ServerApp] Nudge: attempt 10 on kernel 15d09102-e24c-44b4-9de5-9b34cb12cfe7
Exception in callback _chain_future.<locals>._set_state(<Future finished result={}>, <Future at 0x...returned dict>) at /gpfs/share/apps/miniconda3/gpu/4.9.2/lib/python3.8/asyncio/futures.py:354
handle: <Handle _chain_future.<locals>._set_state(<Future finished result={}>, <Future at 0x...returned dict>) at /gpfs/share/apps/miniconda3/gpu/4.9.2/lib/python3.8/asyncio/futures.py:354>
Traceback (most recent call last):
  File "/gpfs/share/apps/miniconda3/gpu/4.9.2/lib/python3.8/asyncio/events.py", line 81, in _run
    self._context.run(self._callback, *self._args)
  File "/gpfs/share/apps/miniconda3/gpu/4.9.2/lib/python3.8/asyncio/futures.py", line 356, in _set_state
    _copy_future_state(other, future)
  File "/gpfs/share/apps/miniconda3/gpu/4.9.2/lib/python3.8/asyncio/futures.py", line 326, in _copy_future_state
    assert not dest.done()
AssertionError
[W 2025-04-21 10:12:06.280 ServerApp] 404 GET /nbextensions/jupyter-js-widgets/extension.js (@192.168.0.103) 44.06ms referer=None
[W 2025-04-21 10:12:06.280 ServerApp] 404 GET /nbextensions/jupyter-js-widgets/extension.js (@192.168.0.103) 44.48ms referer=None
[I 2025-04-21 10:17:45.423 ServerApp] Kernel restarted: 15d09102-e24c-44b4-9de5-9b34cb12cfe7
[I 2025-04-21 10:17:45.434 ServerApp] Starting buffering for 15d09102-e24c-44b4-9de5-9b34cb12cfe7:2cb13977-bfba-4378-9df6-0f26b74e0617
[I 2025-04-21 10:17:45.436 ServerApp] Connecting to kernel 15d09102-e24c-44b4-9de5-9b34cb12cfe7.
[I 2025-04-21 10:17:45.436 ServerApp] Restoring connection for 15d09102-e24c-44b4-9de5-9b34cb12cfe7:2cb13977-bfba-4378-9df6-0f26b74e0617
[W 2025-04-21 10:17:49.973 ServerApp] Nudge: attempt 10 on kernel 15d09102-e24c-44b4-9de5-9b34cb12cfe7
[W 2025-04-21 10:17:55.034 ServerApp] Nudge: attempt 20 on kernel 15d09102-e24c-44b4-9de5-9b34cb12cfe7
[W 2025-04-21 10:18:00.081 ServerApp] Nudge: attempt 30 on kernel 15d09102-e24c-44b4-9de5-9b34cb12cfe7
[W 2025-04-21 10:18:05.125 ServerApp] Nudge: attempt 40 on kernel 15d09102-e24c-44b4-9de5-9b34cb12cfe7
[W 2025-04-21 10:18:10.165 ServerApp] Nudge: attempt 50 on kernel 15d09102-e24c-44b4-9de5-9b34cb12cfe7
[W 2025-04-21 10:18:15.237 ServerApp] Nudge: attempt 60 on kernel 15d09102-e24c-44b4-9de5-9b34cb12cfe7
[W 2025-04-21 10:18:20.258 ServerApp] Nudge: attempt 70 on kernel 15d09102-e24c-44b4-9de5-9b34cb12cfe7
[W 2025-04-21 10:18:25.299 ServerApp] Nudge: attempt 80 on kernel 15d09102-e24c-44b4-9de5-9b34cb12cfe7
[W 2025-04-21 10:18:30.360 ServerApp] Nudge: attempt 90 on kernel 15d09102-e24c-44b4-9de5-9b34cb12cfe7
[W 2025-04-21 10:18:35.409 ServerApp] Nudge: attempt 100 on kernel 15d09102-e24c-44b4-9de5-9b34cb12cfe7
[W 2025-04-21 18:10:04.108 ServerApp] 404 GET /hub/api (@192.168.0.103) 100.19ms referer=None
[I 2025-04-21 18:10:04.119 ServerApp] 302 GET / (@192.168.0.103) 0.31ms
[I 2025-04-21 18:10:04.130 JupyterNotebookApp] 302 GET /tree? (@192.168.0.103) 0.40ms
[I 2025-04-21 18:10:12.563 ServerApp] User fdc9fdcc48db49b4b499ea197d9c92a3 logged in.
[I 2025-04-21 18:10:12.573 ServerApp] 302 POST /login? (fdc9fdcc48db49b4b499ea197d9c92a3@192.168.0.103) 10.19ms
[I 2025-04-21 18:10:20.561 ServerApp] Kernel started: e12e88d2-2be5-4428-bf82-ac35dbd39d53
[W 2025-04-21 18:11:20.593 ServerApp] Timeout waiting for kernel_info reply from e12e88d2-2be5-4428-bf82-ac35dbd39d53
[I 2025-04-21 18:11:20.594 ServerApp] Connecting to kernel e12e88d2-2be5-4428-bf82-ac35dbd39d53.
Exception in callback _chain_future.<locals>._set_state(<Future finished result={}>, <Future at 0x...returned dict>) at /gpfs/share/apps/miniconda3/gpu/4.9.2/lib/python3.8/asyncio/futures.py:354
handle: <Handle _chain_future.<locals>._set_state(<Future finished result={}>, <Future at 0x...returned dict>) at /gpfs/share/apps/miniconda3/gpu/4.9.2/lib/python3.8/asyncio/futures.py:354>
Traceback (most recent call last):
  File "/gpfs/share/apps/miniconda3/gpu/4.9.2/lib/python3.8/asyncio/events.py", line 81, in _run
    self._context.run(self._callback, *self._args)
  File "/gpfs/share/apps/miniconda3/gpu/4.9.2/lib/python3.8/asyncio/futures.py", line 356, in _set_state
    _copy_future_state(other, future)
  File "/gpfs/share/apps/miniconda3/gpu/4.9.2/lib/python3.8/asyncio/futures.py", line 326, in _copy_future_state
    assert not dest.done()
AssertionError
[I 2025-04-21 21:48:02.020 ServerApp] Starting buffering for 15d09102-e24c-44b4-9de5-9b34cb12cfe7:2cb13977-bfba-4378-9df6-0f26b74e0617
[I 2025-04-21 21:48:02.026 ServerApp] Starting buffering for e12e88d2-2be5-4428-bf82-ac35dbd39d53:fb260753-89be-4f14-b2de-c6994d9b0f8b
[I 2025-04-22 08:37:50.376 ServerApp] 302 GET / (@192.168.0.104) 0.58ms
[I 2025-04-22 08:37:50.438 ServerApp] 302 GET / (@192.168.0.104) 0.34ms
[I 2025-04-22 08:37:50.612 JupyterNotebookApp] 302 GET /tree? (@192.168.0.104) 0.69ms
[I 2025-04-22 08:37:50.612 JupyterNotebookApp] 302 GET /tree? (@192.168.0.104) 0.36ms
[W 2025-04-22 08:37:51.348 ServerApp] wrote error: 'Forbidden'
    Traceback (most recent call last):
      File "/gpfs/data/oermannlab/users/slj9342/.local/lib/python3.8/site-packages/tornado/web.py", line 1788, in _execute
        result = method(*self.path_args, **self.path_kwargs)
      File "/gpfs/data/oermannlab/users/slj9342/.local/lib/python3.8/site-packages/tornado/web.py", line 3289, in wrapper
        url = self.get_login_url()
      File "/gpfs/data/oermannlab/users/slj9342/.local/lib/python3.8/site-packages/jupyter_server/base/handlers.py", line 783, in get_login_url
        raise web.HTTPError(403)
    tornado.web.HTTPError: HTTP 403: Forbidden
[W 2025-04-22 08:37:51.399 ServerApp] 403 GET /api/kernels?1745325471344 (@192.168.0.104) 51.56ms referer=None
[W 2025-04-22 08:37:51.400 ServerApp] wrote error: 'Forbidden'
    Traceback (most recent call last):
      File "/gpfs/data/oermannlab/users/slj9342/.local/lib/python3.8/site-packages/tornado/web.py", line 1788, in _execute
        result = method(*self.path_args, **self.path_kwargs)
      File "/gpfs/data/oermannlab/users/slj9342/.local/lib/python3.8/site-packages/tornado/web.py", line 3289, in wrapper
        url = self.get_login_url()
      File "/gpfs/data/oermannlab/users/slj9342/.local/lib/python3.8/site-packages/jupyter_server/base/handlers.py", line 783, in get_login_url
        raise web.HTTPError(403)
    tornado.web.HTTPError: HTTP 403: Forbidden
[W 2025-04-22 08:37:51.400 ServerApp] 403 GET /api/kernelspecs?1745325471343 (@192.168.0.104) 0.78ms referer=None
[W 2025-04-22 08:37:51.402 ServerApp] wrote error: 'Forbidden'
    Traceback (most recent call last):
      File "/gpfs/data/oermannlab/users/slj9342/.local/lib/python3.8/site-packages/tornado/web.py", line 1788, in _execute
        result = method(*self.path_args, **self.path_kwargs)
      File "/gpfs/data/oermannlab/users/slj9342/.local/lib/python3.8/site-packages/tornado/web.py", line 3289, in wrapper
        url = self.get_login_url()
      File "/gpfs/data/oermannlab/users/slj9342/.local/lib/python3.8/site-packages/jupyter_server/base/handlers.py", line 783, in get_login_url
        raise web.HTTPError(403)
    tornado.web.HTTPError: HTTP 403: Forbidden
[W 2025-04-22 08:37:51.402 ServerApp] 403 GET /api/kernelspecs?1745325471344 (@192.168.0.104) 1.78ms referer=None
[W 2025-04-22 08:37:51.403 ServerApp] wrote error: 'Forbidden'
    Traceback (most recent call last):
      File "/gpfs/data/oermannlab/users/slj9342/.local/lib/python3.8/site-packages/tornado/web.py", line 1788, in _execute
        result = method(*self.path_args, **self.path_kwargs)
      File "/gpfs/data/oermannlab/users/slj9342/.local/lib/python3.8/site-packages/tornado/web.py", line 3289, in wrapper
        url = self.get_login_url()
      File "/gpfs/data/oermannlab/users/slj9342/.local/lib/python3.8/site-packages/jupyter_server/base/handlers.py", line 783, in get_login_url
        raise web.HTTPError(403)
    tornado.web.HTTPError: HTTP 403: Forbidden
[W 2025-04-22 08:37:51.403 ServerApp] 403 GET /api/kernels?1745325471345 (@192.168.0.104) 2.02ms referer=None
[W 2025-04-22 08:37:51.403 ServerApp] wrote error: 'Forbidden'
    Traceback (most recent call last):
      File "/gpfs/data/oermannlab/users/slj9342/.local/lib/python3.8/site-packages/tornado/web.py", line 1788, in _execute
        result = method(*self.path_args, **self.path_kwargs)
      File "/gpfs/data/oermannlab/users/slj9342/.local/lib/python3.8/site-packages/tornado/web.py", line 3289, in wrapper
        url = self.get_login_url()
      File "/gpfs/data/oermannlab/users/slj9342/.local/lib/python3.8/site-packages/jupyter_server/base/handlers.py", line 783, in get_login_url
        raise web.HTTPError(403)
    tornado.web.HTTPError: HTTP 403: Forbidden
[W 2025-04-22 08:37:51.403 ServerApp] 403 GET /api/kernels?1745325471353 (@192.168.0.104) 2.27ms referer=None
[W 2025-04-22 08:37:51.404 ServerApp] wrote error: 'Forbidden'
    Traceback (most recent call last):
      File "/gpfs/data/oermannlab/users/slj9342/.local/lib/python3.8/site-packages/tornado/web.py", line 1788, in _execute
        result = method(*self.path_args, **self.path_kwargs)
      File "/gpfs/data/oermannlab/users/slj9342/.local/lib/python3.8/site-packages/tornado/web.py", line 3289, in wrapper
        url = self.get_login_url()
      File "/gpfs/data/oermannlab/users/slj9342/.local/lib/python3.8/site-packages/jupyter_server/base/handlers.py", line 783, in get_login_url
        raise web.HTTPError(403)
    tornado.web.HTTPError: HTTP 403: Forbidden
[W 2025-04-22 08:37:51.404 ServerApp] 403 GET /api/sessions?1745325471354 (@192.168.0.104) 2.51ms referer=None
[W 2025-04-22 08:37:51.404 ServerApp] wrote error: 'Forbidden'
    Traceback (most recent call last):
      File "/gpfs/data/oermannlab/users/slj9342/.local/lib/python3.8/site-packages/tornado/web.py", line 1788, in _execute
        result = method(*self.path_args, **self.path_kwargs)
      File "/gpfs/data/oermannlab/users/slj9342/.local/lib/python3.8/site-packages/tornado/web.py", line 3289, in wrapper
        url = self.get_login_url()
      File "/gpfs/data/oermannlab/users/slj9342/.local/lib/python3.8/site-packages/jupyter_server/base/handlers.py", line 783, in get_login_url
        raise web.HTTPError(403)
    tornado.web.HTTPError: HTTP 403: Forbidden
[W 2025-04-22 08:37:51.404 ServerApp] 403 GET /api/kernels?1745325471354 (@192.168.0.104) 2.78ms referer=None
[W 2025-04-22 08:37:51.404 ServerApp] wrote error: 'Forbidden'
    Traceback (most recent call last):
      File "/gpfs/data/oermannlab/users/slj9342/.local/lib/python3.8/site-packages/tornado/web.py", line 1788, in _execute
        result = method(*self.path_args, **self.path_kwargs)
      File "/gpfs/data/oermannlab/users/slj9342/.local/lib/python3.8/site-packages/tornado/web.py", line 3289, in wrapper
        url = self.get_login_url()
      File "/gpfs/data/oermannlab/users/slj9342/.local/lib/python3.8/site-packages/jupyter_server/base/handlers.py", line 783, in get_login_url
        raise web.HTTPError(403)
    tornado.web.HTTPError: HTTP 403: Forbidden
[W 2025-04-22 08:37:51.405 ServerApp] 403 GET /api/sessions?1745325471355 (@192.168.0.104) 3.00ms referer=None
[W 2025-04-22 08:37:51.409 ServerApp] wrote error: 'Forbidden'
    Traceback (most recent call last):
      File "/gpfs/data/oermannlab/users/slj9342/.local/lib/python3.8/site-packages/tornado/web.py", line 1788, in _execute
        result = method(*self.path_args, **self.path_kwargs)
      File "/gpfs/data/oermannlab/users/slj9342/.local/lib/python3.8/site-packages/tornado/web.py", line 3289, in wrapper
        url = self.get_login_url()
      File "/gpfs/data/oermannlab/users/slj9342/.local/lib/python3.8/site-packages/jupyter_server/base/handlers.py", line 783, in get_login_url
        raise web.HTTPError(403)
    tornado.web.HTTPError: HTTP 403: Forbidden
[W 2025-04-22 08:37:51.409 ServerApp] 403 GET /api/kernelspecs?1745325471402 (@192.168.0.104) 0.81ms referer=None
[I 2025-04-22 08:37:51.409 ServerApp] 302 GET / (@192.168.0.104) 0.73ms
[W 2025-04-22 08:37:51.410 ServerApp] wrote error: 'Forbidden'
    Traceback (most recent call last):
      File "/gpfs/data/oermannlab/users/slj9342/.local/lib/python3.8/site-packages/tornado/web.py", line 1788, in _execute
        result = method(*self.path_args, **self.path_kwargs)
      File "/gpfs/data/oermannlab/users/slj9342/.local/lib/python3.8/site-packages/tornado/web.py", line 3289, in wrapper
        url = self.get_login_url()
      File "/gpfs/data/oermannlab/users/slj9342/.local/lib/python3.8/site-packages/jupyter_server/base/handlers.py", line 783, in get_login_url
        raise web.HTTPError(403)
    tornado.web.HTTPError: HTTP 403: Forbidden
[W 2025-04-22 08:37:51.410 ServerApp] 403 GET /api/kernelspecs?1745325471404 (@192.168.0.104) 0.52ms referer=None
[I 2025-04-22 08:37:51.415 JupyterNotebookApp] 302 GET /tree? (@192.168.0.104) 0.33ms
[W 2025-04-22 08:37:51.797 ServerApp] wrote error: 'Forbidden'
    Traceback (most recent call last):
      File "/gpfs/data/oermannlab/users/slj9342/.local/lib/python3.8/site-packages/tornado/web.py", line 1788, in _execute
        result = method(*self.path_args, **self.path_kwargs)
      File "/gpfs/data/oermannlab/users/slj9342/.local/lib/python3.8/site-packages/tornado/web.py", line 3289, in wrapper
        url = self.get_login_url()
      File "/gpfs/data/oermannlab/users/slj9342/.local/lib/python3.8/site-packages/jupyter_server/base/handlers.py", line 783, in get_login_url
        raise web.HTTPError(403)
    tornado.web.HTTPError: HTTP 403: Forbidden
[W 2025-04-22 08:37:51.798 ServerApp] 403 GET /api/kernelspecs?1745325471793 (@192.168.0.104) 1.06ms referer=None
[W 2025-04-22 08:37:51.804 ServerApp] wrote error: 'Forbidden'
    Traceback (most recent call last):
      File "/gpfs/data/oermannlab/users/slj9342/.local/lib/python3.8/site-packages/tornado/web.py", line 1788, in _execute
        result = method(*self.path_args, **self.path_kwargs)
      File "/gpfs/data/oermannlab/users/slj9342/.local/lib/python3.8/site-packages/tornado/web.py", line 3289, in wrapper
        url = self.get_login_url()
      File "/gpfs/data/oermannlab/users/slj9342/.local/lib/python3.8/site-packages/jupyter_server/base/handlers.py", line 783, in get_login_url
        raise web.HTTPError(403)
    tornado.web.HTTPError: HTTP 403: Forbidden
[W 2025-04-22 08:37:51.805 ServerApp] 403 GET /api/kernels?1745325471794 (@192.168.0.104) 0.87ms referer=None
[W 2025-04-22 08:37:51.805 ServerApp] wrote error: 'Forbidden'
    Traceback (most recent call last):
      File "/gpfs/data/oermannlab/users/slj9342/.local/lib/python3.8/site-packages/tornado/web.py", line 1788, in _execute
        result = method(*self.path_args, **self.path_kwargs)
      File "/gpfs/data/oermannlab/users/slj9342/.local/lib/python3.8/site-packages/tornado/web.py", line 3289, in wrapper
        url = self.get_login_url()
      File "/gpfs/data/oermannlab/users/slj9342/.local/lib/python3.8/site-packages/jupyter_server/base/handlers.py", line 783, in get_login_url
        raise web.HTTPError(403)
    tornado.web.HTTPError: HTTP 403: Forbidden
[W 2025-04-22 08:37:51.806 ServerApp] 403 GET /api/kernelspecs?1745325471794 (@192.168.0.104) 0.70ms referer=None
[W 2025-04-22 08:37:51.806 ServerApp] wrote error: 'Forbidden'
    Traceback (most recent call last):
      File "/gpfs/data/oermannlab/users/slj9342/.local/lib/python3.8/site-packages/tornado/web.py", line 1788, in _execute
        result = method(*self.path_args, **self.path_kwargs)
      File "/gpfs/data/oermannlab/users/slj9342/.local/lib/python3.8/site-packages/tornado/web.py", line 3289, in wrapper
        url = self.get_login_url()
      File "/gpfs/data/oermannlab/users/slj9342/.local/lib/python3.8/site-packages/jupyter_server/base/handlers.py", line 783, in get_login_url
        raise web.HTTPError(403)
    tornado.web.HTTPError: HTTP 403: Forbidden
[W 2025-04-22 08:37:51.806 ServerApp] 403 GET /api/kernels?1745325471794 (@192.168.0.104) 0.67ms referer=None
[W 2025-04-22 08:37:51.807 ServerApp] wrote error: 'Forbidden'
    Traceback (most recent call last):
      File "/gpfs/data/oermannlab/users/slj9342/.local/lib/python3.8/site-packages/tornado/web.py", line 1788, in _execute
        result = method(*self.path_args, **self.path_kwargs)
      File "/gpfs/data/oermannlab/users/slj9342/.local/lib/python3.8/site-packages/tornado/web.py", line 3289, in wrapper
        url = self.get_login_url()
      File "/gpfs/data/oermannlab/users/slj9342/.local/lib/python3.8/site-packages/jupyter_server/base/handlers.py", line 783, in get_login_url
        raise web.HTTPError(403)
    tornado.web.HTTPError: HTTP 403: Forbidden
[W 2025-04-22 08:37:51.808 ServerApp] 403 GET /api/kernels?1745325471797 (@192.168.0.104) 1.16ms referer=None
[W 2025-04-22 08:37:51.808 ServerApp] wrote error: 'Forbidden'
    Traceback (most recent call last):
      File "/gpfs/data/oermannlab/users/slj9342/.local/lib/python3.8/site-packages/tornado/web.py", line 1788, in _execute
        result = method(*self.path_args, **self.path_kwargs)
      File "/gpfs/data/oermannlab/users/slj9342/.local/lib/python3.8/site-packages/tornado/web.py", line 3289, in wrapper
        url = self.get_login_url()
      File "/gpfs/data/oermannlab/users/slj9342/.local/lib/python3.8/site-packages/jupyter_server/base/handlers.py", line 783, in get_login_url
        raise web.HTTPError(403)
    tornado.web.HTTPError: HTTP 403: Forbidden
[W 2025-04-22 08:37:51.808 ServerApp] 403 GET /api/sessions?1745325471798 (@192.168.0.104) 1.45ms referer=None
[W 2025-04-22 08:37:51.808 ServerApp] wrote error: 'Forbidden'
    Traceback (most recent call last):
      File "/gpfs/data/oermannlab/users/slj9342/.local/lib/python3.8/site-packages/tornado/web.py", line 1788, in _execute
        result = method(*self.path_args, **self.path_kwargs)
      File "/gpfs/data/oermannlab/users/slj9342/.local/lib/python3.8/site-packages/tornado/web.py", line 3289, in wrapper
        url = self.get_login_url()
      File "/gpfs/data/oermannlab/users/slj9342/.local/lib/python3.8/site-packages/jupyter_server/base/handlers.py", line 783, in get_login_url
        raise web.HTTPError(403)
    tornado.web.HTTPError: HTTP 403: Forbidden
[W 2025-04-22 08:37:51.809 ServerApp] 403 GET /api/kernels?1745325471798 (@192.168.0.104) 1.74ms referer=None
[W 2025-04-22 08:37:51.809 ServerApp] wrote error: 'Forbidden'
    Traceback (most recent call last):
      File "/gpfs/data/oermannlab/users/slj9342/.local/lib/python3.8/site-packages/tornado/web.py", line 1788, in _execute
        result = method(*self.path_args, **self.path_kwargs)
      File "/gpfs/data/oermannlab/users/slj9342/.local/lib/python3.8/site-packages/tornado/web.py", line 3289, in wrapper
        url = self.get_login_url()
      File "/gpfs/data/oermannlab/users/slj9342/.local/lib/python3.8/site-packages/jupyter_server/base/handlers.py", line 783, in get_login_url
        raise web.HTTPError(403)
    tornado.web.HTTPError: HTTP 403: Forbidden
[W 2025-04-22 08:37:51.809 ServerApp] 403 GET /api/sessions?1745325471799 (@192.168.0.104) 2.02ms referer=None
[W 2025-04-22 08:37:51.809 ServerApp] wrote error: 'Forbidden'
    Traceback (most recent call last):
      File "/gpfs/data/oermannlab/users/slj9342/.local/lib/python3.8/site-packages/tornado/web.py", line 1788, in _execute
        result = method(*self.path_args, **self.path_kwargs)
      File "/gpfs/data/oermannlab/users/slj9342/.local/lib/python3.8/site-packages/tornado/web.py", line 3289, in wrapper
        url = self.get_login_url()
      File "/gpfs/data/oermannlab/users/slj9342/.local/lib/python3.8/site-packages/jupyter_server/base/handlers.py", line 783, in get_login_url
        raise web.HTTPError(403)
    tornado.web.HTTPError: HTTP 403: Forbidden
[W 2025-04-22 08:37:51.809 ServerApp] 403 GET /api/kernelspecs?1745325471804 (@192.168.0.104) 2.24ms referer=None
[W 2025-04-22 08:37:51.813 ServerApp] wrote error: 'Forbidden'
    Traceback (most recent call last):
      File "/gpfs/data/oermannlab/users/slj9342/.local/lib/python3.8/site-packages/tornado/web.py", line 1788, in _execute
        result = method(*self.path_args, **self.path_kwargs)
      File "/gpfs/data/oermannlab/users/slj9342/.local/lib/python3.8/site-packages/tornado/web.py", line 3289, in wrapper
        url = self.get_login_url()
      File "/gpfs/data/oermannlab/users/slj9342/.local/lib/python3.8/site-packages/jupyter_server/base/handlers.py", line 783, in get_login_url
        raise web.HTTPError(403)
    tornado.web.HTTPError: HTTP 403: Forbidden
[W 2025-04-22 08:37:51.813 ServerApp] 403 GET /api/kernelspecs?1745325471808 (@192.168.0.104) 0.72ms referer=None
[I 2025-04-22 08:37:51.814 ServerApp] 302 GET / (@192.168.0.104) 0.25ms
[I 2025-04-22 08:37:51.842 JupyterNotebookApp] 302 GET /tree? (@192.168.0.104) 0.47ms
[W 2025-04-22 08:37:52.074 ServerApp] wrote error: 'Forbidden'
    Traceback (most recent call last):
      File "/gpfs/data/oermannlab/users/slj9342/.local/lib/python3.8/site-packages/tornado/web.py", line 1788, in _execute
        result = method(*self.path_args, **self.path_kwargs)
      File "/gpfs/data/oermannlab/users/slj9342/.local/lib/python3.8/site-packages/tornado/web.py", line 3289, in wrapper
        url = self.get_login_url()
      File "/gpfs/data/oermannlab/users/slj9342/.local/lib/python3.8/site-packages/jupyter_server/base/handlers.py", line 783, in get_login_url
        raise web.HTTPError(403)
    tornado.web.HTTPError: HTTP 403: Forbidden
[W 2025-04-22 08:37:52.075 ServerApp] 403 GET /api/kernelspecs?1745325472071 (@192.168.0.104) 0.96ms referer=None
[W 2025-04-22 08:37:52.143 ServerApp] wrote error: 'Forbidden'
    Traceback (most recent call last):
      File "/gpfs/data/oermannlab/users/slj9342/.local/lib/python3.8/site-packages/tornado/web.py", line 1788, in _execute
        result = method(*self.path_args, **self.path_kwargs)
      File "/gpfs/data/oermannlab/users/slj9342/.local/lib/python3.8/site-packages/tornado/web.py", line 3289, in wrapper
        url = self.get_login_url()
      File "/gpfs/data/oermannlab/users/slj9342/.local/lib/python3.8/site-packages/jupyter_server/base/handlers.py", line 783, in get_login_url
        raise web.HTTPError(403)
    tornado.web.HTTPError: HTTP 403: Forbidden
[W 2025-04-22 08:37:52.143 ServerApp] 403 GET /api/kernels?1745325472071 (@192.168.0.104) 0.85ms referer=None
[W 2025-04-22 08:37:52.144 ServerApp] wrote error: 'Forbidden'
    Traceback (most recent call last):
      File "/gpfs/data/oermannlab/users/slj9342/.local/lib/python3.8/site-packages/tornado/web.py", line 1788, in _execute
        result = method(*self.path_args, **self.path_kwargs)
      File "/gpfs/data/oermannlab/users/slj9342/.local/lib/python3.8/site-packages/tornado/web.py", line 3289, in wrapper
        url = self.get_login_url()
      File "/gpfs/data/oermannlab/users/slj9342/.local/lib/python3.8/site-packages/jupyter_server/base/handlers.py", line 783, in get_login_url
        raise web.HTTPError(403)
    tornado.web.HTTPError: HTTP 403: Forbidden
[W 2025-04-22 08:37:52.144 ServerApp] 403 GET /api/kernelspecs?1745325472072 (@192.168.0.104) 0.65ms referer=None
[W 2025-04-22 08:37:52.144 ServerApp] wrote error: 'Forbidden'
    Traceback (most recent call last):
      File "/gpfs/data/oermannlab/users/slj9342/.local/lib/python3.8/site-packages/tornado/web.py", line 1788, in _execute
        result = method(*self.path_args, **self.path_kwargs)
      File "/gpfs/data/oermannlab/users/slj9342/.local/lib/python3.8/site-packages/tornado/web.py", line 3289, in wrapper
        url = self.get_login_url()
      File "/gpfs/data/oermannlab/users/slj9342/.local/lib/python3.8/site-packages/jupyter_server/base/handlers.py", line 783, in get_login_url
        raise web.HTTPError(403)
    tornado.web.HTTPError: HTTP 403: Forbidden
[W 2025-04-22 08:37:52.145 ServerApp] 403 GET /api/kernels?1745325472072 (@192.168.0.104) 0.56ms referer=None
[W 2025-04-22 08:37:52.145 ServerApp] wrote error: 'Forbidden'
    Traceback (most recent call last):
      File "/gpfs/data/oermannlab/users/slj9342/.local/lib/python3.8/site-packages/tornado/web.py", line 1788, in _execute
        result = method(*self.path_args, **self.path_kwargs)
      File "/gpfs/data/oermannlab/users/slj9342/.local/lib/python3.8/site-packages/tornado/web.py", line 3289, in wrapper
        url = self.get_login_url()
      File "/gpfs/data/oermannlab/users/slj9342/.local/lib/python3.8/site-packages/jupyter_server/base/handlers.py", line 783, in get_login_url
        raise web.HTTPError(403)
    tornado.web.HTTPError: HTTP 403: Forbidden
[W 2025-04-22 08:37:52.146 ServerApp] 403 GET /api/kernels?1745325472075 (@192.168.0.104) 0.79ms referer=None
[W 2025-04-22 08:37:52.146 ServerApp] wrote error: 'Forbidden'
    Traceback (most recent call last):
      File "/gpfs/data/oermannlab/users/slj9342/.local/lib/python3.8/site-packages/tornado/web.py", line 1788, in _execute
        result = method(*self.path_args, **self.path_kwargs)
      File "/gpfs/data/oermannlab/users/slj9342/.local/lib/python3.8/site-packages/tornado/web.py", line 3289, in wrapper
        url = self.get_login_url()
      File "/gpfs/data/oermannlab/users/slj9342/.local/lib/python3.8/site-packages/jupyter_server/base/handlers.py", line 783, in get_login_url
        raise web.HTTPError(403)
    tornado.web.HTTPError: HTTP 403: Forbidden
[W 2025-04-22 08:37:52.146 ServerApp] 403 GET /api/sessions?1745325472075 (@192.168.0.104) 1.07ms referer=None
[W 2025-04-22 08:37:52.146 ServerApp] wrote error: 'Forbidden'
    Traceback (most recent call last):
      File "/gpfs/data/oermannlab/users/slj9342/.local/lib/python3.8/site-packages/tornado/web.py", line 1788, in _execute
        result = method(*self.path_args, **self.path_kwargs)
      File "/gpfs/data/oermannlab/users/slj9342/.local/lib/python3.8/site-packages/tornado/web.py", line 3289, in wrapper
        url = self.get_login_url()
      File "/gpfs/data/oermannlab/users/slj9342/.local/lib/python3.8/site-packages/jupyter_server/base/handlers.py", line 783, in get_login_url
        raise web.HTTPError(403)
    tornado.web.HTTPError: HTTP 403: Forbidden
[W 2025-04-22 08:37:52.146 ServerApp] 403 GET /api/kernels?1745325472076 (@192.168.0.104) 1.37ms referer=None
[W 2025-04-22 08:37:52.147 ServerApp] wrote error: 'Forbidden'
    Traceback (most recent call last):
      File "/gpfs/data/oermannlab/users/slj9342/.local/lib/python3.8/site-packages/tornado/web.py", line 1788, in _execute
        result = method(*self.path_args, **self.path_kwargs)
      File "/gpfs/data/oermannlab/users/slj9342/.local/lib/python3.8/site-packages/tornado/web.py", line 3289, in wrapper
        url = self.get_login_url()
      File "/gpfs/data/oermannlab/users/slj9342/.local/lib/python3.8/site-packages/jupyter_server/base/handlers.py", line 783, in get_login_url
        raise web.HTTPError(403)
    tornado.web.HTTPError: HTTP 403: Forbidden
[W 2025-04-22 08:37:52.147 ServerApp] 403 GET /api/sessions?1745325472140 (@192.168.0.104) 0.60ms referer=None
[W 2025-04-22 08:37:52.148 ServerApp] wrote error: 'Forbidden'
    Traceback (most recent call last):
      File "/gpfs/data/oermannlab/users/slj9342/.local/lib/python3.8/site-packages/tornado/web.py", line 1788, in _execute
        result = method(*self.path_args, **self.path_kwargs)
      File "/gpfs/data/oermannlab/users/slj9342/.local/lib/python3.8/site-packages/tornado/web.py", line 3289, in wrapper
        url = self.get_login_url()
      File "/gpfs/data/oermannlab/users/slj9342/.local/lib/python3.8/site-packages/jupyter_server/base/handlers.py", line 783, in get_login_url
        raise web.HTTPError(403)
    tornado.web.HTTPError: HTTP 403: Forbidden
[W 2025-04-22 08:37:52.148 ServerApp] 403 GET /api/kernelspecs?1745325472143 (@192.168.0.104) 0.59ms referer=None
[W 2025-04-22 08:37:52.150 ServerApp] wrote error: 'Forbidden'
    Traceback (most recent call last):
      File "/gpfs/data/oermannlab/users/slj9342/.local/lib/python3.8/site-packages/tornado/web.py", line 1788, in _execute
        result = method(*self.path_args, **self.path_kwargs)
      File "/gpfs/data/oermannlab/users/slj9342/.local/lib/python3.8/site-packages/tornado/web.py", line 3289, in wrapper
        url = self.get_login_url()
      File "/gpfs/data/oermannlab/users/slj9342/.local/lib/python3.8/site-packages/jupyter_server/base/handlers.py", line 783, in get_login_url
        raise web.HTTPError(403)
    tornado.web.HTTPError: HTTP 403: Forbidden
[W 2025-04-22 08:37:52.150 ServerApp] 403 GET /api/kernelspecs?1745325472145 (@192.168.0.104) 0.48ms referer=None
[W 2025-04-22 08:40:28.234 ServerApp] wrote error: 'Forbidden'
    Traceback (most recent call last):
      File "/gpfs/data/oermannlab/users/slj9342/.local/lib/python3.8/site-packages/tornado/web.py", line 1788, in _execute
        result = method(*self.path_args, **self.path_kwargs)
      File "/gpfs/data/oermannlab/users/slj9342/.local/lib/python3.8/site-packages/tornado/web.py", line 3289, in wrapper
        url = self.get_login_url()
      File "/gpfs/data/oermannlab/users/slj9342/.local/lib/python3.8/site-packages/jupyter_server/base/handlers.py", line 783, in get_login_url
        raise web.HTTPError(403)
    tornado.web.HTTPError: HTTP 403: Forbidden
[W 2025-04-22 08:40:28.237 ServerApp] 403 GET /api/kernelspecs?1745325628225 (@192.168.0.104) 3.47ms referer=None
[W 2025-04-22 08:40:28.238 ServerApp] wrote error: 'Forbidden'
    Traceback (most recent call last):
      File "/gpfs/data/oermannlab/users/slj9342/.local/lib/python3.8/site-packages/tornado/web.py", line 1788, in _execute
        result = method(*self.path_args, **self.path_kwargs)
      File "/gpfs/data/oermannlab/users/slj9342/.local/lib/python3.8/site-packages/tornado/web.py", line 3289, in wrapper
        url = self.get_login_url()
      File "/gpfs/data/oermannlab/users/slj9342/.local/lib/python3.8/site-packages/jupyter_server/base/handlers.py", line 783, in get_login_url
        raise web.HTTPError(403)
    tornado.web.HTTPError: HTTP 403: Forbidden
[W 2025-04-22 08:40:28.238 ServerApp] 403 GET /api/kernels?1745325628225 (@192.168.0.104) 0.81ms referer=None
[W 2025-04-22 08:40:28.239 ServerApp] wrote error: 'Forbidden'
    Traceback (most recent call last):
      File "/gpfs/data/oermannlab/users/slj9342/.local/lib/python3.8/site-packages/tornado/web.py", line 1788, in _execute
        result = method(*self.path_args, **self.path_kwargs)
      File "/gpfs/data/oermannlab/users/slj9342/.local/lib/python3.8/site-packages/tornado/web.py", line 3289, in wrapper
        url = self.get_login_url()
      File "/gpfs/data/oermannlab/users/slj9342/.local/lib/python3.8/site-packages/jupyter_server/base/handlers.py", line 783, in get_login_url
        raise web.HTTPError(403)
    tornado.web.HTTPError: HTTP 403: Forbidden
[W 2025-04-22 08:40:28.240 ServerApp] 403 GET /api/kernels?1745325628226 (@192.168.0.104) 1.19ms referer=None
[W 2025-04-22 08:40:28.240 ServerApp] wrote error: 'Forbidden'
    Traceback (most recent call last):
      File "/gpfs/data/oermannlab/users/slj9342/.local/lib/python3.8/site-packages/tornado/web.py", line 1788, in _execute
        result = method(*self.path_args, **self.path_kwargs)
      File "/gpfs/data/oermannlab/users/slj9342/.local/lib/python3.8/site-packages/tornado/web.py", line 3289, in wrapper
        url = self.get_login_url()
      File "/gpfs/data/oermannlab/users/slj9342/.local/lib/python3.8/site-packages/jupyter_server/base/handlers.py", line 783, in get_login_url
        raise web.HTTPError(403)
    tornado.web.HTTPError: HTTP 403: Forbidden
[W 2025-04-22 08:40:28.240 ServerApp] 403 GET /api/kernelspecs?1745325628226 (@192.168.0.104) 1.50ms referer=None
[W 2025-04-22 08:40:28.240 ServerApp] wrote error: 'Forbidden'
    Traceback (most recent call last):
      File "/gpfs/data/oermannlab/users/slj9342/.local/lib/python3.8/site-packages/tornado/web.py", line 1788, in _execute
        result = method(*self.path_args, **self.path_kwargs)
      File "/gpfs/data/oermannlab/users/slj9342/.local/lib/python3.8/site-packages/tornado/web.py", line 3289, in wrapper
        url = self.get_login_url()
      File "/gpfs/data/oermannlab/users/slj9342/.local/lib/python3.8/site-packages/jupyter_server/base/handlers.py", line 783, in get_login_url
        raise web.HTTPError(403)
    tornado.web.HTTPError: HTTP 403: Forbidden
[W 2025-04-22 08:40:28.240 ServerApp] 403 GET /api/kernels?1745325628228 (@192.168.0.104) 1.81ms referer=None
[W 2025-04-22 08:40:28.241 ServerApp] wrote error: 'Forbidden'
    Traceback (most recent call last):
      File "/gpfs/data/oermannlab/users/slj9342/.local/lib/python3.8/site-packages/tornado/web.py", line 1788, in _execute
        result = method(*self.path_args, **self.path_kwargs)
      File "/gpfs/data/oermannlab/users/slj9342/.local/lib/python3.8/site-packages/tornado/web.py", line 3289, in wrapper
        url = self.get_login_url()
      File "/gpfs/data/oermannlab/users/slj9342/.local/lib/python3.8/site-packages/jupyter_server/base/handlers.py", line 783, in get_login_url
        raise web.HTTPError(403)
    tornado.web.HTTPError: HTTP 403: Forbidden
[W 2025-04-22 08:40:28.241 ServerApp] 403 GET /api/sessions?1745325628229 (@192.168.0.104) 2.11ms referer=None
[W 2025-04-22 08:40:28.241 ServerApp] wrote error: 'Forbidden'
    Traceback (most recent call last):
      File "/gpfs/data/oermannlab/users/slj9342/.local/lib/python3.8/site-packages/tornado/web.py", line 1788, in _execute
        result = method(*self.path_args, **self.path_kwargs)
      File "/gpfs/data/oermannlab/users/slj9342/.local/lib/python3.8/site-packages/tornado/web.py", line 3289, in wrapper
        url = self.get_login_url()
      File "/gpfs/data/oermannlab/users/slj9342/.local/lib/python3.8/site-packages/jupyter_server/base/handlers.py", line 783, in get_login_url
        raise web.HTTPError(403)
    tornado.web.HTTPError: HTTP 403: Forbidden
[W 2025-04-22 08:40:28.241 ServerApp] 403 GET /api/kernels?1745325628230 (@192.168.0.104) 2.42ms referer=None
[W 2025-04-22 08:40:28.241 ServerApp] wrote error: 'Forbidden'
    Traceback (most recent call last):
      File "/gpfs/data/oermannlab/users/slj9342/.local/lib/python3.8/site-packages/tornado/web.py", line 1788, in _execute
        result = method(*self.path_args, **self.path_kwargs)
      File "/gpfs/data/oermannlab/users/slj9342/.local/lib/python3.8/site-packages/tornado/web.py", line 3289, in wrapper
        url = self.get_login_url()
      File "/gpfs/data/oermannlab/users/slj9342/.local/lib/python3.8/site-packages/jupyter_server/base/handlers.py", line 783, in get_login_url
        raise web.HTTPError(403)
    tornado.web.HTTPError: HTTP 403: Forbidden
[W 2025-04-22 08:40:28.242 ServerApp] 403 GET /api/sessions?1745325628230 (@192.168.0.104) 2.72ms referer=None
[W 2025-04-22 08:40:28.242 ServerApp] wrote error: 'Forbidden'
    Traceback (most recent call last):
      File "/gpfs/data/oermannlab/users/slj9342/.local/lib/python3.8/site-packages/tornado/web.py", line 1788, in _execute
        result = method(*self.path_args, **self.path_kwargs)
      File "/gpfs/data/oermannlab/users/slj9342/.local/lib/python3.8/site-packages/tornado/web.py", line 3289, in wrapper
        url = self.get_login_url()
      File "/gpfs/data/oermannlab/users/slj9342/.local/lib/python3.8/site-packages/jupyter_server/base/handlers.py", line 783, in get_login_url
        raise web.HTTPError(403)
    tornado.web.HTTPError: HTTP 403: Forbidden
[W 2025-04-22 08:40:28.243 ServerApp] 403 GET /api/kernelspecs?1745325628239 (@192.168.0.104) 0.54ms referer=None
[W 2025-04-22 08:40:28.244 ServerApp] wrote error: 'Forbidden'
    Traceback (most recent call last):
      File "/gpfs/data/oermannlab/users/slj9342/.local/lib/python3.8/site-packages/tornado/web.py", line 1788, in _execute
        result = method(*self.path_args, **self.path_kwargs)
      File "/gpfs/data/oermannlab/users/slj9342/.local/lib/python3.8/site-packages/tornado/web.py", line 3289, in wrapper
        url = self.get_login_url()
      File "/gpfs/data/oermannlab/users/slj9342/.local/lib/python3.8/site-packages/jupyter_server/base/handlers.py", line 783, in get_login_url
        raise web.HTTPError(403)
    tornado.web.HTTPError: HTTP 403: Forbidden
[W 2025-04-22 08:40:28.245 ServerApp] 403 GET /api/kernelspecs?1745325628241 (@192.168.0.104) 0.56ms referer=None
[I 2025-04-22 08:49:06.393 ServerApp] 302 GET / (@192.168.0.103) 0.36ms
[I 2025-04-22 08:49:06.489 ServerApp] 302 GET / (@192.168.0.103) 0.35ms
[I 2025-04-22 08:49:06.848 JupyterNotebookApp] 302 GET /tree? (@192.168.0.103) 0.46ms
[I 2025-04-22 08:49:06.848 JupyterNotebookApp] 302 GET /tree? (@192.168.0.103) 0.31ms
[W 2025-04-22 08:49:08.660 ServerApp] wrote error: 'Forbidden'
    Traceback (most recent call last):
      File "/gpfs/data/oermannlab/users/slj9342/.local/lib/python3.8/site-packages/tornado/web.py", line 1788, in _execute
        result = method(*self.path_args, **self.path_kwargs)
      File "/gpfs/data/oermannlab/users/slj9342/.local/lib/python3.8/site-packages/tornado/web.py", line 3289, in wrapper
        url = self.get_login_url()
      File "/gpfs/data/oermannlab/users/slj9342/.local/lib/python3.8/site-packages/jupyter_server/base/handlers.py", line 783, in get_login_url
        raise web.HTTPError(403)
    tornado.web.HTTPError: HTTP 403: Forbidden
[W 2025-04-22 08:49:08.662 ServerApp] 403 GET /api/kernelspecs?1745326148496 (@192.168.0.103) 3.00ms referer=None
[W 2025-04-22 08:49:08.663 ServerApp] wrote error: 'Forbidden'
    Traceback (most recent call last):
      File "/gpfs/data/oermannlab/users/slj9342/.local/lib/python3.8/site-packages/tornado/web.py", line 1788, in _execute
        result = method(*self.path_args, **self.path_kwargs)
      File "/gpfs/data/oermannlab/users/slj9342/.local/lib/python3.8/site-packages/tornado/web.py", line 3289, in wrapper
        url = self.get_login_url()
      File "/gpfs/data/oermannlab/users/slj9342/.local/lib/python3.8/site-packages/jupyter_server/base/handlers.py", line 783, in get_login_url
        raise web.HTTPError(403)
    tornado.web.HTTPError: HTTP 403: Forbidden
[W 2025-04-22 08:49:08.663 ServerApp] 403 GET /api/kernels?1745326148497 (@192.168.0.103) 0.63ms referer=None
[W 2025-04-22 08:49:08.910 ServerApp] wrote error: 'Forbidden'
    Traceback (most recent call last):
      File "/gpfs/data/oermannlab/users/slj9342/.local/lib/python3.8/site-packages/tornado/web.py", line 1788, in _execute
        result = method(*self.path_args, **self.path_kwargs)
      File "/gpfs/data/oermannlab/users/slj9342/.local/lib/python3.8/site-packages/tornado/web.py", line 3289, in wrapper
        url = self.get_login_url()
      File "/gpfs/data/oermannlab/users/slj9342/.local/lib/python3.8/site-packages/jupyter_server/base/handlers.py", line 783, in get_login_url
        raise web.HTTPError(403)
    tornado.web.HTTPError: HTTP 403: Forbidden
[W 2025-04-22 08:49:08.910 ServerApp] 403 GET /api/kernels?1745326148660 (@192.168.0.103) 0.83ms referer=None
[W 2025-04-22 08:49:08.911 ServerApp] wrote error: 'Forbidden'
    Traceback (most recent call last):
      File "/gpfs/data/oermannlab/users/slj9342/.local/lib/python3.8/site-packages/tornado/web.py", line 1788, in _execute
        result = method(*self.path_args, **self.path_kwargs)
      File "/gpfs/data/oermannlab/users/slj9342/.local/lib/python3.8/site-packages/tornado/web.py", line 3289, in wrapper
        url = self.get_login_url()
      File "/gpfs/data/oermannlab/users/slj9342/.local/lib/python3.8/site-packages/jupyter_server/base/handlers.py", line 783, in get_login_url
        raise web.HTTPError(403)
    tornado.web.HTTPError: HTTP 403: Forbidden
[W 2025-04-22 08:49:08.911 ServerApp] 403 GET /api/sessions?1745326148662 (@192.168.0.103) 0.57ms referer=None
[W 2025-04-22 08:49:08.924 ServerApp] wrote error: 'Forbidden'
    Traceback (most recent call last):
      File "/gpfs/data/oermannlab/users/slj9342/.local/lib/python3.8/site-packages/tornado/web.py", line 1788, in _execute
        result = method(*self.path_args, **self.path_kwargs)
      File "/gpfs/data/oermannlab/users/slj9342/.local/lib/python3.8/site-packages/tornado/web.py", line 3289, in wrapper
        url = self.get_login_url()
      File "/gpfs/data/oermannlab/users/slj9342/.local/lib/python3.8/site-packages/jupyter_server/base/handlers.py", line 783, in get_login_url
        raise web.HTTPError(403)
    tornado.web.HTTPError: HTTP 403: Forbidden
[W 2025-04-22 08:49:08.924 ServerApp] 403 GET /api/kernelspecs?1745326148897 (@192.168.0.103) 0.71ms referer=None
[I 2025-04-22 08:49:09.037 ServerApp] 302 GET / (@192.168.0.103) 0.36ms
[I 2025-04-22 08:49:09.160 JupyterNotebookApp] 302 GET /tree? (@192.168.0.103) 0.41ms
[W 2025-04-22 08:49:09.436 ServerApp] wrote error: 'Forbidden'
    Traceback (most recent call last):
      File "/gpfs/data/oermannlab/users/slj9342/.local/lib/python3.8/site-packages/tornado/web.py", line 1788, in _execute
        result = method(*self.path_args, **self.path_kwargs)
      File "/gpfs/data/oermannlab/users/slj9342/.local/lib/python3.8/site-packages/tornado/web.py", line 3289, in wrapper
        url = self.get_login_url()
      File "/gpfs/data/oermannlab/users/slj9342/.local/lib/python3.8/site-packages/jupyter_server/base/handlers.py", line 783, in get_login_url
        raise web.HTTPError(403)
    tornado.web.HTTPError: HTTP 403: Forbidden
[W 2025-04-22 08:49:09.436 ServerApp] 403 GET /api/kernelspecs?1745326149433 (@192.168.0.103) 0.91ms referer=None
[W 2025-04-22 08:49:09.456 ServerApp] wrote error: 'Forbidden'
    Traceback (most recent call last):
      File "/gpfs/data/oermannlab/users/slj9342/.local/lib/python3.8/site-packages/tornado/web.py", line 1788, in _execute
        result = method(*self.path_args, **self.path_kwargs)
      File "/gpfs/data/oermannlab/users/slj9342/.local/lib/python3.8/site-packages/tornado/web.py", line 3289, in wrapper
        url = self.get_login_url()
      File "/gpfs/data/oermannlab/users/slj9342/.local/lib/python3.8/site-packages/jupyter_server/base/handlers.py", line 783, in get_login_url
        raise web.HTTPError(403)
    tornado.web.HTTPError: HTTP 403: Forbidden
[W 2025-04-22 08:49:09.456 ServerApp] 403 GET /api/kernels?1745326149433 (@192.168.0.103) 0.80ms referer=None
[W 2025-04-22 08:49:09.458 ServerApp] wrote error: 'Forbidden'
    Traceback (most recent call last):
      File "/gpfs/data/oermannlab/users/slj9342/.local/lib/python3.8/site-packages/tornado/web.py", line 1788, in _execute
        result = method(*self.path_args, **self.path_kwargs)
      File "/gpfs/data/oermannlab/users/slj9342/.local/lib/python3.8/site-packages/tornado/web.py", line 3289, in wrapper
        url = self.get_login_url()
      File "/gpfs/data/oermannlab/users/slj9342/.local/lib/python3.8/site-packages/jupyter_server/base/handlers.py", line 783, in get_login_url
        raise web.HTTPError(403)
    tornado.web.HTTPError: HTTP 403: Forbidden
[W 2025-04-22 08:49:09.458 ServerApp] 403 GET /api/kernels?1745326149451 (@192.168.0.103) 0.70ms referer=None
[W 2025-04-22 08:49:09.459 ServerApp] wrote error: 'Forbidden'
    Traceback (most recent call last):
      File "/gpfs/data/oermannlab/users/slj9342/.local/lib/python3.8/site-packages/tornado/web.py", line 1788, in _execute
        result = method(*self.path_args, **self.path_kwargs)
      File "/gpfs/data/oermannlab/users/slj9342/.local/lib/python3.8/site-packages/tornado/web.py", line 3289, in wrapper
        url = self.get_login_url()
      File "/gpfs/data/oermannlab/users/slj9342/.local/lib/python3.8/site-packages/jupyter_server/base/handlers.py", line 783, in get_login_url
        raise web.HTTPError(403)
    tornado.web.HTTPError: HTTP 403: Forbidden
[W 2025-04-22 08:49:09.459 ServerApp] 403 GET /api/sessions?1745326149452 (@192.168.0.103) 0.62ms referer=None
[W 2025-04-22 08:49:09.459 ServerApp] wrote error: 'Forbidden'
    Traceback (most recent call last):
      File "/gpfs/data/oermannlab/users/slj9342/.local/lib/python3.8/site-packages/tornado/web.py", line 1788, in _execute
        result = method(*self.path_args, **self.path_kwargs)
      File "/gpfs/data/oermannlab/users/slj9342/.local/lib/python3.8/site-packages/tornado/web.py", line 3289, in wrapper
        url = self.get_login_url()
      File "/gpfs/data/oermannlab/users/slj9342/.local/lib/python3.8/site-packages/jupyter_server/base/handlers.py", line 783, in get_login_url
        raise web.HTTPError(403)
    tornado.web.HTTPError: HTTP 403: Forbidden
[W 2025-04-22 08:49:09.460 ServerApp] 403 GET /api/kernelspecs?1745326149455 (@192.168.0.103) 0.50ms referer=None
[I 2025-04-22 08:49:09.699 ServerApp] 302 GET / (@192.168.0.103) 0.34ms
[I 2025-04-22 08:49:09.714 JupyterNotebookApp] 302 GET /tree? (@192.168.0.103) 0.50ms
[W 2025-04-22 08:49:09.930 ServerApp] wrote error: 'Forbidden'
    Traceback (most recent call last):
      File "/gpfs/data/oermannlab/users/slj9342/.local/lib/python3.8/site-packages/tornado/web.py", line 1788, in _execute
        result = method(*self.path_args, **self.path_kwargs)
      File "/gpfs/data/oermannlab/users/slj9342/.local/lib/python3.8/site-packages/tornado/web.py", line 3289, in wrapper
        url = self.get_login_url()
      File "/gpfs/data/oermannlab/users/slj9342/.local/lib/python3.8/site-packages/jupyter_server/base/handlers.py", line 783, in get_login_url
        raise web.HTTPError(403)
    tornado.web.HTTPError: HTTP 403: Forbidden
[W 2025-04-22 08:49:09.931 ServerApp] 403 GET /api/kernelspecs?1745326149928 (@192.168.0.103) 0.90ms referer=None
[W 2025-04-22 08:49:10.009 ServerApp] wrote error: 'Forbidden'
    Traceback (most recent call last):
      File "/gpfs/data/oermannlab/users/slj9342/.local/lib/python3.8/site-packages/tornado/web.py", line 1788, in _execute
        result = method(*self.path_args, **self.path_kwargs)
      File "/gpfs/data/oermannlab/users/slj9342/.local/lib/python3.8/site-packages/tornado/web.py", line 3289, in wrapper
        url = self.get_login_url()
      File "/gpfs/data/oermannlab/users/slj9342/.local/lib/python3.8/site-packages/jupyter_server/base/handlers.py", line 783, in get_login_url
        raise web.HTTPError(403)
    tornado.web.HTTPError: HTTP 403: Forbidden
[W 2025-04-22 08:49:10.009 ServerApp] 403 GET /api/kernels?1745326149928 (@192.168.0.103) 0.79ms referer=None
[W 2025-04-22 08:49:10.088 ServerApp] wrote error: 'Forbidden'
    Traceback (most recent call last):
      File "/gpfs/data/oermannlab/users/slj9342/.local/lib/python3.8/site-packages/tornado/web.py", line 1788, in _execute
        result = method(*self.path_args, **self.path_kwargs)
      File "/gpfs/data/oermannlab/users/slj9342/.local/lib/python3.8/site-packages/tornado/web.py", line 3289, in wrapper
        url = self.get_login_url()
      File "/gpfs/data/oermannlab/users/slj9342/.local/lib/python3.8/site-packages/jupyter_server/base/handlers.py", line 783, in get_login_url
        raise web.HTTPError(403)
    tornado.web.HTTPError: HTTP 403: Forbidden
[W 2025-04-22 08:49:10.088 ServerApp] 403 GET /api/kernels?1745326150005 (@192.168.0.103) 0.89ms referer=None
[W 2025-04-22 08:49:10.089 ServerApp] wrote error: 'Forbidden'
    Traceback (most recent call last):
      File "/gpfs/data/oermannlab/users/slj9342/.local/lib/python3.8/site-packages/tornado/web.py", line 1788, in _execute
        result = method(*self.path_args, **self.path_kwargs)
      File "/gpfs/data/oermannlab/users/slj9342/.local/lib/python3.8/site-packages/tornado/web.py", line 3289, in wrapper
        url = self.get_login_url()
      File "/gpfs/data/oermannlab/users/slj9342/.local/lib/python3.8/site-packages/jupyter_server/base/handlers.py", line 783, in get_login_url
        raise web.HTTPError(403)
    tornado.web.HTTPError: HTTP 403: Forbidden
[W 2025-04-22 08:49:10.089 ServerApp] 403 GET /api/sessions?1745326150006 (@192.168.0.103) 0.56ms referer=None
[W 2025-04-22 08:49:10.644 ServerApp] wrote error: 'Forbidden'
    Traceback (most recent call last):
      File "/gpfs/data/oermannlab/users/slj9342/.local/lib/python3.8/site-packages/tornado/web.py", line 1788, in _execute
        result = method(*self.path_args, **self.path_kwargs)
      File "/gpfs/data/oermannlab/users/slj9342/.local/lib/python3.8/site-packages/tornado/web.py", line 3289, in wrapper
        url = self.get_login_url()
      File "/gpfs/data/oermannlab/users/slj9342/.local/lib/python3.8/site-packages/jupyter_server/base/handlers.py", line 783, in get_login_url
        raise web.HTTPError(403)
    tornado.web.HTTPError: HTTP 403: Forbidden
[W 2025-04-22 08:49:10.645 ServerApp] 403 GET /api/kernelspecs?1745326150065 (@192.168.0.103) 0.89ms referer=None
[W 2025-04-22 08:49:12.625 ServerApp] wrote error: 'Forbidden'
    Traceback (most recent call last):
      File "/gpfs/data/oermannlab/users/slj9342/.local/lib/python3.8/site-packages/tornado/web.py", line 1788, in _execute
        result = method(*self.path_args, **self.path_kwargs)
      File "/gpfs/data/oermannlab/users/slj9342/.local/lib/python3.8/site-packages/tornado/web.py", line 3289, in wrapper
        url = self.get_login_url()
      File "/gpfs/data/oermannlab/users/slj9342/.local/lib/python3.8/site-packages/jupyter_server/base/handlers.py", line 783, in get_login_url
        raise web.HTTPError(403)
    tornado.web.HTTPError: HTTP 403: Forbidden
[W 2025-04-22 08:49:12.625 ServerApp] 403 GET /api/kernels?1745326152574 (@192.168.0.103) 0.86ms referer=None
[W 2025-04-22 08:49:12.626 ServerApp] wrote error: 'Forbidden'
    Traceback (most recent call last):
      File "/gpfs/data/oermannlab/users/slj9342/.local/lib/python3.8/site-packages/tornado/web.py", line 1788, in _execute
        result = method(*self.path_args, **self.path_kwargs)
      File "/gpfs/data/oermannlab/users/slj9342/.local/lib/python3.8/site-packages/tornado/web.py", line 3289, in wrapper
        url = self.get_login_url()
      File "/gpfs/data/oermannlab/users/slj9342/.local/lib/python3.8/site-packages/jupyter_server/base/handlers.py", line 783, in get_login_url
        raise web.HTTPError(403)
    tornado.web.HTTPError: HTTP 403: Forbidden
[W 2025-04-22 08:49:12.626 ServerApp] 403 GET /api/kernelspecs?1745326152573 (@192.168.0.103) 0.83ms referer=None
[W 2025-04-22 08:49:12.627 ServerApp] wrote error: 'Forbidden'
    Traceback (most recent call last):
      File "/gpfs/data/oermannlab/users/slj9342/.local/lib/python3.8/site-packages/tornado/web.py", line 1788, in _execute
        result = method(*self.path_args, **self.path_kwargs)
      File "/gpfs/data/oermannlab/users/slj9342/.local/lib/python3.8/site-packages/tornado/web.py", line 3289, in wrapper
        url = self.get_login_url()
      File "/gpfs/data/oermannlab/users/slj9342/.local/lib/python3.8/site-packages/jupyter_server/base/handlers.py", line 783, in get_login_url
        raise web.HTTPError(403)
    tornado.web.HTTPError: HTTP 403: Forbidden
[W 2025-04-22 08:49:12.627 ServerApp] 403 GET /api/kernels?1745326152594 (@192.168.0.103) 1.08ms referer=None
[W 2025-04-22 08:49:12.627 ServerApp] wrote error: 'Forbidden'
    Traceback (most recent call last):
      File "/gpfs/data/oermannlab/users/slj9342/.local/lib/python3.8/site-packages/tornado/web.py", line 1788, in _execute
        result = method(*self.path_args, **self.path_kwargs)
      File "/gpfs/data/oermannlab/users/slj9342/.local/lib/python3.8/site-packages/tornado/web.py", line 3289, in wrapper
        url = self.get_login_url()
      File "/gpfs/data/oermannlab/users/slj9342/.local/lib/python3.8/site-packages/jupyter_server/base/handlers.py", line 783, in get_login_url
        raise web.HTTPError(403)
    tornado.web.HTTPError: HTTP 403: Forbidden
[W 2025-04-22 08:49:12.627 ServerApp] 403 GET /api/sessions?1745326152595 (@192.168.0.103) 1.38ms referer=None
slurmstepd-a100-4032: error: *** JOB 63170465 ON a100-4032 CANCELLED AT 2025-04-22T09:24:30 ***
