
Terminal command to create your ssh tunnel
ssh -N -L 8515:a100-4005:8515 slj9342@bigpurple.nyumc.org
Windows MobaXterm info
Forwarded port:same as remote port
Remote server: a100-4005
Remote port: 8515
SSH server: bigpurple.nyumc.org
SSH login: slj9342
SSH port: 22
Use a Browser on your local machine to go to:
localhost:8515/lab?token=  (prefix w/ https:// if using password)

[I 2025-04-15 09:27:14.777 ServerApp] Extension package jupyter_lsp took 0.1915s to import
[I 2025-04-15 09:27:15.307 ServerApp] jupyter_lsp | extension was successfully linked.
[I 2025-04-15 09:27:15.311 ServerApp] jupyter_server_terminals | extension was successfully linked.
[I 2025-04-15 09:27:15.316 ServerApp] jupyterlab | extension was successfully linked.
[I 2025-04-15 09:27:15.319 ServerApp] notebook | extension was successfully linked.
[I 2025-04-15 09:27:18.963 ServerApp] notebook_shim | extension was successfully linked.
[I 2025-04-15 09:27:19.120 ServerApp] notebook_shim | extension was successfully loaded.
[I 2025-04-15 09:27:19.121 ServerApp] jupyter_lsp | extension was successfully loaded.
[I 2025-04-15 09:27:19.122 ServerApp] jupyter_server_terminals | extension was successfully loaded.
[I 2025-04-15 09:27:19.129 LabApp] JupyterLab extension loaded from /gpfs/data/oermannlab/users/slj9342/.local/lib/python3.8/site-packages/jupyterlab
[I 2025-04-15 09:27:19.129 LabApp] JupyterLab application directory is /gpfs/data/oermannlab/users/slj9342/.local/share/jupyter/lab
[I 2025-04-15 09:27:19.130 LabApp] Extension Manager is 'pypi'.
[I 2025-04-15 09:27:19.508 ServerApp] jupyterlab | extension was successfully loaded.
[I 2025-04-15 09:27:19.512 ServerApp] notebook | extension was successfully loaded.
[I 2025-04-15 09:27:19.512 ServerApp] Serving notebooks from local directory: /gpfs/data/oermannlab/users/slj9342/dl4med_final_project
[I 2025-04-15 09:27:19.512 ServerApp] Jupyter Server 2.14.2 is running at:
[I 2025-04-15 09:27:19.512 ServerApp] http://a100-4005:8515/tree?token=2da3b37beebf887a64e9b5ab3606ea46df160d193b0b2e3a
[I 2025-04-15 09:27:19.512 ServerApp]     http://127.0.0.1:8515/tree?token=2da3b37beebf887a64e9b5ab3606ea46df160d193b0b2e3a
[I 2025-04-15 09:27:19.512 ServerApp] Use Control-C to stop this server and shut down all kernels (twice to skip confirmation).
[C 2025-04-15 09:27:19.519 ServerApp] 
    
    To access the server, open this file in a browser:
        file:///gpfs/data/oermannlab/users/slj9342/.local/share/jupyter/runtime/jpserver-2670793-open.html
    Or copy and paste one of these URLs:
        http://a100-4005:8515/tree?token=2da3b37beebf887a64e9b5ab3606ea46df160d193b0b2e3a
        http://127.0.0.1:8515/tree?token=2da3b37beebf887a64e9b5ab3606ea46df160d193b0b2e3a
[I 2025-04-15 09:27:19.546 ServerApp] Skipped non-installed server(s): bash-language-server, dockerfile-language-server-nodejs, javascript-typescript-langserver, jedi-language-server, julia-language-server, pyright, python-language-server, python-lsp-server, r-languageserver, sql-language-server, texlab, typescript-language-server, unified-language-server, vscode-css-languageserver-bin, vscode-html-languageserver-bin, vscode-json-languageserver-bin, yaml-language-server
[W 2025-04-15 09:27:36.356 ServerApp] 404 GET /hub/api (@192.168.0.103) 935.32ms referer=None
[I 2025-04-15 09:27:36.360 ServerApp] 302 GET / (@192.168.0.103) 0.32ms
[I 2025-04-15 09:27:36.364 JupyterNotebookApp] 302 GET /tree? (@192.168.0.103) 0.41ms
[I 2025-04-15 09:27:44.000 ServerApp] User 8927169f53704206babe0eb82825c982 logged in.
[I 2025-04-15 09:27:44.001 ServerApp] 302 POST /login? (8927169f53704206babe0eb82825c982@192.168.0.103) 1.91ms
[I 2025-04-15 09:27:53.024 ServerApp] Kernel started: b52d6b9b-9ad3-4ea2-a3d0-1dcd3f4cd6e8
[I 2025-04-15 09:28:02.608 ServerApp] Connecting to kernel b52d6b9b-9ad3-4ea2-a3d0-1dcd3f4cd6e8.
[I 2025-04-15 11:18:02.177 ServerApp] Kernel interrupted: b52d6b9b-9ad3-4ea2-a3d0-1dcd3f4cd6e8
[I 2025-04-15 12:20:59.235 ServerApp] Kernel interrupted: b52d6b9b-9ad3-4ea2-a3d0-1dcd3f4cd6e8
[I 2025-04-15 12:21:30.160 ServerApp] Kernel interrupted: b52d6b9b-9ad3-4ea2-a3d0-1dcd3f4cd6e8
[I 2025-04-15 17:00:10.246 ServerApp] Starting buffering for b52d6b9b-9ad3-4ea2-a3d0-1dcd3f4cd6e8:e475bae9-a9c7-494c-98ed-ecb04bffdd8c
[I 2025-04-15 17:01:40.490 ServerApp] 302 GET / (@192.168.0.104) 0.33ms
[I 2025-04-15 17:01:43.649 JupyterNotebookApp] 302 GET /tree? (@192.168.0.104) 0.49ms
[I 2025-04-15 17:01:55.141 ServerApp] User 5ad7768b918a4727b75321e4e98b2c9a logged in.
[I 2025-04-15 17:01:55.142 ServerApp] 302 POST /login? (5ad7768b918a4727b75321e4e98b2c9a@192.168.0.104) 1.50ms
[I 2025-04-15 17:01:59.749 ServerApp] Connecting to kernel b52d6b9b-9ad3-4ea2-a3d0-1dcd3f4cd6e8.
[W 2025-04-15 17:02:00.621 ServerApp] 404 GET /nbextensions/jupyter-js-widgets/extension.js (@192.168.0.104) 1.76ms referer=None
[W 2025-04-15 17:02:00.622 ServerApp] 404 GET /nbextensions/jupyter-js-widgets/extension.js (@192.168.0.104) 2.73ms referer=None
[I 2025-04-15 18:35:01.440 ServerApp] Starting buffering for b52d6b9b-9ad3-4ea2-a3d0-1dcd3f4cd6e8:199eb480-645b-4340-95e4-0aa68d55a675
[I 2025-04-16 09:09:54.525 ServerApp] 302 GET / (@192.168.0.103) 0.32ms
[I 2025-04-16 09:09:56.117 JupyterNotebookApp] 302 GET /tree? (@192.168.0.103) 0.50ms
[W 2025-04-16 09:10:48.732 ServerApp] wrote error: 'Forbidden'
    Traceback (most recent call last):
      File "/gpfs/data/oermannlab/users/slj9342/.local/lib/python3.8/site-packages/tornado/web.py", line 1788, in _execute
        result = method(*self.path_args, **self.path_kwargs)
      File "/gpfs/data/oermannlab/users/slj9342/.local/lib/python3.8/site-packages/tornado/web.py", line 3289, in wrapper
        url = self.get_login_url()
      File "/gpfs/data/oermannlab/users/slj9342/.local/lib/python3.8/site-packages/jupyter_server/base/handlers.py", line 783, in get_login_url
        raise web.HTTPError(403)
    tornado.web.HTTPError: HTTP 403: Forbidden
[W 2025-04-16 09:10:48.754 ServerApp] 403 GET /api/kernelspecs?1744809048719 (@192.168.0.103) 22.03ms referer=None
[W 2025-04-16 09:10:48.755 ServerApp] wrote error: 'Forbidden'
    Traceback (most recent call last):
      File "/gpfs/data/oermannlab/users/slj9342/.local/lib/python3.8/site-packages/tornado/web.py", line 1788, in _execute
        result = method(*self.path_args, **self.path_kwargs)
      File "/gpfs/data/oermannlab/users/slj9342/.local/lib/python3.8/site-packages/tornado/web.py", line 3289, in wrapper
        url = self.get_login_url()
      File "/gpfs/data/oermannlab/users/slj9342/.local/lib/python3.8/site-packages/jupyter_server/base/handlers.py", line 783, in get_login_url
        raise web.HTTPError(403)
    tornado.web.HTTPError: HTTP 403: Forbidden
[W 2025-04-16 09:10:48.755 ServerApp] 403 GET /api/kernels?1744809048719 (@192.168.0.103) 0.76ms referer=None
[W 2025-04-16 09:10:48.757 ServerApp] wrote error: 'Forbidden'
    Traceback (most recent call last):
      File "/gpfs/data/oermannlab/users/slj9342/.local/lib/python3.8/site-packages/tornado/web.py", line 1788, in _execute
        result = method(*self.path_args, **self.path_kwargs)
      File "/gpfs/data/oermannlab/users/slj9342/.local/lib/python3.8/site-packages/tornado/web.py", line 3289, in wrapper
        url = self.get_login_url()
      File "/gpfs/data/oermannlab/users/slj9342/.local/lib/python3.8/site-packages/jupyter_server/base/handlers.py", line 783, in get_login_url
        raise web.HTTPError(403)
    tornado.web.HTTPError: HTTP 403: Forbidden
[W 2025-04-16 09:10:48.757 ServerApp] 403 GET /api/kernelspecs?1744809048720 (@192.168.0.103) 1.58ms referer=None
[W 2025-04-16 09:10:48.757 ServerApp] wrote error: 'Forbidden'
    Traceback (most recent call last):
      File "/gpfs/data/oermannlab/users/slj9342/.local/lib/python3.8/site-packages/tornado/web.py", line 1788, in _execute
        result = method(*self.path_args, **self.path_kwargs)
      File "/gpfs/data/oermannlab/users/slj9342/.local/lib/python3.8/site-packages/tornado/web.py", line 3289, in wrapper
        url = self.get_login_url()
      File "/gpfs/data/oermannlab/users/slj9342/.local/lib/python3.8/site-packages/jupyter_server/base/handlers.py", line 783, in get_login_url
        raise web.HTTPError(403)
    tornado.web.HTTPError: HTTP 403: Forbidden
[W 2025-04-16 09:10:48.783 ServerApp] 403 GET /api/kernels?1744809048721 (@192.168.0.103) 27.87ms referer=None
[W 2025-04-16 09:10:48.784 ServerApp] wrote error: 'Forbidden'
    Traceback (most recent call last):
      File "/gpfs/data/oermannlab/users/slj9342/.local/lib/python3.8/site-packages/tornado/web.py", line 1788, in _execute
        result = method(*self.path_args, **self.path_kwargs)
      File "/gpfs/data/oermannlab/users/slj9342/.local/lib/python3.8/site-packages/tornado/web.py", line 3289, in wrapper
        url = self.get_login_url()
      File "/gpfs/data/oermannlab/users/slj9342/.local/lib/python3.8/site-packages/jupyter_server/base/handlers.py", line 783, in get_login_url
        raise web.HTTPError(403)
    tornado.web.HTTPError: HTTP 403: Forbidden
[W 2025-04-16 09:10:48.784 ServerApp] 403 GET /api/kernelspecs?1744809048724 (@192.168.0.103) 28.27ms referer=None
[W 2025-04-16 09:10:48.784 ServerApp] wrote error: 'Forbidden'
    Traceback (most recent call last):
      File "/gpfs/data/oermannlab/users/slj9342/.local/lib/python3.8/site-packages/tornado/web.py", line 1788, in _execute
        result = method(*self.path_args, **self.path_kwargs)
      File "/gpfs/data/oermannlab/users/slj9342/.local/lib/python3.8/site-packages/tornado/web.py", line 3289, in wrapper
        url = self.get_login_url()
      File "/gpfs/data/oermannlab/users/slj9342/.local/lib/python3.8/site-packages/jupyter_server/base/handlers.py", line 783, in get_login_url
        raise web.HTTPError(403)
    tornado.web.HTTPError: HTTP 403: Forbidden
[W 2025-04-16 09:10:48.784 ServerApp] 403 GET /api/kernels?1744809048725 (@192.168.0.103) 28.57ms referer=None
[W 2025-04-16 09:10:48.784 ServerApp] wrote error: 'Forbidden'
    Traceback (most recent call last):
      File "/gpfs/data/oermannlab/users/slj9342/.local/lib/python3.8/site-packages/tornado/web.py", line 1788, in _execute
        result = method(*self.path_args, **self.path_kwargs)
      File "/gpfs/data/oermannlab/users/slj9342/.local/lib/python3.8/site-packages/tornado/web.py", line 3289, in wrapper
        url = self.get_login_url()
      File "/gpfs/data/oermannlab/users/slj9342/.local/lib/python3.8/site-packages/jupyter_server/base/handlers.py", line 783, in get_login_url
        raise web.HTTPError(403)
    tornado.web.HTTPError: HTTP 403: Forbidden
[W 2025-04-16 09:10:48.785 ServerApp] 403 GET /api/kernels?1744809048726 (@192.168.0.103) 28.85ms referer=None
[W 2025-04-16 09:10:48.785 ServerApp] wrote error: 'Forbidden'
    Traceback (most recent call last):
      File "/gpfs/data/oermannlab/users/slj9342/.local/lib/python3.8/site-packages/tornado/web.py", line 1788, in _execute
        result = method(*self.path_args, **self.path_kwargs)
      File "/gpfs/data/oermannlab/users/slj9342/.local/lib/python3.8/site-packages/tornado/web.py", line 3289, in wrapper
        url = self.get_login_url()
      File "/gpfs/data/oermannlab/users/slj9342/.local/lib/python3.8/site-packages/jupyter_server/base/handlers.py", line 783, in get_login_url
        raise web.HTTPError(403)
    tornado.web.HTTPError: HTTP 403: Forbidden
[W 2025-04-16 09:10:48.785 ServerApp] 403 GET /api/sessions?1744809048727 (@192.168.0.103) 29.16ms referer=None
[W 2025-04-16 09:10:48.785 ServerApp] wrote error: 'Forbidden'
    Traceback (most recent call last):
      File "/gpfs/data/oermannlab/users/slj9342/.local/lib/python3.8/site-packages/tornado/web.py", line 1788, in _execute
        result = method(*self.path_args, **self.path_kwargs)
      File "/gpfs/data/oermannlab/users/slj9342/.local/lib/python3.8/site-packages/tornado/web.py", line 3289, in wrapper
        url = self.get_login_url()
      File "/gpfs/data/oermannlab/users/slj9342/.local/lib/python3.8/site-packages/jupyter_server/base/handlers.py", line 783, in get_login_url
        raise web.HTTPError(403)
    tornado.web.HTTPError: HTTP 403: Forbidden
[W 2025-04-16 09:10:48.786 ServerApp] 403 GET /api/kernels?1744809048728 (@192.168.0.103) 29.50ms referer=None
[W 2025-04-16 09:10:48.786 ServerApp] wrote error: 'Forbidden'
    Traceback (most recent call last):
      File "/gpfs/data/oermannlab/users/slj9342/.local/lib/python3.8/site-packages/tornado/web.py", line 1788, in _execute
        result = method(*self.path_args, **self.path_kwargs)
      File "/gpfs/data/oermannlab/users/slj9342/.local/lib/python3.8/site-packages/tornado/web.py", line 3289, in wrapper
        url = self.get_login_url()
      File "/gpfs/data/oermannlab/users/slj9342/.local/lib/python3.8/site-packages/jupyter_server/base/handlers.py", line 783, in get_login_url
        raise web.HTTPError(403)
    tornado.web.HTTPError: HTTP 403: Forbidden
[W 2025-04-16 09:10:48.786 ServerApp] 403 GET /api/sessions?1744809048728 (@192.168.0.103) 29.96ms referer=None
[W 2025-04-16 09:10:48.786 ServerApp] wrote error: 'Forbidden'
    Traceback (most recent call last):
      File "/gpfs/data/oermannlab/users/slj9342/.local/lib/python3.8/site-packages/tornado/web.py", line 1788, in _execute
        result = method(*self.path_args, **self.path_kwargs)
      File "/gpfs/data/oermannlab/users/slj9342/.local/lib/python3.8/site-packages/tornado/web.py", line 3289, in wrapper
        url = self.get_login_url()
      File "/gpfs/data/oermannlab/users/slj9342/.local/lib/python3.8/site-packages/jupyter_server/base/handlers.py", line 783, in get_login_url
        raise web.HTTPError(403)
    tornado.web.HTTPError: HTTP 403: Forbidden
[W 2025-04-16 09:10:48.787 ServerApp] 403 GET /api/kernels?1744809048729 (@192.168.0.103) 30.26ms referer=None
[W 2025-04-16 09:10:48.787 ServerApp] wrote error: 'Forbidden'
    Traceback (most recent call last):
      File "/gpfs/data/oermannlab/users/slj9342/.local/lib/python3.8/site-packages/tornado/web.py", line 1788, in _execute
        result = method(*self.path_args, **self.path_kwargs)
      File "/gpfs/data/oermannlab/users/slj9342/.local/lib/python3.8/site-packages/tornado/web.py", line 3289, in wrapper
        url = self.get_login_url()
      File "/gpfs/data/oermannlab/users/slj9342/.local/lib/python3.8/site-packages/jupyter_server/base/handlers.py", line 783, in get_login_url
        raise web.HTTPError(403)
    tornado.web.HTTPError: HTTP 403: Forbidden
[W 2025-04-16 09:10:48.787 ServerApp] 403 GET /api/sessions?1744809048730 (@192.168.0.103) 30.55ms referer=None
[W 2025-04-16 09:10:48.788 ServerApp] wrote error: 'Forbidden'
    Traceback (most recent call last):
      File "/gpfs/data/oermannlab/users/slj9342/.local/lib/python3.8/site-packages/tornado/web.py", line 1788, in _execute
        result = method(*self.path_args, **self.path_kwargs)
      File "/gpfs/data/oermannlab/users/slj9342/.local/lib/python3.8/site-packages/tornado/web.py", line 3289, in wrapper
        url = self.get_login_url()
      File "/gpfs/data/oermannlab/users/slj9342/.local/lib/python3.8/site-packages/jupyter_server/base/handlers.py", line 783, in get_login_url
        raise web.HTTPError(403)
    tornado.web.HTTPError: HTTP 403: Forbidden
[W 2025-04-16 09:10:48.788 ServerApp] 403 GET /api/kernelspecs?1744809048757 (@192.168.0.103) 0.78ms referer=None
[W 2025-04-16 09:10:48.788 ServerApp] wrote error: 'Forbidden'
    Traceback (most recent call last):
      File "/gpfs/data/oermannlab/users/slj9342/.local/lib/python3.8/site-packages/tornado/web.py", line 1788, in _execute
        result = method(*self.path_args, **self.path_kwargs)
      File "/gpfs/data/oermannlab/users/slj9342/.local/lib/python3.8/site-packages/tornado/web.py", line 3289, in wrapper
        url = self.get_login_url()
      File "/gpfs/data/oermannlab/users/slj9342/.local/lib/python3.8/site-packages/jupyter_server/base/handlers.py", line 783, in get_login_url
        raise web.HTTPError(403)
    tornado.web.HTTPError: HTTP 403: Forbidden
[W 2025-04-16 09:10:48.789 ServerApp] 403 GET /api/kernelspecs?1744809048759 (@192.168.0.103) 0.93ms referer=None
[W 2025-04-16 09:10:48.794 ServerApp] wrote error: 'Forbidden'
    Traceback (most recent call last):
      File "/gpfs/data/oermannlab/users/slj9342/.local/lib/python3.8/site-packages/tornado/web.py", line 1788, in _execute
        result = method(*self.path_args, **self.path_kwargs)
      File "/gpfs/data/oermannlab/users/slj9342/.local/lib/python3.8/site-packages/tornado/web.py", line 3289, in wrapper
        url = self.get_login_url()
      File "/gpfs/data/oermannlab/users/slj9342/.local/lib/python3.8/site-packages/jupyter_server/base/handlers.py", line 783, in get_login_url
        raise web.HTTPError(403)
    tornado.web.HTTPError: HTTP 403: Forbidden
[W 2025-04-16 09:10:48.795 ServerApp] 403 GET /api/kernelspecs?1744809048789 (@192.168.0.103) 0.74ms referer=None
[I 2025-04-16 09:10:48.795 ServerApp] 302 GET / (@192.168.0.103) 0.24ms
[I 2025-04-16 09:10:48.799 JupyterNotebookApp] 302 GET /tree? (@192.168.0.103) 0.28ms
[W 2025-04-16 09:10:49.272 ServerApp] wrote error: 'Forbidden'
    Traceback (most recent call last):
      File "/gpfs/data/oermannlab/users/slj9342/.local/lib/python3.8/site-packages/tornado/web.py", line 1788, in _execute
        result = method(*self.path_args, **self.path_kwargs)
      File "/gpfs/data/oermannlab/users/slj9342/.local/lib/python3.8/site-packages/tornado/web.py", line 3289, in wrapper
        url = self.get_login_url()
      File "/gpfs/data/oermannlab/users/slj9342/.local/lib/python3.8/site-packages/jupyter_server/base/handlers.py", line 783, in get_login_url
        raise web.HTTPError(403)
    tornado.web.HTTPError: HTTP 403: Forbidden
[W 2025-04-16 09:10:49.273 ServerApp] 403 GET /api/kernelspecs?1744809049267 (@192.168.0.103) 0.81ms referer=None
[W 2025-04-16 09:10:49.278 ServerApp] wrote error: 'Forbidden'
    Traceback (most recent call last):
      File "/gpfs/data/oermannlab/users/slj9342/.local/lib/python3.8/site-packages/tornado/web.py", line 1788, in _execute
        result = method(*self.path_args, **self.path_kwargs)
      File "/gpfs/data/oermannlab/users/slj9342/.local/lib/python3.8/site-packages/tornado/web.py", line 3289, in wrapper
        url = self.get_login_url()
      File "/gpfs/data/oermannlab/users/slj9342/.local/lib/python3.8/site-packages/jupyter_server/base/handlers.py", line 783, in get_login_url
        raise web.HTTPError(403)
    tornado.web.HTTPError: HTTP 403: Forbidden
[W 2025-04-16 09:10:49.278 ServerApp] 403 GET /api/kernels?1744809049268 (@192.168.0.103) 0.72ms referer=None
[W 2025-04-16 09:10:49.278 ServerApp] wrote error: 'Forbidden'
    Traceback (most recent call last):
      File "/gpfs/data/oermannlab/users/slj9342/.local/lib/python3.8/site-packages/tornado/web.py", line 1788, in _execute
        result = method(*self.path_args, **self.path_kwargs)
      File "/gpfs/data/oermannlab/users/slj9342/.local/lib/python3.8/site-packages/tornado/web.py", line 3289, in wrapper
        url = self.get_login_url()
      File "/gpfs/data/oermannlab/users/slj9342/.local/lib/python3.8/site-packages/jupyter_server/base/handlers.py", line 783, in get_login_url
        raise web.HTTPError(403)
    tornado.web.HTTPError: HTTP 403: Forbidden
[W 2025-04-16 09:10:49.279 ServerApp] 403 GET /api/kernelspecs?1744809049269 (@192.168.0.103) 0.55ms referer=None
[W 2025-04-16 09:10:49.279 ServerApp] wrote error: 'Forbidden'
    Traceback (most recent call last):
      File "/gpfs/data/oermannlab/users/slj9342/.local/lib/python3.8/site-packages/tornado/web.py", line 1788, in _execute
        result = method(*self.path_args, **self.path_kwargs)
      File "/gpfs/data/oermannlab/users/slj9342/.local/lib/python3.8/site-packages/tornado/web.py", line 3289, in wrapper
        url = self.get_login_url()
      File "/gpfs/data/oermannlab/users/slj9342/.local/lib/python3.8/site-packages/jupyter_server/base/handlers.py", line 783, in get_login_url
        raise web.HTTPError(403)
    tornado.web.HTTPError: HTTP 403: Forbidden
[W 2025-04-16 09:10:49.280 ServerApp] 403 GET /api/kernels?1744809049269 (@192.168.0.103) 0.76ms referer=None
[W 2025-04-16 09:10:49.280 ServerApp] wrote error: 'Forbidden'
    Traceback (most recent call last):
      File "/gpfs/data/oermannlab/users/slj9342/.local/lib/python3.8/site-packages/tornado/web.py", line 1788, in _execute
        result = method(*self.path_args, **self.path_kwargs)
      File "/gpfs/data/oermannlab/users/slj9342/.local/lib/python3.8/site-packages/tornado/web.py", line 3289, in wrapper
        url = self.get_login_url()
      File "/gpfs/data/oermannlab/users/slj9342/.local/lib/python3.8/site-packages/jupyter_server/base/handlers.py", line 783, in get_login_url
        raise web.HTTPError(403)
    tornado.web.HTTPError: HTTP 403: Forbidden
[W 2025-04-16 09:10:49.280 ServerApp] 403 GET /api/kernels?1744809049272 (@192.168.0.103) 1.23ms referer=None
[W 2025-04-16 09:10:49.280 ServerApp] wrote error: 'Forbidden'
    Traceback (most recent call last):
      File "/gpfs/data/oermannlab/users/slj9342/.local/lib/python3.8/site-packages/tornado/web.py", line 1788, in _execute
        result = method(*self.path_args, **self.path_kwargs)
      File "/gpfs/data/oermannlab/users/slj9342/.local/lib/python3.8/site-packages/tornado/web.py", line 3289, in wrapper
        url = self.get_login_url()
      File "/gpfs/data/oermannlab/users/slj9342/.local/lib/python3.8/site-packages/jupyter_server/base/handlers.py", line 783, in get_login_url
        raise web.HTTPError(403)
    tornado.web.HTTPError: HTTP 403: Forbidden
[W 2025-04-16 09:10:49.281 ServerApp] 403 GET /api/sessions?1744809049273 (@192.168.0.103) 1.51ms referer=None
[W 2025-04-16 09:10:49.281 ServerApp] wrote error: 'Forbidden'
    Traceback (most recent call last):
      File "/gpfs/data/oermannlab/users/slj9342/.local/lib/python3.8/site-packages/tornado/web.py", line 1788, in _execute
        result = method(*self.path_args, **self.path_kwargs)
      File "/gpfs/data/oermannlab/users/slj9342/.local/lib/python3.8/site-packages/tornado/web.py", line 3289, in wrapper
        url = self.get_login_url()
      File "/gpfs/data/oermannlab/users/slj9342/.local/lib/python3.8/site-packages/jupyter_server/base/handlers.py", line 783, in get_login_url
        raise web.HTTPError(403)
    tornado.web.HTTPError: HTTP 403: Forbidden
[W 2025-04-16 09:10:49.281 ServerApp] 403 GET /api/kernels?1744809049274 (@192.168.0.103) 0.58ms referer=None
[W 2025-04-16 09:10:49.282 ServerApp] wrote error: 'Forbidden'
    Traceback (most recent call last):
      File "/gpfs/data/oermannlab/users/slj9342/.local/lib/python3.8/site-packages/tornado/web.py", line 1788, in _execute
        result = method(*self.path_args, **self.path_kwargs)
      File "/gpfs/data/oermannlab/users/slj9342/.local/lib/python3.8/site-packages/tornado/web.py", line 3289, in wrapper
        url = self.get_login_url()
      File "/gpfs/data/oermannlab/users/slj9342/.local/lib/python3.8/site-packages/jupyter_server/base/handlers.py", line 783, in get_login_url
        raise web.HTTPError(403)
    tornado.web.HTTPError: HTTP 403: Forbidden
[W 2025-04-16 09:10:49.282 ServerApp] 403 GET /api/kernelspecs?1744809049278 (@192.168.0.103) 0.59ms referer=None
[W 2025-04-16 09:10:49.283 ServerApp] wrote error: 'Forbidden'
    Traceback (most recent call last):
      File "/gpfs/data/oermannlab/users/slj9342/.local/lib/python3.8/site-packages/tornado/web.py", line 1788, in _execute
        result = method(*self.path_args, **self.path_kwargs)
      File "/gpfs/data/oermannlab/users/slj9342/.local/lib/python3.8/site-packages/tornado/web.py", line 3289, in wrapper
        url = self.get_login_url()
      File "/gpfs/data/oermannlab/users/slj9342/.local/lib/python3.8/site-packages/jupyter_server/base/handlers.py", line 783, in get_login_url
        raise web.HTTPError(403)
    tornado.web.HTTPError: HTTP 403: Forbidden
[W 2025-04-16 09:10:49.283 ServerApp] 403 GET /api/sessions?1744809049275 (@192.168.0.103) 0.47ms referer=None
[W 2025-04-16 09:10:49.289 ServerApp] wrote error: 'Forbidden'
    Traceback (most recent call last):
      File "/gpfs/data/oermannlab/users/slj9342/.local/lib/python3.8/site-packages/tornado/web.py", line 1788, in _execute
        result = method(*self.path_args, **self.path_kwargs)
      File "/gpfs/data/oermannlab/users/slj9342/.local/lib/python3.8/site-packages/tornado/web.py", line 3289, in wrapper
        url = self.get_login_url()
      File "/gpfs/data/oermannlab/users/slj9342/.local/lib/python3.8/site-packages/jupyter_server/base/handlers.py", line 783, in get_login_url
        raise web.HTTPError(403)
    tornado.web.HTTPError: HTTP 403: Forbidden
[W 2025-04-16 09:10:49.290 ServerApp] 403 GET /api/kernelspecs?1744809049281 (@192.168.0.103) 1.58ms referer=None
slurmstepd-a100-4005: error: *** JOB 63041604 ON a100-4005 CANCELLED AT 2025-04-16T09:11:01 ***
