
Terminal command to create your ssh tunnel
ssh -N -L 9632:a100-4032:9632 slj9342@bigpurple.nyumc.org
Windows MobaXterm info
Forwarded port:same as remote port
Remote server: a100-4032
Remote port: 9632
SSH server: bigpurple.nyumc.org
SSH login: slj9342
SSH port: 22
Use a Browser on your local machine to go to:
localhost:9632/lab?token=  (prefix w/ https:// if using password)

[I 2025-04-24 15:53:32.762 ServerApp] Extension package jupyter_lsp took 0.2170s to import
[I 2025-04-24 15:53:33.258 ServerApp] jupyter_lsp | extension was successfully linked.
[I 2025-04-24 15:53:33.262 ServerApp] jupyter_server_terminals | extension was successfully linked.
[I 2025-04-24 15:53:33.266 ServerApp] jupyterlab | extension was successfully linked.
[I 2025-04-24 15:53:33.270 ServerApp] notebook | extension was successfully linked.
[I 2025-04-24 15:53:36.910 ServerApp] notebook_shim | extension was successfully linked.
[I 2025-04-24 15:53:37.043 ServerApp] notebook_shim | extension was successfully loaded.
[I 2025-04-24 15:53:37.045 ServerApp] jupyter_lsp | extension was successfully loaded.
[I 2025-04-24 15:53:37.047 ServerApp] jupyter_server_terminals | extension was successfully loaded.
[I 2025-04-24 15:53:37.054 LabApp] JupyterLab extension loaded from /gpfs/data/oermannlab/users/slj9342/.local/lib/python3.8/site-packages/jupyterlab
[I 2025-04-24 15:53:37.054 LabApp] JupyterLab application directory is /gpfs/data/oermannlab/users/slj9342/.local/share/jupyter/lab
[I 2025-04-24 15:53:37.055 LabApp] Extension Manager is 'pypi'.
[I 2025-04-24 15:53:37.495 ServerApp] jupyterlab | extension was successfully loaded.
[I 2025-04-24 15:53:37.498 ServerApp] notebook | extension was successfully loaded.
[I 2025-04-24 15:53:37.499 ServerApp] Serving notebooks from local directory: /gpfs/data/oermannlab/users/slj9342/dl4med_final_project
[I 2025-04-24 15:53:37.499 ServerApp] Jupyter Server 2.14.2 is running at:
[I 2025-04-24 15:53:37.499 ServerApp] http://a100-4032:9632/tree?token=563c07ee8249a5040a8db110bfccb158122e825cd57b66dc
[I 2025-04-24 15:53:37.499 ServerApp]     http://127.0.0.1:9632/tree?token=563c07ee8249a5040a8db110bfccb158122e825cd57b66dc
[I 2025-04-24 15:53:37.499 ServerApp] Use Control-C to stop this server and shut down all kernels (twice to skip confirmation).
[C 2025-04-24 15:53:37.505 ServerApp] 
    
    To access the server, open this file in a browser:
        file:///gpfs/data/oermannlab/users/slj9342/.local/share/jupyter/runtime/jpserver-192037-open.html
    Or copy and paste one of these URLs:
        http://a100-4032:9632/tree?token=563c07ee8249a5040a8db110bfccb158122e825cd57b66dc
        http://127.0.0.1:9632/tree?token=563c07ee8249a5040a8db110bfccb158122e825cd57b66dc
[I 2025-04-24 15:53:37.534 ServerApp] Skipped non-installed server(s): bash-language-server, dockerfile-language-server-nodejs, javascript-typescript-langserver, jedi-language-server, julia-language-server, pyright, python-language-server, python-lsp-server, r-languageserver, sql-language-server, texlab, typescript-language-server, unified-language-server, vscode-css-languageserver-bin, vscode-html-languageserver-bin, vscode-json-languageserver-bin, yaml-language-server
[W 2025-04-24 18:18:38.899 ServerApp] 404 GET /hub/api (@192.168.0.104) 102.83ms referer=None
[I 2025-04-24 18:18:38.902 ServerApp] 302 GET / (@192.168.0.104) 0.32ms
[I 2025-04-24 18:18:38.904 JupyterNotebookApp] 302 GET /tree? (@192.168.0.104) 0.39ms
[I 2025-04-24 18:18:46.448 ServerApp] User 175f1206b4894f258d3b7602bc10c39c logged in.
[I 2025-04-24 18:18:46.448 ServerApp] 302 POST /login? (175f1206b4894f258d3b7602bc10c39c@192.168.0.104) 0.83ms
[I 2025-04-24 18:19:27.087 ServerApp] Kernel started: 12705ed9-cefe-4460-8364-5e82567317a9
[I 2025-04-24 18:19:37.140 ServerApp] Connecting to kernel 12705ed9-cefe-4460-8364-5e82567317a9.
[I 2025-04-24 18:34:17.302 ServerApp] Kernel interrupted: 12705ed9-cefe-4460-8364-5e82567317a9
[I 2025-04-25 02:19:46.214 ServerApp] Starting buffering for 12705ed9-cefe-4460-8364-5e82567317a9:5c817f18-061e-4a1d-ad89-52a5e5b3940f
[I 2025-04-25 09:12:26.308 ServerApp] 302 GET / (@192.168.0.104) 0.36ms
[I 2025-04-25 09:12:26.491 JupyterNotebookApp] 302 GET /tree? (@192.168.0.104) 0.51ms
[W 2025-04-25 09:12:26.711 ServerApp] wrote error: 'Forbidden'
    Traceback (most recent call last):
      File "/gpfs/data/oermannlab/users/slj9342/.local/lib/python3.8/site-packages/tornado/web.py", line 1788, in _execute
        result = method(*self.path_args, **self.path_kwargs)
      File "/gpfs/data/oermannlab/users/slj9342/.local/lib/python3.8/site-packages/tornado/web.py", line 3289, in wrapper
        url = self.get_login_url()
      File "/gpfs/data/oermannlab/users/slj9342/.local/lib/python3.8/site-packages/jupyter_server/base/handlers.py", line 783, in get_login_url
        raise web.HTTPError(403)
    tornado.web.HTTPError: HTTP 403: Forbidden
[W 2025-04-25 09:12:26.743 ServerApp] 403 GET /api/kernelspecs?1745586746707 (@192.168.0.104) 32.64ms referer=None
[W 2025-04-25 09:12:30.685 ServerApp] wrote error: 'Forbidden'
    Traceback (most recent call last):
      File "/gpfs/data/oermannlab/users/slj9342/.local/lib/python3.8/site-packages/tornado/web.py", line 1788, in _execute
        result = method(*self.path_args, **self.path_kwargs)
      File "/gpfs/data/oermannlab/users/slj9342/.local/lib/python3.8/site-packages/tornado/web.py", line 3289, in wrapper
        url = self.get_login_url()
      File "/gpfs/data/oermannlab/users/slj9342/.local/lib/python3.8/site-packages/jupyter_server/base/handlers.py", line 783, in get_login_url
        raise web.HTTPError(403)
    tornado.web.HTTPError: HTTP 403: Forbidden
[W 2025-04-25 09:12:30.685 ServerApp] 403 GET /api/kernels?1745586746707 (@192.168.0.104) 0.79ms referer=None
[W 2025-04-25 09:12:30.686 ServerApp] wrote error: 'Forbidden'
    Traceback (most recent call last):
      File "/gpfs/data/oermannlab/users/slj9342/.local/lib/python3.8/site-packages/tornado/web.py", line 1788, in _execute
        result = method(*self.path_args, **self.path_kwargs)
      File "/gpfs/data/oermannlab/users/slj9342/.local/lib/python3.8/site-packages/tornado/web.py", line 3289, in wrapper
        url = self.get_login_url()
      File "/gpfs/data/oermannlab/users/slj9342/.local/lib/python3.8/site-packages/jupyter_server/base/handlers.py", line 783, in get_login_url
        raise web.HTTPError(403)
    tornado.web.HTTPError: HTTP 403: Forbidden
[W 2025-04-25 09:12:30.686 ServerApp] 403 GET /api/kernels?1745586746712 (@192.168.0.104) 0.77ms referer=None
[W 2025-04-25 09:12:30.687 ServerApp] wrote error: 'Forbidden'
    Traceback (most recent call last):
      File "/gpfs/data/oermannlab/users/slj9342/.local/lib/python3.8/site-packages/tornado/web.py", line 1788, in _execute
        result = method(*self.path_args, **self.path_kwargs)
      File "/gpfs/data/oermannlab/users/slj9342/.local/lib/python3.8/site-packages/tornado/web.py", line 3289, in wrapper
        url = self.get_login_url()
      File "/gpfs/data/oermannlab/users/slj9342/.local/lib/python3.8/site-packages/jupyter_server/base/handlers.py", line 783, in get_login_url
        raise web.HTTPError(403)
    tornado.web.HTTPError: HTTP 403: Forbidden
[W 2025-04-25 09:12:30.687 ServerApp] 403 GET /api/sessions?1745586746716 (@192.168.0.104) 1.03ms referer=None
[W 2025-04-25 09:12:30.687 ServerApp] wrote error: 'Forbidden'
    Traceback (most recent call last):
      File "/gpfs/data/oermannlab/users/slj9342/.local/lib/python3.8/site-packages/tornado/web.py", line 1788, in _execute
        result = method(*self.path_args, **self.path_kwargs)
      File "/gpfs/data/oermannlab/users/slj9342/.local/lib/python3.8/site-packages/tornado/web.py", line 3289, in wrapper
        url = self.get_login_url()
      File "/gpfs/data/oermannlab/users/slj9342/.local/lib/python3.8/site-packages/jupyter_server/base/handlers.py", line 783, in get_login_url
        raise web.HTTPError(403)
    tornado.web.HTTPError: HTTP 403: Forbidden
[W 2025-04-25 09:12:30.687 ServerApp] 403 GET /api/kernelspecs?1745586746776 (@192.168.0.104) 1.35ms referer=None
[I 2025-04-25 09:12:30.699 ServerApp] 302 GET / (@192.168.0.104) 0.21ms
[I 2025-04-25 09:12:30.702 JupyterNotebookApp] 302 GET /tree? (@192.168.0.104) 0.29ms
[W 2025-04-25 09:12:30.788 ServerApp] wrote error: 'Forbidden'
    Traceback (most recent call last):
      File "/gpfs/data/oermannlab/users/slj9342/.local/lib/python3.8/site-packages/tornado/web.py", line 1788, in _execute
        result = method(*self.path_args, **self.path_kwargs)
      File "/gpfs/data/oermannlab/users/slj9342/.local/lib/python3.8/site-packages/tornado/web.py", line 3289, in wrapper
        url = self.get_login_url()
      File "/gpfs/data/oermannlab/users/slj9342/.local/lib/python3.8/site-packages/jupyter_server/base/handlers.py", line 783, in get_login_url
        raise web.HTTPError(403)
    tornado.web.HTTPError: HTTP 403: Forbidden
[W 2025-04-25 09:12:30.789 ServerApp] 403 GET /api/kernelspecs?1745586750784 (@192.168.0.104) 0.85ms referer=None
[W 2025-04-25 09:12:30.799 ServerApp] wrote error: 'Forbidden'
    Traceback (most recent call last):
      File "/gpfs/data/oermannlab/users/slj9342/.local/lib/python3.8/site-packages/tornado/web.py", line 1788, in _execute
        result = method(*self.path_args, **self.path_kwargs)
      File "/gpfs/data/oermannlab/users/slj9342/.local/lib/python3.8/site-packages/tornado/web.py", line 3289, in wrapper
        url = self.get_login_url()
      File "/gpfs/data/oermannlab/users/slj9342/.local/lib/python3.8/site-packages/jupyter_server/base/handlers.py", line 783, in get_login_url
        raise web.HTTPError(403)
    tornado.web.HTTPError: HTTP 403: Forbidden
[W 2025-04-25 09:12:30.799 ServerApp] 403 GET /api/kernels?1745586750785 (@192.168.0.104) 0.67ms referer=None
[W 2025-04-25 09:12:30.800 ServerApp] wrote error: 'Forbidden'
    Traceback (most recent call last):
      File "/gpfs/data/oermannlab/users/slj9342/.local/lib/python3.8/site-packages/tornado/web.py", line 1788, in _execute
        result = method(*self.path_args, **self.path_kwargs)
      File "/gpfs/data/oermannlab/users/slj9342/.local/lib/python3.8/site-packages/tornado/web.py", line 3289, in wrapper
        url = self.get_login_url()
      File "/gpfs/data/oermannlab/users/slj9342/.local/lib/python3.8/site-packages/jupyter_server/base/handlers.py", line 783, in get_login_url
        raise web.HTTPError(403)
    tornado.web.HTTPError: HTTP 403: Forbidden
[W 2025-04-25 09:12:30.800 ServerApp] 403 GET /api/kernels?1745586750790 (@192.168.0.104) 0.65ms referer=None
[W 2025-04-25 09:12:30.800 ServerApp] wrote error: 'Forbidden'
    Traceback (most recent call last):
      File "/gpfs/data/oermannlab/users/slj9342/.local/lib/python3.8/site-packages/tornado/web.py", line 1788, in _execute
        result = method(*self.path_args, **self.path_kwargs)
      File "/gpfs/data/oermannlab/users/slj9342/.local/lib/python3.8/site-packages/tornado/web.py", line 3289, in wrapper
        url = self.get_login_url()
      File "/gpfs/data/oermannlab/users/slj9342/.local/lib/python3.8/site-packages/jupyter_server/base/handlers.py", line 783, in get_login_url
        raise web.HTTPError(403)
    tornado.web.HTTPError: HTTP 403: Forbidden
[W 2025-04-25 09:12:30.800 ServerApp] 403 GET /api/sessions?1745586750790 (@192.168.0.104) 0.91ms referer=None
[W 2025-04-25 09:12:30.801 ServerApp] wrote error: 'Forbidden'
    Traceback (most recent call last):
      File "/gpfs/data/oermannlab/users/slj9342/.local/lib/python3.8/site-packages/tornado/web.py", line 1788, in _execute
        result = method(*self.path_args, **self.path_kwargs)
      File "/gpfs/data/oermannlab/users/slj9342/.local/lib/python3.8/site-packages/tornado/web.py", line 3289, in wrapper
        url = self.get_login_url()
      File "/gpfs/data/oermannlab/users/slj9342/.local/lib/python3.8/site-packages/jupyter_server/base/handlers.py", line 783, in get_login_url
        raise web.HTTPError(403)
    tornado.web.HTTPError: HTTP 403: Forbidden
[W 2025-04-25 09:12:30.801 ServerApp] 403 GET /api/kernelspecs?1745586750798 (@192.168.0.104) 0.46ms referer=None
[W 2025-04-25 09:14:38.291 ServerApp] 404 GET /hub/api (@192.168.0.104) 2.32ms referer=None
[I 2025-04-25 09:14:38.293 ServerApp] 302 GET / (@192.168.0.104) 0.24ms
[I 2025-04-25 09:14:38.296 JupyterNotebookApp] 302 GET /tree? (@192.168.0.104) 0.33ms
[I 2025-04-25 09:14:44.751 ServerApp] User ae7e77fefef4407daabcd46ce428c8f3 logged in.
[I 2025-04-25 09:14:44.751 ServerApp] 302 POST /login? (ae7e77fefef4407daabcd46ce428c8f3@192.168.0.104) 0.90ms
[I 2025-04-25 09:14:57.910 ServerApp] Kernel started: 4bd18154-a7d0-42c6-bd48-fcb6a40134da
[I 2025-04-25 09:15:08.765 ServerApp] Connecting to kernel 4bd18154-a7d0-42c6-bd48-fcb6a40134da.
[I 2025-04-25 09:15:09.325 ServerApp] 302 GET / (@192.168.0.104) 1.96ms
[I 2025-04-25 09:15:09.513 JupyterNotebookApp] 302 GET /tree? (@192.168.0.104) 0.53ms
[I 2025-04-25 09:15:16.889 ServerApp] User 8363bbdc2a5342b29ec22f95800428d3 logged in.
[I 2025-04-25 09:15:16.903 ServerApp] 302 POST /login? (8363bbdc2a5342b29ec22f95800428d3@192.168.0.104) 15.26ms
[I 2025-04-25 09:19:42.344 ServerApp] Kernel interrupted: 4bd18154-a7d0-42c6-bd48-fcb6a40134da
[I 2025-04-25 10:28:31.771 ServerApp] 302 GET / (@192.168.0.104) 0.39ms
[I 2025-04-25 10:28:31.870 ServerApp] 302 GET / (@192.168.0.104) 0.36ms
[I 2025-04-25 10:28:33.665 JupyterNotebookApp] 302 GET /tree? (@192.168.0.104) 0.77ms
[I 2025-04-25 10:28:33.665 JupyterNotebookApp] 302 GET /tree? (@192.168.0.104) 0.83ms
[W 2025-04-25 10:28:34.049 ServerApp] wrote error: 'Forbidden'
    Traceback (most recent call last):
      File "/gpfs/data/oermannlab/users/slj9342/.local/lib/python3.8/site-packages/tornado/web.py", line 1788, in _execute
        result = method(*self.path_args, **self.path_kwargs)
      File "/gpfs/data/oermannlab/users/slj9342/.local/lib/python3.8/site-packages/tornado/web.py", line 3289, in wrapper
        url = self.get_login_url()
      File "/gpfs/data/oermannlab/users/slj9342/.local/lib/python3.8/site-packages/jupyter_server/base/handlers.py", line 783, in get_login_url
        raise web.HTTPError(403)
    tornado.web.HTTPError: HTTP 403: Forbidden
[W 2025-04-25 10:28:34.054 ServerApp] 403 GET /api/kernelspecs?1745591314045 (@192.168.0.104) 5.14ms referer=None
[W 2025-04-25 10:28:34.055 ServerApp] wrote error: 'Forbidden'
    Traceback (most recent call last):
      File "/gpfs/data/oermannlab/users/slj9342/.local/lib/python3.8/site-packages/tornado/web.py", line 1788, in _execute
        result = method(*self.path_args, **self.path_kwargs)
      File "/gpfs/data/oermannlab/users/slj9342/.local/lib/python3.8/site-packages/tornado/web.py", line 3289, in wrapper
        url = self.get_login_url()
      File "/gpfs/data/oermannlab/users/slj9342/.local/lib/python3.8/site-packages/jupyter_server/base/handlers.py", line 783, in get_login_url
        raise web.HTTPError(403)
    tornado.web.HTTPError: HTTP 403: Forbidden
[W 2025-04-25 10:28:34.055 ServerApp] 403 GET /api/kernels?1745591314045 (@192.168.0.104) 0.56ms referer=None
[W 2025-04-25 10:28:34.200 ServerApp] wrote error: 'Forbidden'
    Traceback (most recent call last):
      File "/gpfs/data/oermannlab/users/slj9342/.local/lib/python3.8/site-packages/tornado/web.py", line 1788, in _execute
        result = method(*self.path_args, **self.path_kwargs)
      File "/gpfs/data/oermannlab/users/slj9342/.local/lib/python3.8/site-packages/tornado/web.py", line 3289, in wrapper
        url = self.get_login_url()
      File "/gpfs/data/oermannlab/users/slj9342/.local/lib/python3.8/site-packages/jupyter_server/base/handlers.py", line 783, in get_login_url
        raise web.HTTPError(403)
    tornado.web.HTTPError: HTTP 403: Forbidden
[W 2025-04-25 10:28:34.201 ServerApp] 403 GET /api/kernelspecs?1745591314046 (@192.168.0.104) 0.85ms referer=None
[W 2025-04-25 10:28:34.201 ServerApp] wrote error: 'Forbidden'
    Traceback (most recent call last):
      File "/gpfs/data/oermannlab/users/slj9342/.local/lib/python3.8/site-packages/tornado/web.py", line 1788, in _execute
        result = method(*self.path_args, **self.path_kwargs)
      File "/gpfs/data/oermannlab/users/slj9342/.local/lib/python3.8/site-packages/tornado/web.py", line 3289, in wrapper
        url = self.get_login_url()
      File "/gpfs/data/oermannlab/users/slj9342/.local/lib/python3.8/site-packages/jupyter_server/base/handlers.py", line 783, in get_login_url
        raise web.HTTPError(403)
    tornado.web.HTTPError: HTTP 403: Forbidden
[W 2025-04-25 10:28:34.201 ServerApp] 403 GET /api/kernels?1745591314046 (@192.168.0.104) 0.65ms referer=None
[W 2025-04-25 10:28:34.202 ServerApp] wrote error: 'Forbidden'
    Traceback (most recent call last):
      File "/gpfs/data/oermannlab/users/slj9342/.local/lib/python3.8/site-packages/tornado/web.py", line 1788, in _execute
        result = method(*self.path_args, **self.path_kwargs)
      File "/gpfs/data/oermannlab/users/slj9342/.local/lib/python3.8/site-packages/tornado/web.py", line 3289, in wrapper
        url = self.get_login_url()
      File "/gpfs/data/oermannlab/users/slj9342/.local/lib/python3.8/site-packages/jupyter_server/base/handlers.py", line 783, in get_login_url
        raise web.HTTPError(403)
    tornado.web.HTTPError: HTTP 403: Forbidden
[W 2025-04-25 10:28:34.202 ServerApp] 403 GET /api/sessions?1745591314050 (@192.168.0.104) 0.86ms referer=None
[W 2025-04-25 10:28:34.203 ServerApp] wrote error: 'Forbidden'
    Traceback (most recent call last):
      File "/gpfs/data/oermannlab/users/slj9342/.local/lib/python3.8/site-packages/tornado/web.py", line 1788, in _execute
        result = method(*self.path_args, **self.path_kwargs)
      File "/gpfs/data/oermannlab/users/slj9342/.local/lib/python3.8/site-packages/tornado/web.py", line 3289, in wrapper
        url = self.get_login_url()
      File "/gpfs/data/oermannlab/users/slj9342/.local/lib/python3.8/site-packages/jupyter_server/base/handlers.py", line 783, in get_login_url
        raise web.HTTPError(403)
    tornado.web.HTTPError: HTTP 403: Forbidden
[W 2025-04-25 10:28:34.203 ServerApp] 403 GET /api/kernels?1745591314049 (@192.168.0.104) 1.12ms referer=None
[W 2025-04-25 10:28:34.203 ServerApp] wrote error: 'Forbidden'
    Traceback (most recent call last):
      File "/gpfs/data/oermannlab/users/slj9342/.local/lib/python3.8/site-packages/tornado/web.py", line 1788, in _execute
        result = method(*self.path_args, **self.path_kwargs)
      File "/gpfs/data/oermannlab/users/slj9342/.local/lib/python3.8/site-packages/tornado/web.py", line 3289, in wrapper
        url = self.get_login_url()
      File "/gpfs/data/oermannlab/users/slj9342/.local/lib/python3.8/site-packages/jupyter_server/base/handlers.py", line 783, in get_login_url
        raise web.HTTPError(403)
    tornado.web.HTTPError: HTTP 403: Forbidden
[W 2025-04-25 10:28:34.203 ServerApp] 403 GET /api/kernels?1745591314051 (@192.168.0.104) 1.40ms referer=None
[W 2025-04-25 10:28:34.203 ServerApp] wrote error: 'Forbidden'
    Traceback (most recent call last):
      File "/gpfs/data/oermannlab/users/slj9342/.local/lib/python3.8/site-packages/tornado/web.py", line 1788, in _execute
        result = method(*self.path_args, **self.path_kwargs)
      File "/gpfs/data/oermannlab/users/slj9342/.local/lib/python3.8/site-packages/tornado/web.py", line 3289, in wrapper
        url = self.get_login_url()
      File "/gpfs/data/oermannlab/users/slj9342/.local/lib/python3.8/site-packages/jupyter_server/base/handlers.py", line 783, in get_login_url
        raise web.HTTPError(403)
    tornado.web.HTTPError: HTTP 403: Forbidden
[W 2025-04-25 10:28:34.204 ServerApp] 403 GET /api/sessions?1745591314051 (@192.168.0.104) 1.67ms referer=None
[W 2025-04-25 10:28:34.205 ServerApp] wrote error: 'Forbidden'
    Traceback (most recent call last):
      File "/gpfs/data/oermannlab/users/slj9342/.local/lib/python3.8/site-packages/tornado/web.py", line 1788, in _execute
        result = method(*self.path_args, **self.path_kwargs)
      File "/gpfs/data/oermannlab/users/slj9342/.local/lib/python3.8/site-packages/tornado/web.py", line 3289, in wrapper
        url = self.get_login_url()
      File "/gpfs/data/oermannlab/users/slj9342/.local/lib/python3.8/site-packages/jupyter_server/base/handlers.py", line 783, in get_login_url
        raise web.HTTPError(403)
    tornado.web.HTTPError: HTTP 403: Forbidden
[W 2025-04-25 10:28:34.205 ServerApp] 403 GET /api/kernelspecs?1745591314181 (@192.168.0.104) 0.46ms referer=None
[I 2025-04-25 10:28:35.207 ServerApp] 302 GET / (@192.168.0.104) 0.36ms
[I 2025-04-25 10:28:35.287 JupyterNotebookApp] 302 GET /tree? (@192.168.0.104) 0.43ms
[W 2025-04-25 10:28:35.369 ServerApp] wrote error: 'Forbidden'
    Traceback (most recent call last):
      File "/gpfs/data/oermannlab/users/slj9342/.local/lib/python3.8/site-packages/tornado/web.py", line 1788, in _execute
        result = method(*self.path_args, **self.path_kwargs)
      File "/gpfs/data/oermannlab/users/slj9342/.local/lib/python3.8/site-packages/tornado/web.py", line 3289, in wrapper
        url = self.get_login_url()
      File "/gpfs/data/oermannlab/users/slj9342/.local/lib/python3.8/site-packages/jupyter_server/base/handlers.py", line 783, in get_login_url
        raise web.HTTPError(403)
    tornado.web.HTTPError: HTTP 403: Forbidden
[W 2025-04-25 10:28:35.370 ServerApp] 403 GET /api/kernelspecs?1745591315366 (@192.168.0.104) 0.86ms referer=None
[W 2025-04-25 10:28:35.388 ServerApp] wrote error: 'Forbidden'
    Traceback (most recent call last):
      File "/gpfs/data/oermannlab/users/slj9342/.local/lib/python3.8/site-packages/tornado/web.py", line 1788, in _execute
        result = method(*self.path_args, **self.path_kwargs)
      File "/gpfs/data/oermannlab/users/slj9342/.local/lib/python3.8/site-packages/tornado/web.py", line 3289, in wrapper
        url = self.get_login_url()
      File "/gpfs/data/oermannlab/users/slj9342/.local/lib/python3.8/site-packages/jupyter_server/base/handlers.py", line 783, in get_login_url
        raise web.HTTPError(403)
    tornado.web.HTTPError: HTTP 403: Forbidden
[W 2025-04-25 10:28:35.388 ServerApp] 403 GET /api/kernels?1745591315367 (@192.168.0.104) 0.76ms referer=None
[W 2025-04-25 10:28:35.403 ServerApp] wrote error: 'Forbidden'
    Traceback (most recent call last):
      File "/gpfs/data/oermannlab/users/slj9342/.local/lib/python3.8/site-packages/tornado/web.py", line 1788, in _execute
        result = method(*self.path_args, **self.path_kwargs)
      File "/gpfs/data/oermannlab/users/slj9342/.local/lib/python3.8/site-packages/tornado/web.py", line 3289, in wrapper
        url = self.get_login_url()
      File "/gpfs/data/oermannlab/users/slj9342/.local/lib/python3.8/site-packages/jupyter_server/base/handlers.py", line 783, in get_login_url
        raise web.HTTPError(403)
    tornado.web.HTTPError: HTTP 403: Forbidden
[W 2025-04-25 10:28:35.404 ServerApp] 403 GET /api/sessions?1745591315384 (@192.168.0.104) 0.73ms referer=None
[W 2025-04-25 10:28:35.404 ServerApp] wrote error: 'Forbidden'
    Traceback (most recent call last):
      File "/gpfs/data/oermannlab/users/slj9342/.local/lib/python3.8/site-packages/tornado/web.py", line 1788, in _execute
        result = method(*self.path_args, **self.path_kwargs)
      File "/gpfs/data/oermannlab/users/slj9342/.local/lib/python3.8/site-packages/tornado/web.py", line 3289, in wrapper
        url = self.get_login_url()
      File "/gpfs/data/oermannlab/users/slj9342/.local/lib/python3.8/site-packages/jupyter_server/base/handlers.py", line 783, in get_login_url
        raise web.HTTPError(403)
    tornado.web.HTTPError: HTTP 403: Forbidden
[W 2025-04-25 10:28:35.405 ServerApp] 403 GET /api/kernels?1745591315383 (@192.168.0.104) 0.56ms referer=None
[W 2025-04-25 10:28:35.405 ServerApp] wrote error: 'Forbidden'
    Traceback (most recent call last):
      File "/gpfs/data/oermannlab/users/slj9342/.local/lib/python3.8/site-packages/tornado/web.py", line 1788, in _execute
        result = method(*self.path_args, **self.path_kwargs)
      File "/gpfs/data/oermannlab/users/slj9342/.local/lib/python3.8/site-packages/tornado/web.py", line 3289, in wrapper
        url = self.get_login_url()
      File "/gpfs/data/oermannlab/users/slj9342/.local/lib/python3.8/site-packages/jupyter_server/base/handlers.py", line 783, in get_login_url
        raise web.HTTPError(403)
    tornado.web.HTTPError: HTTP 403: Forbidden
[W 2025-04-25 10:28:35.405 ServerApp] 403 GET /api/kernelspecs?1745591315388 (@192.168.0.104) 0.49ms referer=None
[I 2025-04-25 10:28:35.765 ServerApp] 302 GET / (@192.168.0.104) 0.39ms
[I 2025-04-25 10:28:35.947 JupyterNotebookApp] 302 GET /tree? (@192.168.0.104) 0.48ms
[W 2025-04-25 10:28:36.091 ServerApp] wrote error: 'Forbidden'
    Traceback (most recent call last):
      File "/gpfs/data/oermannlab/users/slj9342/.local/lib/python3.8/site-packages/tornado/web.py", line 1788, in _execute
        result = method(*self.path_args, **self.path_kwargs)
      File "/gpfs/data/oermannlab/users/slj9342/.local/lib/python3.8/site-packages/tornado/web.py", line 3289, in wrapper
        url = self.get_login_url()
      File "/gpfs/data/oermannlab/users/slj9342/.local/lib/python3.8/site-packages/jupyter_server/base/handlers.py", line 783, in get_login_url
        raise web.HTTPError(403)
    tornado.web.HTTPError: HTTP 403: Forbidden
[W 2025-04-25 10:28:36.092 ServerApp] 403 GET /api/kernelspecs?1745591316087 (@192.168.0.104) 0.88ms referer=None
[W 2025-04-25 10:28:36.179 ServerApp] wrote error: 'Forbidden'
    Traceback (most recent call last):
      File "/gpfs/data/oermannlab/users/slj9342/.local/lib/python3.8/site-packages/tornado/web.py", line 1788, in _execute
        result = method(*self.path_args, **self.path_kwargs)
      File "/gpfs/data/oermannlab/users/slj9342/.local/lib/python3.8/site-packages/tornado/web.py", line 3289, in wrapper
        url = self.get_login_url()
      File "/gpfs/data/oermannlab/users/slj9342/.local/lib/python3.8/site-packages/jupyter_server/base/handlers.py", line 783, in get_login_url
        raise web.HTTPError(403)
    tornado.web.HTTPError: HTTP 403: Forbidden
[W 2025-04-25 10:28:36.180 ServerApp] 403 GET /api/kernels?1745591316088 (@192.168.0.104) 0.83ms referer=None
[W 2025-04-25 10:28:36.180 ServerApp] wrote error: 'Forbidden'
    Traceback (most recent call last):
      File "/gpfs/data/oermannlab/users/slj9342/.local/lib/python3.8/site-packages/tornado/web.py", line 1788, in _execute
        result = method(*self.path_args, **self.path_kwargs)
      File "/gpfs/data/oermannlab/users/slj9342/.local/lib/python3.8/site-packages/tornado/web.py", line 3289, in wrapper
        url = self.get_login_url()
      File "/gpfs/data/oermannlab/users/slj9342/.local/lib/python3.8/site-packages/jupyter_server/base/handlers.py", line 783, in get_login_url
        raise web.HTTPError(403)
    tornado.web.HTTPError: HTTP 403: Forbidden
[W 2025-04-25 10:28:36.181 ServerApp] 403 GET /api/kernelspecs?1745591316088 (@192.168.0.104) 0.57ms referer=None
[W 2025-04-25 10:28:36.182 ServerApp] wrote error: 'Forbidden'
    Traceback (most recent call last):
      File "/gpfs/data/oermannlab/users/slj9342/.local/lib/python3.8/site-packages/tornado/web.py", line 1788, in _execute
        result = method(*self.path_args, **self.path_kwargs)
      File "/gpfs/data/oermannlab/users/slj9342/.local/lib/python3.8/site-packages/tornado/web.py", line 3289, in wrapper
        url = self.get_login_url()
      File "/gpfs/data/oermannlab/users/slj9342/.local/lib/python3.8/site-packages/jupyter_server/base/handlers.py", line 783, in get_login_url
        raise web.HTTPError(403)
    tornado.web.HTTPError: HTTP 403: Forbidden
[W 2025-04-25 10:28:36.182 ServerApp] 403 GET /api/kernels?1745591316089 (@192.168.0.104) 0.94ms referer=None
[W 2025-04-25 10:28:36.182 ServerApp] wrote error: 'Forbidden'
    Traceback (most recent call last):
      File "/gpfs/data/oermannlab/users/slj9342/.local/lib/python3.8/site-packages/tornado/web.py", line 1788, in _execute
        result = method(*self.path_args, **self.path_kwargs)
      File "/gpfs/data/oermannlab/users/slj9342/.local/lib/python3.8/site-packages/tornado/web.py", line 3289, in wrapper
        url = self.get_login_url()
      File "/gpfs/data/oermannlab/users/slj9342/.local/lib/python3.8/site-packages/jupyter_server/base/handlers.py", line 783, in get_login_url
        raise web.HTTPError(403)
    tornado.web.HTTPError: HTTP 403: Forbidden
[W 2025-04-25 10:28:36.182 ServerApp] 403 GET /api/kernels?1745591316092 (@192.168.0.104) 1.21ms referer=None
[W 2025-04-25 10:28:36.182 ServerApp] wrote error: 'Forbidden'
    Traceback (most recent call last):
      File "/gpfs/data/oermannlab/users/slj9342/.local/lib/python3.8/site-packages/tornado/web.py", line 1788, in _execute
        result = method(*self.path_args, **self.path_kwargs)
      File "/gpfs/data/oermannlab/users/slj9342/.local/lib/python3.8/site-packages/tornado/web.py", line 3289, in wrapper
        url = self.get_login_url()
      File "/gpfs/data/oermannlab/users/slj9342/.local/lib/python3.8/site-packages/jupyter_server/base/handlers.py", line 783, in get_login_url
        raise web.HTTPError(403)
    tornado.web.HTTPError: HTTP 403: Forbidden
[W 2025-04-25 10:28:36.183 ServerApp] 403 GET /api/sessions?1745591316092 (@192.168.0.104) 1.49ms referer=None
[W 2025-04-25 10:28:36.183 ServerApp] wrote error: 'Forbidden'
    Traceback (most recent call last):
      File "/gpfs/data/oermannlab/users/slj9342/.local/lib/python3.8/site-packages/tornado/web.py", line 1788, in _execute
        result = method(*self.path_args, **self.path_kwargs)
      File "/gpfs/data/oermannlab/users/slj9342/.local/lib/python3.8/site-packages/tornado/web.py", line 3289, in wrapper
        url = self.get_login_url()
      File "/gpfs/data/oermannlab/users/slj9342/.local/lib/python3.8/site-packages/jupyter_server/base/handlers.py", line 783, in get_login_url
        raise web.HTTPError(403)
    tornado.web.HTTPError: HTTP 403: Forbidden
[W 2025-04-25 10:28:36.183 ServerApp] 403 GET /api/kernels?1745591316093 (@192.168.0.104) 1.75ms referer=None
[W 2025-04-25 10:28:36.183 ServerApp] wrote error: 'Forbidden'
    Traceback (most recent call last):
      File "/gpfs/data/oermannlab/users/slj9342/.local/lib/python3.8/site-packages/tornado/web.py", line 1788, in _execute
        result = method(*self.path_args, **self.path_kwargs)
      File "/gpfs/data/oermannlab/users/slj9342/.local/lib/python3.8/site-packages/tornado/web.py", line 3289, in wrapper
        url = self.get_login_url()
      File "/gpfs/data/oermannlab/users/slj9342/.local/lib/python3.8/site-packages/jupyter_server/base/handlers.py", line 783, in get_login_url
        raise web.HTTPError(403)
    tornado.web.HTTPError: HTTP 403: Forbidden
[W 2025-04-25 10:28:36.183 ServerApp] 403 GET /api/sessions?1745591316094 (@192.168.0.104) 2.01ms referer=None
[W 2025-04-25 10:28:36.292 ServerApp] wrote error: 'Forbidden'
    Traceback (most recent call last):
      File "/gpfs/data/oermannlab/users/slj9342/.local/lib/python3.8/site-packages/tornado/web.py", line 1788, in _execute
        result = method(*self.path_args, **self.path_kwargs)
      File "/gpfs/data/oermannlab/users/slj9342/.local/lib/python3.8/site-packages/tornado/web.py", line 3289, in wrapper
        url = self.get_login_url()
      File "/gpfs/data/oermannlab/users/slj9342/.local/lib/python3.8/site-packages/jupyter_server/base/handlers.py", line 783, in get_login_url
        raise web.HTTPError(403)
    tornado.web.HTTPError: HTTP 403: Forbidden
[W 2025-04-25 10:28:36.292 ServerApp] 403 GET /api/kernelspecs?1745591316168 (@192.168.0.104) 0.93ms referer=None
[I 2025-04-25 10:28:50.320 ServerApp] User 5e1975f4abc142ccaae48d5af21ff753 logged in.
[I 2025-04-25 10:28:50.321 ServerApp] 302 POST /login? (5e1975f4abc142ccaae48d5af21ff753@192.168.0.104) 1.79ms
[I 2025-04-25 10:29:02.808 ServerApp] Kernel started: 8e67e9e2-9200-4922-9498-c74d6369577f
[I 2025-04-25 10:29:12.583 ServerApp] Connecting to kernel 8e67e9e2-9200-4922-9498-c74d6369577f.
[I 2025-04-25 10:29:13.294 ServerApp] 302 GET / (@192.168.0.104) 0.26ms
[I 2025-04-25 10:29:13.368 JupyterNotebookApp] 302 GET /tree? (@192.168.0.104) 0.51ms
[I 2025-04-25 10:29:18.484 ServerApp] User 169c4b753bb4499cb82dbae9dd1599f6 logged in.
[I 2025-04-25 10:29:18.485 ServerApp] 302 POST /login? (169c4b753bb4499cb82dbae9dd1599f6@192.168.0.104) 0.97ms
[I 2025-04-25 10:33:23.430 ServerApp] Starting buffering for 4bd18154-a7d0-42c6-bd48-fcb6a40134da:d91f84ef-8b53-49af-85cc-055b07b01905
[I 2025-04-25 12:04:59.016 ServerApp] Kernel interrupted: 8e67e9e2-9200-4922-9498-c74d6369577f
[I 2025-04-25 15:21:15.296 ServerApp] 302 GET / (@192.168.0.102) 0.33ms
[I 2025-04-25 15:21:15.417 ServerApp] 302 GET / (@192.168.0.102) 0.35ms
[I 2025-04-25 15:21:15.698 JupyterNotebookApp] 302 GET /tree? (@192.168.0.102) 0.75ms
[I 2025-04-25 15:21:15.698 JupyterNotebookApp] 302 GET /tree? (@192.168.0.102) 0.81ms
[W 2025-04-25 15:21:15.918 ServerApp] wrote error: 'Forbidden'
    Traceback (most recent call last):
      File "/gpfs/data/oermannlab/users/slj9342/.local/lib/python3.8/site-packages/tornado/web.py", line 1788, in _execute
        result = method(*self.path_args, **self.path_kwargs)
      File "/gpfs/data/oermannlab/users/slj9342/.local/lib/python3.8/site-packages/tornado/web.py", line 3289, in wrapper
        url = self.get_login_url()
      File "/gpfs/data/oermannlab/users/slj9342/.local/lib/python3.8/site-packages/jupyter_server/base/handlers.py", line 783, in get_login_url
        raise web.HTTPError(403)
    tornado.web.HTTPError: HTTP 403: Forbidden
[W 2025-04-25 15:21:15.922 ServerApp] 403 GET /api/kernelspecs?1745608875914 (@192.168.0.102) 4.72ms referer=None
[W 2025-04-25 15:21:15.923 ServerApp] wrote error: 'Forbidden'
    Traceback (most recent call last):
      File "/gpfs/data/oermannlab/users/slj9342/.local/lib/python3.8/site-packages/tornado/web.py", line 1788, in _execute
        result = method(*self.path_args, **self.path_kwargs)
      File "/gpfs/data/oermannlab/users/slj9342/.local/lib/python3.8/site-packages/tornado/web.py", line 3289, in wrapper
        url = self.get_login_url()
      File "/gpfs/data/oermannlab/users/slj9342/.local/lib/python3.8/site-packages/jupyter_server/base/handlers.py", line 783, in get_login_url
        raise web.HTTPError(403)
    tornado.web.HTTPError: HTTP 403: Forbidden
[W 2025-04-25 15:21:15.923 ServerApp] 403 GET /api/kernels?1745608875914 (@192.168.0.102) 0.60ms referer=None
[W 2025-04-25 15:21:15.930 ServerApp] wrote error: 'Forbidden'
    Traceback (most recent call last):
      File "/gpfs/data/oermannlab/users/slj9342/.local/lib/python3.8/site-packages/tornado/web.py", line 1788, in _execute
        result = method(*self.path_args, **self.path_kwargs)
      File "/gpfs/data/oermannlab/users/slj9342/.local/lib/python3.8/site-packages/tornado/web.py", line 3289, in wrapper
        url = self.get_login_url()
      File "/gpfs/data/oermannlab/users/slj9342/.local/lib/python3.8/site-packages/jupyter_server/base/handlers.py", line 783, in get_login_url
        raise web.HTTPError(403)
    tornado.web.HTTPError: HTTP 403: Forbidden
[W 2025-04-25 15:21:15.930 ServerApp] 403 GET /api/kernelspecs?1745608875915 (@192.168.0.102) 0.71ms referer=None
[W 2025-04-25 15:21:15.930 ServerApp] wrote error: 'Forbidden'
    Traceback (most recent call last):
      File "/gpfs/data/oermannlab/users/slj9342/.local/lib/python3.8/site-packages/tornado/web.py", line 1788, in _execute
        result = method(*self.path_args, **self.path_kwargs)
      File "/gpfs/data/oermannlab/users/slj9342/.local/lib/python3.8/site-packages/tornado/web.py", line 3289, in wrapper
        url = self.get_login_url()
      File "/gpfs/data/oermannlab/users/slj9342/.local/lib/python3.8/site-packages/jupyter_server/base/handlers.py", line 783, in get_login_url
        raise web.HTTPError(403)
    tornado.web.HTTPError: HTTP 403: Forbidden
[W 2025-04-25 15:21:15.931 ServerApp] 403 GET /api/kernels?1745608875915 (@192.168.0.102) 0.62ms referer=None
[W 2025-04-25 15:21:15.932 ServerApp] wrote error: 'Forbidden'
    Traceback (most recent call last):
      File "/gpfs/data/oermannlab/users/slj9342/.local/lib/python3.8/site-packages/tornado/web.py", line 1788, in _execute
        result = method(*self.path_args, **self.path_kwargs)
      File "/gpfs/data/oermannlab/users/slj9342/.local/lib/python3.8/site-packages/tornado/web.py", line 3289, in wrapper
        url = self.get_login_url()
      File "/gpfs/data/oermannlab/users/slj9342/.local/lib/python3.8/site-packages/jupyter_server/base/handlers.py", line 783, in get_login_url
        raise web.HTTPError(403)
    tornado.web.HTTPError: HTTP 403: Forbidden
[W 2025-04-25 15:21:15.932 ServerApp] 403 GET /api/kernels?1745608875919 (@192.168.0.102) 0.86ms referer=None
[W 2025-04-25 15:21:15.932 ServerApp] wrote error: 'Forbidden'
    Traceback (most recent call last):
      File "/gpfs/data/oermannlab/users/slj9342/.local/lib/python3.8/site-packages/tornado/web.py", line 1788, in _execute
        result = method(*self.path_args, **self.path_kwargs)
      File "/gpfs/data/oermannlab/users/slj9342/.local/lib/python3.8/site-packages/tornado/web.py", line 3289, in wrapper
        url = self.get_login_url()
      File "/gpfs/data/oermannlab/users/slj9342/.local/lib/python3.8/site-packages/jupyter_server/base/handlers.py", line 783, in get_login_url
        raise web.HTTPError(403)
    tornado.web.HTTPError: HTTP 403: Forbidden
[W 2025-04-25 15:21:15.932 ServerApp] 403 GET /api/sessions?1745608875920 (@192.168.0.102) 1.12ms referer=None
[W 2025-04-25 15:21:15.932 ServerApp] wrote error: 'Forbidden'
    Traceback (most recent call last):
      File "/gpfs/data/oermannlab/users/slj9342/.local/lib/python3.8/site-packages/tornado/web.py", line 1788, in _execute
        result = method(*self.path_args, **self.path_kwargs)
      File "/gpfs/data/oermannlab/users/slj9342/.local/lib/python3.8/site-packages/tornado/web.py", line 3289, in wrapper
        url = self.get_login_url()
      File "/gpfs/data/oermannlab/users/slj9342/.local/lib/python3.8/site-packages/jupyter_server/base/handlers.py", line 783, in get_login_url
        raise web.HTTPError(403)
    tornado.web.HTTPError: HTTP 403: Forbidden
[W 2025-04-25 15:21:15.933 ServerApp] 403 GET /api/kernels?1745608875920 (@192.168.0.102) 1.39ms referer=None
[W 2025-04-25 15:21:15.933 ServerApp] wrote error: 'Forbidden'
    Traceback (most recent call last):
      File "/gpfs/data/oermannlab/users/slj9342/.local/lib/python3.8/site-packages/tornado/web.py", line 1788, in _execute
        result = method(*self.path_args, **self.path_kwargs)
      File "/gpfs/data/oermannlab/users/slj9342/.local/lib/python3.8/site-packages/tornado/web.py", line 3289, in wrapper
        url = self.get_login_url()
      File "/gpfs/data/oermannlab/users/slj9342/.local/lib/python3.8/site-packages/jupyter_server/base/handlers.py", line 783, in get_login_url
        raise web.HTTPError(403)
    tornado.web.HTTPError: HTTP 403: Forbidden
[W 2025-04-25 15:21:15.933 ServerApp] 403 GET /api/sessions?1745608875921 (@192.168.0.102) 1.66ms referer=None
[I 2025-04-25 15:21:15.954 ServerApp] 302 GET / (@192.168.0.102) 0.30ms
[W 2025-04-25 15:21:15.955 ServerApp] wrote error: 'Forbidden'
    Traceback (most recent call last):
      File "/gpfs/data/oermannlab/users/slj9342/.local/lib/python3.8/site-packages/tornado/web.py", line 1788, in _execute
        result = method(*self.path_args, **self.path_kwargs)
      File "/gpfs/data/oermannlab/users/slj9342/.local/lib/python3.8/site-packages/tornado/web.py", line 3289, in wrapper
        url = self.get_login_url()
      File "/gpfs/data/oermannlab/users/slj9342/.local/lib/python3.8/site-packages/jupyter_server/base/handlers.py", line 783, in get_login_url
        raise web.HTTPError(403)
    tornado.web.HTTPError: HTTP 403: Forbidden
[W 2025-04-25 15:21:15.955 ServerApp] 403 GET /api/kernelspecs?1745608875930 (@192.168.0.102) 0.60ms referer=None
[W 2025-04-25 15:21:15.956 ServerApp] wrote error: 'Forbidden'
    Traceback (most recent call last):
      File "/gpfs/data/oermannlab/users/slj9342/.local/lib/python3.8/site-packages/tornado/web.py", line 1788, in _execute
        result = method(*self.path_args, **self.path_kwargs)
      File "/gpfs/data/oermannlab/users/slj9342/.local/lib/python3.8/site-packages/tornado/web.py", line 3289, in wrapper
        url = self.get_login_url()
      File "/gpfs/data/oermannlab/users/slj9342/.local/lib/python3.8/site-packages/jupyter_server/base/handlers.py", line 783, in get_login_url
        raise web.HTTPError(403)
    tornado.web.HTTPError: HTTP 403: Forbidden
[W 2025-04-25 15:21:15.956 ServerApp] 403 GET /api/kernelspecs?1745608875932 (@192.168.0.102) 0.57ms referer=None
[I 2025-04-25 15:21:15.960 JupyterNotebookApp] 302 GET /tree? (@192.168.0.102) 0.36ms
[W 2025-04-25 15:21:16.072 ServerApp] wrote error: 'Forbidden'
    Traceback (most recent call last):
      File "/gpfs/data/oermannlab/users/slj9342/.local/lib/python3.8/site-packages/tornado/web.py", line 1788, in _execute
        result = method(*self.path_args, **self.path_kwargs)
      File "/gpfs/data/oermannlab/users/slj9342/.local/lib/python3.8/site-packages/tornado/web.py", line 3289, in wrapper
        url = self.get_login_url()
      File "/gpfs/data/oermannlab/users/slj9342/.local/lib/python3.8/site-packages/jupyter_server/base/handlers.py", line 783, in get_login_url
        raise web.HTTPError(403)
    tornado.web.HTTPError: HTTP 403: Forbidden
[W 2025-04-25 15:21:16.073 ServerApp] 403 GET /api/kernelspecs?1745608876069 (@192.168.0.102) 0.83ms referer=None
[W 2025-04-25 15:21:16.096 ServerApp] wrote error: 'Forbidden'
    Traceback (most recent call last):
      File "/gpfs/data/oermannlab/users/slj9342/.local/lib/python3.8/site-packages/tornado/web.py", line 1788, in _execute
        result = method(*self.path_args, **self.path_kwargs)
      File "/gpfs/data/oermannlab/users/slj9342/.local/lib/python3.8/site-packages/tornado/web.py", line 3289, in wrapper
        url = self.get_login_url()
      File "/gpfs/data/oermannlab/users/slj9342/.local/lib/python3.8/site-packages/jupyter_server/base/handlers.py", line 783, in get_login_url
        raise web.HTTPError(403)
    tornado.web.HTTPError: HTTP 403: Forbidden
[W 2025-04-25 15:21:16.097 ServerApp] 403 GET /api/kernels?1745608876069 (@192.168.0.102) 1.39ms referer=None
[W 2025-04-25 15:21:16.097 ServerApp] wrote error: 'Forbidden'
    Traceback (most recent call last):
      File "/gpfs/data/oermannlab/users/slj9342/.local/lib/python3.8/site-packages/tornado/web.py", line 1788, in _execute
        result = method(*self.path_args, **self.path_kwargs)
      File "/gpfs/data/oermannlab/users/slj9342/.local/lib/python3.8/site-packages/tornado/web.py", line 3289, in wrapper
        url = self.get_login_url()
      File "/gpfs/data/oermannlab/users/slj9342/.local/lib/python3.8/site-packages/jupyter_server/base/handlers.py", line 783, in get_login_url
        raise web.HTTPError(403)
    tornado.web.HTTPError: HTTP 403: Forbidden
[W 2025-04-25 15:21:16.097 ServerApp] 403 GET /api/kernelspecs?1745608876069 (@192.168.0.102) 1.62ms referer=None
[W 2025-04-25 15:21:16.097 ServerApp] wrote error: 'Forbidden'
    Traceback (most recent call last):
      File "/gpfs/data/oermannlab/users/slj9342/.local/lib/python3.8/site-packages/tornado/web.py", line 1788, in _execute
        result = method(*self.path_args, **self.path_kwargs)
      File "/gpfs/data/oermannlab/users/slj9342/.local/lib/python3.8/site-packages/tornado/web.py", line 3289, in wrapper
        url = self.get_login_url()
      File "/gpfs/data/oermannlab/users/slj9342/.local/lib/python3.8/site-packages/jupyter_server/base/handlers.py", line 783, in get_login_url
        raise web.HTTPError(403)
    tornado.web.HTTPError: HTTP 403: Forbidden
[W 2025-04-25 15:21:16.098 ServerApp] 403 GET /api/kernels?1745608876070 (@192.168.0.102) 1.89ms referer=None
[W 2025-04-25 15:21:16.098 ServerApp] wrote error: 'Forbidden'
    Traceback (most recent call last):
      File "/gpfs/data/oermannlab/users/slj9342/.local/lib/python3.8/site-packages/tornado/web.py", line 1788, in _execute
        result = method(*self.path_args, **self.path_kwargs)
      File "/gpfs/data/oermannlab/users/slj9342/.local/lib/python3.8/site-packages/tornado/web.py", line 3289, in wrapper
        url = self.get_login_url()
      File "/gpfs/data/oermannlab/users/slj9342/.local/lib/python3.8/site-packages/jupyter_server/base/handlers.py", line 783, in get_login_url
        raise web.HTTPError(403)
    tornado.web.HTTPError: HTTP 403: Forbidden
[W 2025-04-25 15:21:16.098 ServerApp] 403 GET /api/kernels?1745608876071 (@192.168.0.102) 2.15ms referer=None
[W 2025-04-25 15:21:16.098 ServerApp] wrote error: 'Forbidden'
    Traceback (most recent call last):
      File "/gpfs/data/oermannlab/users/slj9342/.local/lib/python3.8/site-packages/tornado/web.py", line 1788, in _execute
        result = method(*self.path_args, **self.path_kwargs)
      File "/gpfs/data/oermannlab/users/slj9342/.local/lib/python3.8/site-packages/tornado/web.py", line 3289, in wrapper
        url = self.get_login_url()
      File "/gpfs/data/oermannlab/users/slj9342/.local/lib/python3.8/site-packages/jupyter_server/base/handlers.py", line 783, in get_login_url
        raise web.HTTPError(403)
    tornado.web.HTTPError: HTTP 403: Forbidden
[W 2025-04-25 15:21:16.098 ServerApp] 403 GET /api/sessions?1745608876072 (@192.168.0.102) 2.43ms referer=None
[W 2025-04-25 15:21:16.098 ServerApp] wrote error: 'Forbidden'
    Traceback (most recent call last):
      File "/gpfs/data/oermannlab/users/slj9342/.local/lib/python3.8/site-packages/tornado/web.py", line 1788, in _execute
        result = method(*self.path_args, **self.path_kwargs)
      File "/gpfs/data/oermannlab/users/slj9342/.local/lib/python3.8/site-packages/tornado/web.py", line 3289, in wrapper
        url = self.get_login_url()
      File "/gpfs/data/oermannlab/users/slj9342/.local/lib/python3.8/site-packages/jupyter_server/base/handlers.py", line 783, in get_login_url
        raise web.HTTPError(403)
    tornado.web.HTTPError: HTTP 403: Forbidden
[W 2025-04-25 15:21:16.099 ServerApp] 403 GET /api/kernels?1745608876073 (@192.168.0.102) 2.70ms referer=None
[W 2025-04-25 15:21:16.101 ServerApp] wrote error: 'Forbidden'
    Traceback (most recent call last):
      File "/gpfs/data/oermannlab/users/slj9342/.local/lib/python3.8/site-packages/tornado/web.py", line 1788, in _execute
        result = method(*self.path_args, **self.path_kwargs)
      File "/gpfs/data/oermannlab/users/slj9342/.local/lib/python3.8/site-packages/tornado/web.py", line 3289, in wrapper
        url = self.get_login_url()
      File "/gpfs/data/oermannlab/users/slj9342/.local/lib/python3.8/site-packages/jupyter_server/base/handlers.py", line 783, in get_login_url
        raise web.HTTPError(403)
    tornado.web.HTTPError: HTTP 403: Forbidden
[W 2025-04-25 15:21:16.101 ServerApp] 403 GET /api/sessions?1745608876077 (@192.168.0.102) 1.98ms referer=None
[W 2025-04-25 15:21:16.101 ServerApp] wrote error: 'Forbidden'
    Traceback (most recent call last):
      File "/gpfs/data/oermannlab/users/slj9342/.local/lib/python3.8/site-packages/tornado/web.py", line 1788, in _execute
        result = method(*self.path_args, **self.path_kwargs)
      File "/gpfs/data/oermannlab/users/slj9342/.local/lib/python3.8/site-packages/tornado/web.py", line 3289, in wrapper
        url = self.get_login_url()
      File "/gpfs/data/oermannlab/users/slj9342/.local/lib/python3.8/site-packages/jupyter_server/base/handlers.py", line 783, in get_login_url
        raise web.HTTPError(403)
    tornado.web.HTTPError: HTTP 403: Forbidden
[W 2025-04-25 15:21:16.101 ServerApp] 403 GET /api/kernelspecs?1745608876079 (@192.168.0.102) 2.23ms referer=None
[W 2025-04-25 15:21:16.101 ServerApp] wrote error: 'Forbidden'
    Traceback (most recent call last):
      File "/gpfs/data/oermannlab/users/slj9342/.local/lib/python3.8/site-packages/tornado/web.py", line 1788, in _execute
        result = method(*self.path_args, **self.path_kwargs)
      File "/gpfs/data/oermannlab/users/slj9342/.local/lib/python3.8/site-packages/tornado/web.py", line 3289, in wrapper
        url = self.get_login_url()
      File "/gpfs/data/oermannlab/users/slj9342/.local/lib/python3.8/site-packages/jupyter_server/base/handlers.py", line 783, in get_login_url
        raise web.HTTPError(403)
    tornado.web.HTTPError: HTTP 403: Forbidden
[W 2025-04-25 15:21:16.102 ServerApp] 403 GET /api/kernels?1745608876079 (@192.168.0.102) 2.49ms referer=None
[W 2025-04-25 15:21:16.102 ServerApp] wrote error: 'Forbidden'
    Traceback (most recent call last):
      File "/gpfs/data/oermannlab/users/slj9342/.local/lib/python3.8/site-packages/tornado/web.py", line 1788, in _execute
        result = method(*self.path_args, **self.path_kwargs)
      File "/gpfs/data/oermannlab/users/slj9342/.local/lib/python3.8/site-packages/tornado/web.py", line 3289, in wrapper
        url = self.get_login_url()
      File "/gpfs/data/oermannlab/users/slj9342/.local/lib/python3.8/site-packages/jupyter_server/base/handlers.py", line 783, in get_login_url
        raise web.HTTPError(403)
    tornado.web.HTTPError: HTTP 403: Forbidden
[W 2025-04-25 15:21:16.102 ServerApp] 403 GET /api/kernelspecs?1745608876079 (@192.168.0.102) 2.76ms referer=None
[W 2025-04-25 15:21:16.102 ServerApp] wrote error: 'Forbidden'
    Traceback (most recent call last):
      File "/gpfs/data/oermannlab/users/slj9342/.local/lib/python3.8/site-packages/tornado/web.py", line 1788, in _execute
        result = method(*self.path_args, **self.path_kwargs)
      File "/gpfs/data/oermannlab/users/slj9342/.local/lib/python3.8/site-packages/tornado/web.py", line 3289, in wrapper
        url = self.get_login_url()
      File "/gpfs/data/oermannlab/users/slj9342/.local/lib/python3.8/site-packages/jupyter_server/base/handlers.py", line 783, in get_login_url
        raise web.HTTPError(403)
    tornado.web.HTTPError: HTTP 403: Forbidden
[W 2025-04-25 15:21:16.102 ServerApp] 403 GET /api/kernels?1745608876080 (@192.168.0.102) 3.04ms referer=None
[W 2025-04-25 15:21:16.102 ServerApp] wrote error: 'Forbidden'
    Traceback (most recent call last):
      File "/gpfs/data/oermannlab/users/slj9342/.local/lib/python3.8/site-packages/tornado/web.py", line 1788, in _execute
        result = method(*self.path_args, **self.path_kwargs)
      File "/gpfs/data/oermannlab/users/slj9342/.local/lib/python3.8/site-packages/tornado/web.py", line 3289, in wrapper
        url = self.get_login_url()
      File "/gpfs/data/oermannlab/users/slj9342/.local/lib/python3.8/site-packages/jupyter_server/base/handlers.py", line 783, in get_login_url
        raise web.HTTPError(403)
    tornado.web.HTTPError: HTTP 403: Forbidden
[W 2025-04-25 15:21:16.103 ServerApp] 403 GET /api/kernelspecs?1745608876081 (@192.168.0.102) 3.31ms referer=None
[W 2025-04-25 15:21:16.103 ServerApp] wrote error: 'Forbidden'
    Traceback (most recent call last):
      File "/gpfs/data/oermannlab/users/slj9342/.local/lib/python3.8/site-packages/tornado/web.py", line 1788, in _execute
        result = method(*self.path_args, **self.path_kwargs)
      File "/gpfs/data/oermannlab/users/slj9342/.local/lib/python3.8/site-packages/tornado/web.py", line 3289, in wrapper
        url = self.get_login_url()
      File "/gpfs/data/oermannlab/users/slj9342/.local/lib/python3.8/site-packages/jupyter_server/base/handlers.py", line 783, in get_login_url
        raise web.HTTPError(403)
    tornado.web.HTTPError: HTTP 403: Forbidden
[W 2025-04-25 15:21:16.103 ServerApp] 403 GET /api/kernels?1745608876082 (@192.168.0.102) 3.57ms referer=None
[W 2025-04-25 15:21:16.103 ServerApp] wrote error: 'Forbidden'
    Traceback (most recent call last):
      File "/gpfs/data/oermannlab/users/slj9342/.local/lib/python3.8/site-packages/tornado/web.py", line 1788, in _execute
        result = method(*self.path_args, **self.path_kwargs)
      File "/gpfs/data/oermannlab/users/slj9342/.local/lib/python3.8/site-packages/tornado/web.py", line 3289, in wrapper
        url = self.get_login_url()
      File "/gpfs/data/oermannlab/users/slj9342/.local/lib/python3.8/site-packages/jupyter_server/base/handlers.py", line 783, in get_login_url
        raise web.HTTPError(403)
    tornado.web.HTTPError: HTTP 403: Forbidden
[W 2025-04-25 15:21:16.103 ServerApp] 403 GET /api/kernels?1745608876088 (@192.168.0.102) 3.82ms referer=None
[W 2025-04-25 15:21:16.104 ServerApp] wrote error: 'Forbidden'
    Traceback (most recent call last):
      File "/gpfs/data/oermannlab/users/slj9342/.local/lib/python3.8/site-packages/tornado/web.py", line 1788, in _execute
        result = method(*self.path_args, **self.path_kwargs)
      File "/gpfs/data/oermannlab/users/slj9342/.local/lib/python3.8/site-packages/tornado/web.py", line 3289, in wrapper
        url = self.get_login_url()
      File "/gpfs/data/oermannlab/users/slj9342/.local/lib/python3.8/site-packages/jupyter_server/base/handlers.py", line 783, in get_login_url
        raise web.HTTPError(403)
    tornado.web.HTTPError: HTTP 403: Forbidden
[W 2025-04-25 15:21:16.104 ServerApp] 403 GET /api/sessions?1745608876089 (@192.168.0.102) 4.07ms referer=None
[W 2025-04-25 15:21:16.104 ServerApp] wrote error: 'Forbidden'
    Traceback (most recent call last):
      File "/gpfs/data/oermannlab/users/slj9342/.local/lib/python3.8/site-packages/tornado/web.py", line 1788, in _execute
        result = method(*self.path_args, **self.path_kwargs)
      File "/gpfs/data/oermannlab/users/slj9342/.local/lib/python3.8/site-packages/tornado/web.py", line 3289, in wrapper
        url = self.get_login_url()
      File "/gpfs/data/oermannlab/users/slj9342/.local/lib/python3.8/site-packages/jupyter_server/base/handlers.py", line 783, in get_login_url
        raise web.HTTPError(403)
    tornado.web.HTTPError: HTTP 403: Forbidden
[W 2025-04-25 15:21:16.104 ServerApp] 403 GET /api/kernels?1745608876090 (@192.168.0.102) 4.32ms referer=None
[W 2025-04-25 15:21:16.104 ServerApp] wrote error: 'Forbidden'
    Traceback (most recent call last):
      File "/gpfs/data/oermannlab/users/slj9342/.local/lib/python3.8/site-packages/tornado/web.py", line 1788, in _execute
        result = method(*self.path_args, **self.path_kwargs)
      File "/gpfs/data/oermannlab/users/slj9342/.local/lib/python3.8/site-packages/tornado/web.py", line 3289, in wrapper
        url = self.get_login_url()
      File "/gpfs/data/oermannlab/users/slj9342/.local/lib/python3.8/site-packages/jupyter_server/base/handlers.py", line 783, in get_login_url
        raise web.HTTPError(403)
    tornado.web.HTTPError: HTTP 403: Forbidden
[W 2025-04-25 15:21:16.105 ServerApp] 403 GET /api/sessions?1745608876091 (@192.168.0.102) 4.51ms referer=None
[W 2025-04-25 15:21:16.105 ServerApp] wrote error: 'Forbidden'
    Traceback (most recent call last):
      File "/gpfs/data/oermannlab/users/slj9342/.local/lib/python3.8/site-packages/tornado/web.py", line 1788, in _execute
        result = method(*self.path_args, **self.path_kwargs)
      File "/gpfs/data/oermannlab/users/slj9342/.local/lib/python3.8/site-packages/tornado/web.py", line 3289, in wrapper
        url = self.get_login_url()
      File "/gpfs/data/oermannlab/users/slj9342/.local/lib/python3.8/site-packages/jupyter_server/base/handlers.py", line 783, in get_login_url
        raise web.HTTPError(403)
    tornado.web.HTTPError: HTTP 403: Forbidden
[W 2025-04-25 15:21:16.105 ServerApp] 403 GET /api/kernels?1745608876092 (@192.168.0.102) 4.75ms referer=None
[W 2025-04-25 15:21:16.105 ServerApp] wrote error: 'Forbidden'
    Traceback (most recent call last):
      File "/gpfs/data/oermannlab/users/slj9342/.local/lib/python3.8/site-packages/tornado/web.py", line 1788, in _execute
        result = method(*self.path_args, **self.path_kwargs)
      File "/gpfs/data/oermannlab/users/slj9342/.local/lib/python3.8/site-packages/tornado/web.py", line 3289, in wrapper
        url = self.get_login_url()
      File "/gpfs/data/oermannlab/users/slj9342/.local/lib/python3.8/site-packages/jupyter_server/base/handlers.py", line 783, in get_login_url
        raise web.HTTPError(403)
    tornado.web.HTTPError: HTTP 403: Forbidden
[W 2025-04-25 15:21:16.105 ServerApp] 403 GET /api/sessions?1745608876092 (@192.168.0.102) 5.02ms referer=None
[W 2025-04-25 15:21:16.106 ServerApp] wrote error: 'Forbidden'
    Traceback (most recent call last):
      File "/gpfs/data/oermannlab/users/slj9342/.local/lib/python3.8/site-packages/tornado/web.py", line 1788, in _execute
        result = method(*self.path_args, **self.path_kwargs)
      File "/gpfs/data/oermannlab/users/slj9342/.local/lib/python3.8/site-packages/tornado/web.py", line 3289, in wrapper
        url = self.get_login_url()
      File "/gpfs/data/oermannlab/users/slj9342/.local/lib/python3.8/site-packages/jupyter_server/base/handlers.py", line 783, in get_login_url
        raise web.HTTPError(403)
    tornado.web.HTTPError: HTTP 403: Forbidden
[W 2025-04-25 15:21:16.106 ServerApp] 403 GET /api/kernelspecs?1745608876093 (@192.168.0.102) 0.67ms referer=None
[W 2025-04-25 15:21:16.109 ServerApp] wrote error: 'Forbidden'
    Traceback (most recent call last):
      File "/gpfs/data/oermannlab/users/slj9342/.local/lib/python3.8/site-packages/tornado/web.py", line 1788, in _execute
        result = method(*self.path_args, **self.path_kwargs)
      File "/gpfs/data/oermannlab/users/slj9342/.local/lib/python3.8/site-packages/tornado/web.py", line 3289, in wrapper
        url = self.get_login_url()
      File "/gpfs/data/oermannlab/users/slj9342/.local/lib/python3.8/site-packages/jupyter_server/base/handlers.py", line 783, in get_login_url
        raise web.HTTPError(403)
    tornado.web.HTTPError: HTTP 403: Forbidden
[W 2025-04-25 15:21:16.109 ServerApp] 403 GET /api/kernelspecs?1745608876099 (@192.168.0.102) 0.50ms referer=None
[I 2025-04-25 15:21:16.109 ServerApp] 302 GET / (@192.168.0.102) 0.20ms
[W 2025-04-25 15:21:16.117 ServerApp] wrote error: 'Forbidden'
    Traceback (most recent call last):
      File "/gpfs/data/oermannlab/users/slj9342/.local/lib/python3.8/site-packages/tornado/web.py", line 1788, in _execute
        result = method(*self.path_args, **self.path_kwargs)
      File "/gpfs/data/oermannlab/users/slj9342/.local/lib/python3.8/site-packages/tornado/web.py", line 3289, in wrapper
        url = self.get_login_url()
      File "/gpfs/data/oermannlab/users/slj9342/.local/lib/python3.8/site-packages/jupyter_server/base/handlers.py", line 783, in get_login_url
        raise web.HTTPError(403)
    tornado.web.HTTPError: HTTP 403: Forbidden
[W 2025-04-25 15:21:16.117 ServerApp] 403 GET /api/kernelspecs?1745608876109 (@192.168.0.102) 0.49ms referer=None
[W 2025-04-25 15:21:16.117 ServerApp] wrote error: 'Forbidden'
    Traceback (most recent call last):
      File "/gpfs/data/oermannlab/users/slj9342/.local/lib/python3.8/site-packages/tornado/web.py", line 1788, in _execute
        result = method(*self.path_args, **self.path_kwargs)
      File "/gpfs/data/oermannlab/users/slj9342/.local/lib/python3.8/site-packages/tornado/web.py", line 3289, in wrapper
        url = self.get_login_url()
      File "/gpfs/data/oermannlab/users/slj9342/.local/lib/python3.8/site-packages/jupyter_server/base/handlers.py", line 783, in get_login_url
        raise web.HTTPError(403)
    tornado.web.HTTPError: HTTP 403: Forbidden
[W 2025-04-25 15:21:16.118 ServerApp] 403 GET /api/kernelspecs?1745608876109 (@192.168.0.102) 0.50ms referer=None
[W 2025-04-25 15:21:16.118 ServerApp] wrote error: 'Forbidden'
    Traceback (most recent call last):
      File "/gpfs/data/oermannlab/users/slj9342/.local/lib/python3.8/site-packages/tornado/web.py", line 1788, in _execute
        result = method(*self.path_args, **self.path_kwargs)
      File "/gpfs/data/oermannlab/users/slj9342/.local/lib/python3.8/site-packages/tornado/web.py", line 3289, in wrapper
        url = self.get_login_url()
      File "/gpfs/data/oermannlab/users/slj9342/.local/lib/python3.8/site-packages/jupyter_server/base/handlers.py", line 783, in get_login_url
        raise web.HTTPError(403)
    tornado.web.HTTPError: HTTP 403: Forbidden
[W 2025-04-25 15:21:16.118 ServerApp] 403 GET /api/kernelspecs?1745608876110 (@192.168.0.102) 0.48ms referer=None
[I 2025-04-25 15:21:16.119 JupyterNotebookApp] 302 GET /tree? (@192.168.0.102) 0.30ms
[I 2025-04-25 15:21:31.117 ServerApp] 302 GET / (@192.168.0.102) 0.39ms
[I 2025-04-25 15:21:31.119 JupyterNotebookApp] 302 GET /tree? (@192.168.0.102) 0.40ms
[W 2025-04-25 15:21:31.143 ServerApp] wrote error: 'Forbidden'
    Traceback (most recent call last):
      File "/gpfs/data/oermannlab/users/slj9342/.local/lib/python3.8/site-packages/tornado/web.py", line 1788, in _execute
        result = method(*self.path_args, **self.path_kwargs)
      File "/gpfs/data/oermannlab/users/slj9342/.local/lib/python3.8/site-packages/tornado/web.py", line 3289, in wrapper
        url = self.get_login_url()
      File "/gpfs/data/oermannlab/users/slj9342/.local/lib/python3.8/site-packages/jupyter_server/base/handlers.py", line 783, in get_login_url
        raise web.HTTPError(403)
    tornado.web.HTTPError: HTTP 403: Forbidden
[W 2025-04-25 15:21:31.144 ServerApp] 403 GET /api/kernelspecs?1745608891139 (@192.168.0.102) 0.80ms referer=None
[W 2025-04-25 15:21:31.150 ServerApp] wrote error: 'Forbidden'
    Traceback (most recent call last):
      File "/gpfs/data/oermannlab/users/slj9342/.local/lib/python3.8/site-packages/tornado/web.py", line 1788, in _execute
        result = method(*self.path_args, **self.path_kwargs)
      File "/gpfs/data/oermannlab/users/slj9342/.local/lib/python3.8/site-packages/tornado/web.py", line 3289, in wrapper
        url = self.get_login_url()
      File "/gpfs/data/oermannlab/users/slj9342/.local/lib/python3.8/site-packages/jupyter_server/base/handlers.py", line 783, in get_login_url
        raise web.HTTPError(403)
    tornado.web.HTTPError: HTTP 403: Forbidden
[W 2025-04-25 15:21:31.150 ServerApp] 403 GET /api/kernels?1745608891140 (@192.168.0.102) 0.72ms referer=None
[W 2025-04-25 15:21:31.151 ServerApp] wrote error: 'Forbidden'
    Traceback (most recent call last):
      File "/gpfs/data/oermannlab/users/slj9342/.local/lib/python3.8/site-packages/tornado/web.py", line 1788, in _execute
        result = method(*self.path_args, **self.path_kwargs)
      File "/gpfs/data/oermannlab/users/slj9342/.local/lib/python3.8/site-packages/tornado/web.py", line 3289, in wrapper
        url = self.get_login_url()
      File "/gpfs/data/oermannlab/users/slj9342/.local/lib/python3.8/site-packages/jupyter_server/base/handlers.py", line 783, in get_login_url
        raise web.HTTPError(403)
    tornado.web.HTTPError: HTTP 403: Forbidden
[W 2025-04-25 15:21:31.151 ServerApp] 403 GET /api/kernelspecs?1745608891140 (@192.168.0.102) 0.59ms referer=None
[W 2025-04-25 15:21:31.151 ServerApp] wrote error: 'Forbidden'
    Traceback (most recent call last):
      File "/gpfs/data/oermannlab/users/slj9342/.local/lib/python3.8/site-packages/tornado/web.py", line 1788, in _execute
        result = method(*self.path_args, **self.path_kwargs)
      File "/gpfs/data/oermannlab/users/slj9342/.local/lib/python3.8/site-packages/tornado/web.py", line 3289, in wrapper
        url = self.get_login_url()
      File "/gpfs/data/oermannlab/users/slj9342/.local/lib/python3.8/site-packages/jupyter_server/base/handlers.py", line 783, in get_login_url
        raise web.HTTPError(403)
    tornado.web.HTTPError: HTTP 403: Forbidden
[W 2025-04-25 15:21:31.152 ServerApp] 403 GET /api/kernels?1745608891141 (@192.168.0.102) 0.51ms referer=None
[W 2025-04-25 15:21:31.152 ServerApp] wrote error: 'Forbidden'
    Traceback (most recent call last):
      File "/gpfs/data/oermannlab/users/slj9342/.local/lib/python3.8/site-packages/tornado/web.py", line 1788, in _execute
        result = method(*self.path_args, **self.path_kwargs)
      File "/gpfs/data/oermannlab/users/slj9342/.local/lib/python3.8/site-packages/tornado/web.py", line 3289, in wrapper
        url = self.get_login_url()
      File "/gpfs/data/oermannlab/users/slj9342/.local/lib/python3.8/site-packages/jupyter_server/base/handlers.py", line 783, in get_login_url
        raise web.HTTPError(403)
    tornado.web.HTTPError: HTTP 403: Forbidden
[W 2025-04-25 15:21:31.153 ServerApp] 403 GET /api/kernels?1745608891143 (@192.168.0.102) 0.83ms referer=None
[W 2025-04-25 15:21:31.153 ServerApp] wrote error: 'Forbidden'
    Traceback (most recent call last):
      File "/gpfs/data/oermannlab/users/slj9342/.local/lib/python3.8/site-packages/tornado/web.py", line 1788, in _execute
        result = method(*self.path_args, **self.path_kwargs)
      File "/gpfs/data/oermannlab/users/slj9342/.local/lib/python3.8/site-packages/tornado/web.py", line 3289, in wrapper
        url = self.get_login_url()
      File "/gpfs/data/oermannlab/users/slj9342/.local/lib/python3.8/site-packages/jupyter_server/base/handlers.py", line 783, in get_login_url
        raise web.HTTPError(403)
    tornado.web.HTTPError: HTTP 403: Forbidden
[W 2025-04-25 15:21:31.153 ServerApp] 403 GET /api/sessions?1745608891144 (@192.168.0.102) 1.08ms referer=None
[W 2025-04-25 15:21:31.153 ServerApp] wrote error: 'Forbidden'
    Traceback (most recent call last):
      File "/gpfs/data/oermannlab/users/slj9342/.local/lib/python3.8/site-packages/tornado/web.py", line 1788, in _execute
        result = method(*self.path_args, **self.path_kwargs)
      File "/gpfs/data/oermannlab/users/slj9342/.local/lib/python3.8/site-packages/tornado/web.py", line 3289, in wrapper
        url = self.get_login_url()
      File "/gpfs/data/oermannlab/users/slj9342/.local/lib/python3.8/site-packages/jupyter_server/base/handlers.py", line 783, in get_login_url
        raise web.HTTPError(403)
    tornado.web.HTTPError: HTTP 403: Forbidden
[W 2025-04-25 15:21:31.153 ServerApp] 403 GET /api/kernels?1745608891144 (@192.168.0.102) 1.36ms referer=None
[W 2025-04-25 15:21:31.153 ServerApp] wrote error: 'Forbidden'
    Traceback (most recent call last):
      File "/gpfs/data/oermannlab/users/slj9342/.local/lib/python3.8/site-packages/tornado/web.py", line 1788, in _execute
        result = method(*self.path_args, **self.path_kwargs)
      File "/gpfs/data/oermannlab/users/slj9342/.local/lib/python3.8/site-packages/tornado/web.py", line 3289, in wrapper
        url = self.get_login_url()
      File "/gpfs/data/oermannlab/users/slj9342/.local/lib/python3.8/site-packages/jupyter_server/base/handlers.py", line 783, in get_login_url
        raise web.HTTPError(403)
    tornado.web.HTTPError: HTTP 403: Forbidden
[W 2025-04-25 15:21:31.154 ServerApp] 403 GET /api/sessions?1745608891145 (@192.168.0.102) 1.63ms referer=None
[W 2025-04-25 15:21:31.154 ServerApp] wrote error: 'Forbidden'
    Traceback (most recent call last):
      File "/gpfs/data/oermannlab/users/slj9342/.local/lib/python3.8/site-packages/tornado/web.py", line 1788, in _execute
        result = method(*self.path_args, **self.path_kwargs)
      File "/gpfs/data/oermannlab/users/slj9342/.local/lib/python3.8/site-packages/tornado/web.py", line 3289, in wrapper
        url = self.get_login_url()
      File "/gpfs/data/oermannlab/users/slj9342/.local/lib/python3.8/site-packages/jupyter_server/base/handlers.py", line 783, in get_login_url
        raise web.HTTPError(403)
    tornado.web.HTTPError: HTTP 403: Forbidden
[W 2025-04-25 15:21:31.155 ServerApp] 403 GET /api/kernelspecs?1745608891149 (@192.168.0.102) 0.54ms referer=None
[W 2025-04-25 15:21:31.157 ServerApp] wrote error: 'Forbidden'
    Traceback (most recent call last):
      File "/gpfs/data/oermannlab/users/slj9342/.local/lib/python3.8/site-packages/tornado/web.py", line 1788, in _execute
        result = method(*self.path_args, **self.path_kwargs)
      File "/gpfs/data/oermannlab/users/slj9342/.local/lib/python3.8/site-packages/tornado/web.py", line 3289, in wrapper
        url = self.get_login_url()
      File "/gpfs/data/oermannlab/users/slj9342/.local/lib/python3.8/site-packages/jupyter_server/base/handlers.py", line 783, in get_login_url
        raise web.HTTPError(403)
    tornado.web.HTTPError: HTTP 403: Forbidden
[W 2025-04-25 15:21:31.157 ServerApp] 403 GET /api/kernelspecs?1745608891153 (@192.168.0.102) 0.44ms referer=None
[W 2025-04-25 15:21:33.837 ServerApp] wrote error: 'Forbidden'
    Traceback (most recent call last):
      File "/gpfs/data/oermannlab/users/slj9342/.local/lib/python3.8/site-packages/tornado/web.py", line 1788, in _execute
        result = method(*self.path_args, **self.path_kwargs)
      File "/gpfs/data/oermannlab/users/slj9342/.local/lib/python3.8/site-packages/tornado/web.py", line 3289, in wrapper
        url = self.get_login_url()
      File "/gpfs/data/oermannlab/users/slj9342/.local/lib/python3.8/site-packages/jupyter_server/base/handlers.py", line 783, in get_login_url
        raise web.HTTPError(403)
    tornado.web.HTTPError: HTTP 403: Forbidden
[W 2025-04-25 15:21:33.838 ServerApp] 403 GET /api/kernelspecs?1745608893834 (@192.168.0.102) 1.03ms referer=None
[W 2025-04-25 15:21:33.839 ServerApp] wrote error: 'Forbidden'
    Traceback (most recent call last):
      File "/gpfs/data/oermannlab/users/slj9342/.local/lib/python3.8/site-packages/tornado/web.py", line 1788, in _execute
        result = method(*self.path_args, **self.path_kwargs)
      File "/gpfs/data/oermannlab/users/slj9342/.local/lib/python3.8/site-packages/tornado/web.py", line 3289, in wrapper
        url = self.get_login_url()
      File "/gpfs/data/oermannlab/users/slj9342/.local/lib/python3.8/site-packages/jupyter_server/base/handlers.py", line 783, in get_login_url
        raise web.HTTPError(403)
    tornado.web.HTTPError: HTTP 403: Forbidden
[W 2025-04-25 15:21:33.839 ServerApp] 403 GET /api/kernels?1745608893835 (@192.168.0.102) 0.67ms referer=None
[W 2025-04-25 15:21:33.840 ServerApp] wrote error: 'Forbidden'
    Traceback (most recent call last):
      File "/gpfs/data/oermannlab/users/slj9342/.local/lib/python3.8/site-packages/tornado/web.py", line 1788, in _execute
        result = method(*self.path_args, **self.path_kwargs)
      File "/gpfs/data/oermannlab/users/slj9342/.local/lib/python3.8/site-packages/tornado/web.py", line 3289, in wrapper
        url = self.get_login_url()
      File "/gpfs/data/oermannlab/users/slj9342/.local/lib/python3.8/site-packages/jupyter_server/base/handlers.py", line 783, in get_login_url
        raise web.HTTPError(403)
    tornado.web.HTTPError: HTTP 403: Forbidden
[W 2025-04-25 15:21:33.840 ServerApp] 403 GET /api/kernels?1745608893836 (@192.168.0.102) 0.81ms referer=None
[W 2025-04-25 15:21:33.841 ServerApp] wrote error: 'Forbidden'
    Traceback (most recent call last):
      File "/gpfs/data/oermannlab/users/slj9342/.local/lib/python3.8/site-packages/tornado/web.py", line 1788, in _execute
        result = method(*self.path_args, **self.path_kwargs)
      File "/gpfs/data/oermannlab/users/slj9342/.local/lib/python3.8/site-packages/tornado/web.py", line 3289, in wrapper
        url = self.get_login_url()
      File "/gpfs/data/oermannlab/users/slj9342/.local/lib/python3.8/site-packages/jupyter_server/base/handlers.py", line 783, in get_login_url
        raise web.HTTPError(403)
    tornado.web.HTTPError: HTTP 403: Forbidden
[W 2025-04-25 15:21:33.841 ServerApp] 403 GET /api/sessions?1745608893837 (@192.168.0.102) 1.00ms referer=None
[W 2025-04-25 15:21:33.845 ServerApp] wrote error: 'Forbidden'
    Traceback (most recent call last):
      File "/gpfs/data/oermannlab/users/slj9342/.local/lib/python3.8/site-packages/tornado/web.py", line 1788, in _execute
        result = method(*self.path_args, **self.path_kwargs)
      File "/gpfs/data/oermannlab/users/slj9342/.local/lib/python3.8/site-packages/tornado/web.py", line 3289, in wrapper
        url = self.get_login_url()
      File "/gpfs/data/oermannlab/users/slj9342/.local/lib/python3.8/site-packages/jupyter_server/base/handlers.py", line 783, in get_login_url
        raise web.HTTPError(403)
    tornado.web.HTTPError: HTTP 403: Forbidden
[W 2025-04-25 15:21:33.845 ServerApp] 403 GET /api/kernelspecs?1745608893839 (@192.168.0.102) 0.60ms referer=None
[I 2025-04-25 15:21:34.376 ServerApp] 302 GET / (@192.168.0.102) 0.38ms
[I 2025-04-25 15:21:34.377 JupyterNotebookApp] 302 GET /tree? (@192.168.0.102) 0.35ms
[W 2025-04-25 15:21:35.838 ServerApp] wrote error: 'Forbidden'
    Traceback (most recent call last):
      File "/gpfs/data/oermannlab/users/slj9342/.local/lib/python3.8/site-packages/tornado/web.py", line 1788, in _execute
        result = method(*self.path_args, **self.path_kwargs)
      File "/gpfs/data/oermannlab/users/slj9342/.local/lib/python3.8/site-packages/tornado/web.py", line 3289, in wrapper
        url = self.get_login_url()
      File "/gpfs/data/oermannlab/users/slj9342/.local/lib/python3.8/site-packages/jupyter_server/base/handlers.py", line 783, in get_login_url
        raise web.HTTPError(403)
    tornado.web.HTTPError: HTTP 403: Forbidden
[W 2025-04-25 15:21:35.839 ServerApp] 403 GET /api/kernelspecs?1745608895835 (@192.168.0.102) 0.94ms referer=None
[W 2025-04-25 15:21:35.840 ServerApp] wrote error: 'Forbidden'
    Traceback (most recent call last):
      File "/gpfs/data/oermannlab/users/slj9342/.local/lib/python3.8/site-packages/tornado/web.py", line 1788, in _execute
        result = method(*self.path_args, **self.path_kwargs)
      File "/gpfs/data/oermannlab/users/slj9342/.local/lib/python3.8/site-packages/tornado/web.py", line 3289, in wrapper
        url = self.get_login_url()
      File "/gpfs/data/oermannlab/users/slj9342/.local/lib/python3.8/site-packages/jupyter_server/base/handlers.py", line 783, in get_login_url
        raise web.HTTPError(403)
    tornado.web.HTTPError: HTTP 403: Forbidden
[W 2025-04-25 15:21:35.841 ServerApp] 403 GET /api/kernels?1745608895836 (@192.168.0.102) 0.64ms referer=None
[W 2025-04-25 15:21:35.841 ServerApp] wrote error: 'Forbidden'
    Traceback (most recent call last):
      File "/gpfs/data/oermannlab/users/slj9342/.local/lib/python3.8/site-packages/tornado/web.py", line 1788, in _execute
        result = method(*self.path_args, **self.path_kwargs)
      File "/gpfs/data/oermannlab/users/slj9342/.local/lib/python3.8/site-packages/tornado/web.py", line 3289, in wrapper
        url = self.get_login_url()
      File "/gpfs/data/oermannlab/users/slj9342/.local/lib/python3.8/site-packages/jupyter_server/base/handlers.py", line 783, in get_login_url
        raise web.HTTPError(403)
    tornado.web.HTTPError: HTTP 403: Forbidden
[W 2025-04-25 15:21:35.841 ServerApp] 403 GET /api/kernels?1745608895837 (@192.168.0.102) 0.53ms referer=None
[W 2025-04-25 15:21:35.842 ServerApp] wrote error: 'Forbidden'
    Traceback (most recent call last):
      File "/gpfs/data/oermannlab/users/slj9342/.local/lib/python3.8/site-packages/tornado/web.py", line 1788, in _execute
        result = method(*self.path_args, **self.path_kwargs)
      File "/gpfs/data/oermannlab/users/slj9342/.local/lib/python3.8/site-packages/tornado/web.py", line 3289, in wrapper
        url = self.get_login_url()
      File "/gpfs/data/oermannlab/users/slj9342/.local/lib/python3.8/site-packages/jupyter_server/base/handlers.py", line 783, in get_login_url
        raise web.HTTPError(403)
    tornado.web.HTTPError: HTTP 403: Forbidden
[W 2025-04-25 15:21:35.842 ServerApp] 403 GET /api/sessions?1745608895838 (@192.168.0.102) 0.51ms referer=None
[W 2025-04-25 15:21:35.852 ServerApp] wrote error: 'Forbidden'
    Traceback (most recent call last):
      File "/gpfs/data/oermannlab/users/slj9342/.local/lib/python3.8/site-packages/tornado/web.py", line 1788, in _execute
        result = method(*self.path_args, **self.path_kwargs)
      File "/gpfs/data/oermannlab/users/slj9342/.local/lib/python3.8/site-packages/tornado/web.py", line 3289, in wrapper
        url = self.get_login_url()
      File "/gpfs/data/oermannlab/users/slj9342/.local/lib/python3.8/site-packages/jupyter_server/base/handlers.py", line 783, in get_login_url
        raise web.HTTPError(403)
    tornado.web.HTTPError: HTTP 403: Forbidden
[W 2025-04-25 15:21:35.853 ServerApp] 403 GET /api/kernelspecs?1745608895845 (@192.168.0.102) 0.85ms referer=None
[I 2025-04-25 15:26:22.312 ServerApp] 302 GET / (@192.168.0.102) 0.31ms
[I 2025-04-25 15:26:22.312 ServerApp] 302 GET / (@192.168.0.102) 0.25ms
[I 2025-04-25 15:26:22.371 JupyterNotebookApp] 302 GET /tree? (@192.168.0.102) 0.52ms
[I 2025-04-25 15:26:22.371 JupyterNotebookApp] 302 GET /tree? (@192.168.0.102) 0.63ms
[W 2025-04-25 15:26:22.441 ServerApp] wrote error: 'Forbidden'
    Traceback (most recent call last):
      File "/gpfs/data/oermannlab/users/slj9342/.local/lib/python3.8/site-packages/tornado/web.py", line 1788, in _execute
        result = method(*self.path_args, **self.path_kwargs)
      File "/gpfs/data/oermannlab/users/slj9342/.local/lib/python3.8/site-packages/tornado/web.py", line 3289, in wrapper
        url = self.get_login_url()
      File "/gpfs/data/oermannlab/users/slj9342/.local/lib/python3.8/site-packages/jupyter_server/base/handlers.py", line 783, in get_login_url
        raise web.HTTPError(403)
    tornado.web.HTTPError: HTTP 403: Forbidden
[W 2025-04-25 15:26:22.441 ServerApp] 403 GET /api/kernelspecs?1745609182438 (@192.168.0.102) 0.77ms referer=None
[W 2025-04-25 15:26:22.442 ServerApp] wrote error: 'Forbidden'
    Traceback (most recent call last):
      File "/gpfs/data/oermannlab/users/slj9342/.local/lib/python3.8/site-packages/tornado/web.py", line 1788, in _execute
        result = method(*self.path_args, **self.path_kwargs)
      File "/gpfs/data/oermannlab/users/slj9342/.local/lib/python3.8/site-packages/tornado/web.py", line 3289, in wrapper
        url = self.get_login_url()
      File "/gpfs/data/oermannlab/users/slj9342/.local/lib/python3.8/site-packages/jupyter_server/base/handlers.py", line 783, in get_login_url
        raise web.HTTPError(403)
    tornado.web.HTTPError: HTTP 403: Forbidden
[W 2025-04-25 15:26:22.442 ServerApp] 403 GET /api/kernels?1745609182439 (@192.168.0.102) 1.02ms referer=None
[W 2025-04-25 15:26:22.449 ServerApp] wrote error: 'Forbidden'
    Traceback (most recent call last):
      File "/gpfs/data/oermannlab/users/slj9342/.local/lib/python3.8/site-packages/tornado/web.py", line 1788, in _execute
        result = method(*self.path_args, **self.path_kwargs)
      File "/gpfs/data/oermannlab/users/slj9342/.local/lib/python3.8/site-packages/tornado/web.py", line 3289, in wrapper
        url = self.get_login_url()
      File "/gpfs/data/oermannlab/users/slj9342/.local/lib/python3.8/site-packages/jupyter_server/base/handlers.py", line 783, in get_login_url
        raise web.HTTPError(403)
    tornado.web.HTTPError: HTTP 403: Forbidden
[W 2025-04-25 15:26:22.449 ServerApp] 403 GET /api/kernels?1745609182442 (@192.168.0.102) 0.50ms referer=None
[W 2025-04-25 15:26:22.449 ServerApp] wrote error: 'Forbidden'
    Traceback (most recent call last):
      File "/gpfs/data/oermannlab/users/slj9342/.local/lib/python3.8/site-packages/tornado/web.py", line 1788, in _execute
        result = method(*self.path_args, **self.path_kwargs)
      File "/gpfs/data/oermannlab/users/slj9342/.local/lib/python3.8/site-packages/tornado/web.py", line 3289, in wrapper
        url = self.get_login_url()
      File "/gpfs/data/oermannlab/users/slj9342/.local/lib/python3.8/site-packages/jupyter_server/base/handlers.py", line 783, in get_login_url
        raise web.HTTPError(403)
    tornado.web.HTTPError: HTTP 403: Forbidden
[W 2025-04-25 15:26:22.450 ServerApp] 403 GET /api/sessions?1745609182445 (@192.168.0.102) 0.47ms referer=None
[W 2025-04-25 15:26:22.454 ServerApp] wrote error: 'Forbidden'
    Traceback (most recent call last):
      File "/gpfs/data/oermannlab/users/slj9342/.local/lib/python3.8/site-packages/tornado/web.py", line 1788, in _execute
        result = method(*self.path_args, **self.path_kwargs)
      File "/gpfs/data/oermannlab/users/slj9342/.local/lib/python3.8/site-packages/tornado/web.py", line 3289, in wrapper
        url = self.get_login_url()
      File "/gpfs/data/oermannlab/users/slj9342/.local/lib/python3.8/site-packages/jupyter_server/base/handlers.py", line 783, in get_login_url
        raise web.HTTPError(403)
    tornado.web.HTTPError: HTTP 403: Forbidden
[W 2025-04-25 15:26:22.454 ServerApp] 403 GET /api/kernelspecs?1745609182449 (@192.168.0.102) 0.47ms referer=None
[I 2025-04-25 15:26:22.454 ServerApp] 302 GET / (@192.168.0.102) 0.19ms
[I 2025-04-25 15:26:22.457 JupyterNotebookApp] 302 GET /tree? (@192.168.0.102) 0.27ms
[W 2025-04-25 15:26:22.473 ServerApp] wrote error: 'Forbidden'
    Traceback (most recent call last):
      File "/gpfs/data/oermannlab/users/slj9342/.local/lib/python3.8/site-packages/tornado/web.py", line 1788, in _execute
        result = method(*self.path_args, **self.path_kwargs)
      File "/gpfs/data/oermannlab/users/slj9342/.local/lib/python3.8/site-packages/tornado/web.py", line 3289, in wrapper
        url = self.get_login_url()
      File "/gpfs/data/oermannlab/users/slj9342/.local/lib/python3.8/site-packages/jupyter_server/base/handlers.py", line 783, in get_login_url
        raise web.HTTPError(403)
    tornado.web.HTTPError: HTTP 403: Forbidden
[W 2025-04-25 15:26:22.473 ServerApp] 403 GET /api/kernelspecs?1745609182470 (@192.168.0.102) 0.61ms referer=None
[W 2025-04-25 15:26:22.479 ServerApp] wrote error: 'Forbidden'
    Traceback (most recent call last):
      File "/gpfs/data/oermannlab/users/slj9342/.local/lib/python3.8/site-packages/tornado/web.py", line 1788, in _execute
        result = method(*self.path_args, **self.path_kwargs)
      File "/gpfs/data/oermannlab/users/slj9342/.local/lib/python3.8/site-packages/tornado/web.py", line 3289, in wrapper
        url = self.get_login_url()
      File "/gpfs/data/oermannlab/users/slj9342/.local/lib/python3.8/site-packages/jupyter_server/base/handlers.py", line 783, in get_login_url
        raise web.HTTPError(403)
    tornado.web.HTTPError: HTTP 403: Forbidden
[W 2025-04-25 15:26:22.479 ServerApp] 403 GET /api/kernels?1745609182473 (@192.168.0.102) 0.98ms referer=None
[W 2025-04-25 15:26:22.479 ServerApp] wrote error: 'Forbidden'
    Traceback (most recent call last):
      File "/gpfs/data/oermannlab/users/slj9342/.local/lib/python3.8/site-packages/tornado/web.py", line 1788, in _execute
        result = method(*self.path_args, **self.path_kwargs)
      File "/gpfs/data/oermannlab/users/slj9342/.local/lib/python3.8/site-packages/tornado/web.py", line 3289, in wrapper
        url = self.get_login_url()
      File "/gpfs/data/oermannlab/users/slj9342/.local/lib/python3.8/site-packages/jupyter_server/base/handlers.py", line 783, in get_login_url
        raise web.HTTPError(403)
    tornado.web.HTTPError: HTTP 403: Forbidden
[W 2025-04-25 15:26:22.480 ServerApp] 403 GET /api/kernels?1745609182475 (@192.168.0.102) 1.18ms referer=None
[W 2025-04-25 15:26:22.480 ServerApp] wrote error: 'Forbidden'
    Traceback (most recent call last):
      File "/gpfs/data/oermannlab/users/slj9342/.local/lib/python3.8/site-packages/tornado/web.py", line 1788, in _execute
        result = method(*self.path_args, **self.path_kwargs)
      File "/gpfs/data/oermannlab/users/slj9342/.local/lib/python3.8/site-packages/tornado/web.py", line 3289, in wrapper
        url = self.get_login_url()
      File "/gpfs/data/oermannlab/users/slj9342/.local/lib/python3.8/site-packages/jupyter_server/base/handlers.py", line 783, in get_login_url
        raise web.HTTPError(403)
    tornado.web.HTTPError: HTTP 403: Forbidden
[W 2025-04-25 15:26:22.480 ServerApp] 403 GET /api/sessions?1745609182477 (@192.168.0.102) 1.39ms referer=None
[W 2025-04-25 15:26:22.481 ServerApp] wrote error: 'Forbidden'
    Traceback (most recent call last):
      File "/gpfs/data/oermannlab/users/slj9342/.local/lib/python3.8/site-packages/tornado/web.py", line 1788, in _execute
        result = method(*self.path_args, **self.path_kwargs)
      File "/gpfs/data/oermannlab/users/slj9342/.local/lib/python3.8/site-packages/tornado/web.py", line 3289, in wrapper
        url = self.get_login_url()
      File "/gpfs/data/oermannlab/users/slj9342/.local/lib/python3.8/site-packages/jupyter_server/base/handlers.py", line 783, in get_login_url
        raise web.HTTPError(403)
    tornado.web.HTTPError: HTTP 403: Forbidden
[W 2025-04-25 15:26:22.481 ServerApp] 403 GET /api/kernels?1745609182471 (@192.168.0.102) 0.80ms referer=None
[W 2025-04-25 15:26:22.481 ServerApp] wrote error: 'Forbidden'
    Traceback (most recent call last):
      File "/gpfs/data/oermannlab/users/slj9342/.local/lib/python3.8/site-packages/tornado/web.py", line 1788, in _execute
        result = method(*self.path_args, **self.path_kwargs)
      File "/gpfs/data/oermannlab/users/slj9342/.local/lib/python3.8/site-packages/tornado/web.py", line 3289, in wrapper
        url = self.get_login_url()
      File "/gpfs/data/oermannlab/users/slj9342/.local/lib/python3.8/site-packages/jupyter_server/base/handlers.py", line 783, in get_login_url
        raise web.HTTPError(403)
    tornado.web.HTTPError: HTTP 403: Forbidden
[W 2025-04-25 15:26:22.481 ServerApp] 403 GET /api/kernelspecs?1745609182471 (@192.168.0.102) 1.07ms referer=None
[W 2025-04-25 15:26:22.482 ServerApp] wrote error: 'Forbidden'
    Traceback (most recent call last):
      File "/gpfs/data/oermannlab/users/slj9342/.local/lib/python3.8/site-packages/tornado/web.py", line 1788, in _execute
        result = method(*self.path_args, **self.path_kwargs)
      File "/gpfs/data/oermannlab/users/slj9342/.local/lib/python3.8/site-packages/tornado/web.py", line 3289, in wrapper
        url = self.get_login_url()
      File "/gpfs/data/oermannlab/users/slj9342/.local/lib/python3.8/site-packages/jupyter_server/base/handlers.py", line 783, in get_login_url
        raise web.HTTPError(403)
    tornado.web.HTTPError: HTTP 403: Forbidden
[W 2025-04-25 15:26:22.482 ServerApp] 403 GET /api/kernels?1745609182472 (@192.168.0.102) 1.33ms referer=None
[W 2025-04-25 15:26:22.482 ServerApp] wrote error: 'Forbidden'
    Traceback (most recent call last):
      File "/gpfs/data/oermannlab/users/slj9342/.local/lib/python3.8/site-packages/tornado/web.py", line 1788, in _execute
        result = method(*self.path_args, **self.path_kwargs)
      File "/gpfs/data/oermannlab/users/slj9342/.local/lib/python3.8/site-packages/tornado/web.py", line 3289, in wrapper
        url = self.get_login_url()
      File "/gpfs/data/oermannlab/users/slj9342/.local/lib/python3.8/site-packages/jupyter_server/base/handlers.py", line 783, in get_login_url
        raise web.HTTPError(403)
    tornado.web.HTTPError: HTTP 403: Forbidden
[W 2025-04-25 15:26:22.483 ServerApp] 403 GET /api/sessions?1745609182474 (@192.168.0.102) 0.69ms referer=None
[W 2025-04-25 15:26:22.483 ServerApp] wrote error: 'Forbidden'
    Traceback (most recent call last):
      File "/gpfs/data/oermannlab/users/slj9342/.local/lib/python3.8/site-packages/tornado/web.py", line 1788, in _execute
        result = method(*self.path_args, **self.path_kwargs)
      File "/gpfs/data/oermannlab/users/slj9342/.local/lib/python3.8/site-packages/tornado/web.py", line 3289, in wrapper
        url = self.get_login_url()
      File "/gpfs/data/oermannlab/users/slj9342/.local/lib/python3.8/site-packages/jupyter_server/base/handlers.py", line 783, in get_login_url
        raise web.HTTPError(403)
    tornado.web.HTTPError: HTTP 403: Forbidden
[W 2025-04-25 15:26:22.483 ServerApp] 403 GET /api/kernelspecs?1745609182478 (@192.168.0.102) 0.85ms referer=None
[W 2025-04-25 15:26:22.486 ServerApp] wrote error: 'Forbidden'
    Traceback (most recent call last):
      File "/gpfs/data/oermannlab/users/slj9342/.local/lib/python3.8/site-packages/tornado/web.py", line 1788, in _execute
        result = method(*self.path_args, **self.path_kwargs)
      File "/gpfs/data/oermannlab/users/slj9342/.local/lib/python3.8/site-packages/tornado/web.py", line 3289, in wrapper
        url = self.get_login_url()
      File "/gpfs/data/oermannlab/users/slj9342/.local/lib/python3.8/site-packages/jupyter_server/base/handlers.py", line 783, in get_login_url
        raise web.HTTPError(403)
    tornado.web.HTTPError: HTTP 403: Forbidden
[W 2025-04-25 15:26:22.486 ServerApp] 403 GET /api/kernelspecs?1745609182482 (@192.168.0.102) 0.48ms referer=None
[W 2025-04-25 15:26:22.487 ServerApp] wrote error: 'Forbidden'
    Traceback (most recent call last):
      File "/gpfs/data/oermannlab/users/slj9342/.local/lib/python3.8/site-packages/tornado/web.py", line 1788, in _execute
        result = method(*self.path_args, **self.path_kwargs)
      File "/gpfs/data/oermannlab/users/slj9342/.local/lib/python3.8/site-packages/tornado/web.py", line 3289, in wrapper
        url = self.get_login_url()
      File "/gpfs/data/oermannlab/users/slj9342/.local/lib/python3.8/site-packages/jupyter_server/base/handlers.py", line 783, in get_login_url
        raise web.HTTPError(403)
    tornado.web.HTTPError: HTTP 403: Forbidden
[W 2025-04-25 15:26:22.487 ServerApp] 403 GET /api/sessions?1745609182482 (@192.168.0.102) 0.57ms referer=None
[I 2025-04-25 15:26:22.487 ServerApp] 302 GET / (@192.168.0.102) 0.58ms
[I 2025-04-25 15:26:22.489 JupyterNotebookApp] 302 GET /tree? (@192.168.0.102) 0.27ms
[W 2025-04-25 15:26:27.524 ServerApp] 401 POST /login? (@192.168.0.102) 0.72ms referer=None
[W 2025-04-25 15:26:27.527 ServerApp] wrote error: 'Forbidden'
    Traceback (most recent call last):
      File "/gpfs/data/oermannlab/users/slj9342/.local/lib/python3.8/site-packages/tornado/web.py", line 1788, in _execute
        result = method(*self.path_args, **self.path_kwargs)
      File "/gpfs/data/oermannlab/users/slj9342/.local/lib/python3.8/site-packages/tornado/web.py", line 3289, in wrapper
        url = self.get_login_url()
      File "/gpfs/data/oermannlab/users/slj9342/.local/lib/python3.8/site-packages/jupyter_server/base/handlers.py", line 783, in get_login_url
        raise web.HTTPError(403)
    tornado.web.HTTPError: HTTP 403: Forbidden
[W 2025-04-25 15:26:27.527 ServerApp] 403 GET /api/kernelspecs?1745609187525 (@192.168.0.102) 0.52ms referer=None
[W 2025-04-25 15:26:27.533 ServerApp] wrote error: 'Forbidden'
    Traceback (most recent call last):
      File "/gpfs/data/oermannlab/users/slj9342/.local/lib/python3.8/site-packages/tornado/web.py", line 1788, in _execute
        result = method(*self.path_args, **self.path_kwargs)
      File "/gpfs/data/oermannlab/users/slj9342/.local/lib/python3.8/site-packages/tornado/web.py", line 3289, in wrapper
        url = self.get_login_url()
      File "/gpfs/data/oermannlab/users/slj9342/.local/lib/python3.8/site-packages/jupyter_server/base/handlers.py", line 783, in get_login_url
        raise web.HTTPError(403)
    tornado.web.HTTPError: HTTP 403: Forbidden
[W 2025-04-25 15:26:27.533 ServerApp] 403 GET /api/kernelspecs?1745609187532 (@192.168.0.102) 0.49ms referer=None
[W 2025-04-25 15:26:27.533 ServerApp] wrote error: 'Forbidden'
    Traceback (most recent call last):
      File "/gpfs/data/oermannlab/users/slj9342/.local/lib/python3.8/site-packages/tornado/web.py", line 1788, in _execute
        result = method(*self.path_args, **self.path_kwargs)
      File "/gpfs/data/oermannlab/users/slj9342/.local/lib/python3.8/site-packages/tornado/web.py", line 3289, in wrapper
        url = self.get_login_url()
      File "/gpfs/data/oermannlab/users/slj9342/.local/lib/python3.8/site-packages/jupyter_server/base/handlers.py", line 783, in get_login_url
        raise web.HTTPError(403)
    tornado.web.HTTPError: HTTP 403: Forbidden
[W 2025-04-25 15:26:27.534 ServerApp] 403 GET /api/kernels?1745609187526 (@192.168.0.102) 0.68ms referer=None
[W 2025-04-25 15:26:27.534 ServerApp] wrote error: 'Forbidden'
    Traceback (most recent call last):
      File "/gpfs/data/oermannlab/users/slj9342/.local/lib/python3.8/site-packages/tornado/web.py", line 1788, in _execute
        result = method(*self.path_args, **self.path_kwargs)
      File "/gpfs/data/oermannlab/users/slj9342/.local/lib/python3.8/site-packages/tornado/web.py", line 3289, in wrapper
        url = self.get_login_url()
      File "/gpfs/data/oermannlab/users/slj9342/.local/lib/python3.8/site-packages/jupyter_server/base/handlers.py", line 783, in get_login_url
        raise web.HTTPError(403)
    tornado.web.HTTPError: HTTP 403: Forbidden
[W 2025-04-25 15:26:27.534 ServerApp] 403 GET /api/kernels?1745609187527 (@192.168.0.102) 0.94ms referer=None
[W 2025-04-25 15:26:27.534 ServerApp] wrote error: 'Forbidden'
    Traceback (most recent call last):
      File "/gpfs/data/oermannlab/users/slj9342/.local/lib/python3.8/site-packages/tornado/web.py", line 1788, in _execute
        result = method(*self.path_args, **self.path_kwargs)
      File "/gpfs/data/oermannlab/users/slj9342/.local/lib/python3.8/site-packages/tornado/web.py", line 3289, in wrapper
        url = self.get_login_url()
      File "/gpfs/data/oermannlab/users/slj9342/.local/lib/python3.8/site-packages/jupyter_server/base/handlers.py", line 783, in get_login_url
        raise web.HTTPError(403)
    tornado.web.HTTPError: HTTP 403: Forbidden
[W 2025-04-25 15:26:27.534 ServerApp] 403 GET /api/sessions?1745609187527 (@192.168.0.102) 1.22ms referer=None
[I 2025-04-25 15:47:13.908 ServerApp] Starting buffering for 8e67e9e2-9200-4922-9498-c74d6369577f:54eb24f9-18fc-4faa-be33-e22a331b387b
